Workbook

Sheet District
A1: District 227 Performance Dashboard
A2: Membership, Payments & Club Recognition Goals
A4: Payments Goals | D4: Clubs Goals | G4: Distinguished Clubs Goals
A5: Base Payments | B5: 8634 | D5: Base Clubs | E5: 174 | G5: Distinguished Clubs Prereq | H5: 0
A6: Distinguished | B6: =ROUND(B5*1.01, 0) | D6: Distinguished | E6: =E5 | G6: Distinguished | H6: =ROUND(0.4*E5, 0)
A7: Select Distinguished | B7: =ROUND(B5*1.03, 0) | D7: Select Distinguished | E7: 184 | G7: Select Distinguished | H7: 89
A8: President's Distinguished | B8: =ROUND(B5*1.05, 0) | D8: President's Distinguished | E8: 194 | G8: President's Distinguished | H8: 100
A9: Smedley Distinguished | B9: =ROUND(B5*1.08, 0) | D9: Smedley Distinguished | E9: 197 | G9: Smedley Distinguished | H9: 108
A11: Payments To Date | B11: =Overall!L12 | D11: Active Clubs | E11: =Overall!C12 | G11: Distinguished To Date | H11: =Overall!D12
A13: Pending Distinguished | B13: =IF(B6-B11<0,0,B6-B11) | D13: Pending Distinguished | E13: =IF(E6-E11<0,0,E6-E11) | G13: Pending Distinguished | H13: =IF(H6-H11<0,0,H6-H11)
A14: Pending Select Distinguished | B14: =IF(B7-B11<0,0,B7-B11) | D14: Pending Select Distinguished | E14: =IF(E7-E11<0,0,E7-E11) | G14: Pending Select Distinguished | H14: =IF(H7-H11<0,0,H7-H11)
A15: Pending President's Distinguished | B15: =IF(B8-B11<0,0,B8-B11) | D15: Pending President's Distinguished | E15: =IF(E8-E11<0,0,E8-E11) | G15: Pending President's Distinguished | H15: =IF(H8-H11<0,0,H8-H11)
A16: Pending Smedley Distinguished | B16: =IF(B9-B11<0,0,B9-B11) | D16: Pending Smedley Distinguished | E16: =IF(E9-E11<0,0,E9-E11) | G16: Pending Smedley Distinguished | H16: =IF(H9-H11<0,0,H9-H11)
A18: Payments % Base | B18: =B11/B5 | D18: 20 + Clubs | E18: =Overall!M12 | G18: Distinguished % Base | H18: =H11/E5
A19: Payments % SDD Goal | B19: =B11/B9 | D19: 20 + Clubs % Active Clubs | E19: =E18/E11
A21: Membership Campaigns & Deadlines
A23: Campaign Name | B23: Timeline | C23: Status / Time Left
A24: Smedley Award | B24: Aug 1 - Sep 30 | C24: =IF(TODAY()>DATE(YEAR(TODAY()),9,30), "Ended", DATE(YEAR(TODAY()),9,30)-TODAY() & " days left")
A25: Talk Up Toastmasters | B25: Feb 1 - Mar 31 | C25: =IF(TODAY()>DATE(YEAR(TODAY())+IF(MONTH(TODAY())>3,1,0),3,31), "Ended", DATE(YEAR(TODAY())+IF(MONTH(TODAY())>3,1,0),3,31)-TODAY() & " days left")
A26: Beat the Clock | B26: May 1 - Jun 30 | C26: =IF(TODAY()>DATE(YEAR(TODAY())+IF(MONTH(TODAY())>6,1,0),6,30), "Ended", DATE(YEAR(TODAY())+IF(MONTH(TODAY())>6,1,0),6,30)-TODAY() & " days left")

Sheet ClubDetails
A1: Club Number | B1: District | C1: Division | D1: Area | E1: Club Name | F1: Club Status | G1: Base Membership | H1: Active Membership | I1: Goals Met | J1: New Member Payments | K1: September Renewals | L1: March Renewals | M1: Total Payments | N1: Sept Single Renewal | O1: Sept Double Renewal | P1: March Single Renewal | Q1: March Double Renewal
A2: 28679549 | B2: 227 | C2: 0D | D2: 0A | E2: Vialto Toastmasters Club | F2: Active | G2: 21 | H2: 21 | I2: 1 | J2: 0 | K2: 21 | L2: 0 | M2: 21 | N2: 21 | O2: 0 | P2: 0 | Q2: 0
A3: 28680070 | B3: 227 | C3: 0D | D3: 0A | E3: Envision India Toastmasters Club | F3: Active | G3: 24 | H3: 24 | I3: 1 | J3: 0 | K3: 24 | L3: 0 | M3: 48 | N3: 24 | O3: 0 | P3: 0 | Q3: 0
A4: 28680152 | B4: 227 | C4: 0D | D4: 0A | E4: rProcess Toastmasters Club | F4: Active | G4: 21 | H4: 21 | I4: 0 | J4: 0 | K4: 19 | L4: 0 | M4: 19 | N4: 19 | O4: 0 | P4: 0 | Q4: 0
A5: 28680397 | B5: 227 | C5: 0D | D5: 0A | E5: Uxcel Toastmasters Club | F5: Active | G5: 20 | H5: 20 | I5: 0 | J5: 0 | K5: 8 | L5: 7 | M5: 15 | N5: 8 | O5: 0 | P5: 7 | Q5: 0
A6: 28680500 | B6: 227 | C6: 0D | D6: 0A | E6: eGov Toastmasters Club | F6: Active | G6: 30 | H6: 30 | I6: 0 | J6: 0 | K6: 0 | L6: 0 | M6: 0 | N6: 0 | O6: 0 | P6: 0 | Q6: 0
A7: 3803102 | B7: 227 | C7: A | D7: 01 | E7: RESONANCE | F7: Active | G7: 33 | H7: 33 | I7: 0 | J7: 0 | K7: 15 | L7: 11 | M7: 26 | N7: 15 | O7: 0 | P7: 11 | Q7: 0
A8: 28675382 | B8: 227 | C8: A | D8: 01 | E8: INDO-MIM Toastmasters Club | F8: Active | G8: 13 | H8: 13 | I8: 0 | J8: 0 | K8: 0 | L8: 0 | M8: 0 | N8: 0 | O8: 0 | P8: 0 | Q8: 0
A9: 28676720 | B9: 227 | C9: A | D9: 01 | E9: Presidency University Toastmasters Club | F9: Active | G9: 15 | H9: 15 | I9: 0 | J9: 0 | K9: 10 | L9: 1 | M9: 11 | N9: 10 | O9: 0 | P9: 1 | Q9: 0
A10: 28678850 | B10: 227 | C10: A | D10: 01 | E10: Shell STCB Verve | F10: Active | G10: 27 | H10: 28 | I10: 1 | J10: 1 | K10: 9 | L10: 3 | M10: 13 | N10: 9 | O10: 0 | P10: 3 | Q10: 0
A11: 28679352 | B11: 227 | C11: A | D11: 01 | E11: Eden Toastmasters Club | F11: Active | G11: 10 | H11: 12 | I11: 0 | J11: 2 | K11: 0 | L11: 0 | M11: 2 | N11: 0 | O11: 0 | P11: 0 | Q11: 0
A12: 28679508 | B12: 227 | C12: A | D12: 01 | E12: SISA Emerging Orators Circle | F12: Active | G12: 16 | H12: 16 | I12: 0 | J12: 0 | K12: 0 | L12: 0 | M12: 0 | N12: 0 | O12: 0 | P12: 0 | Q12: 0
A13: 2379914 | B13: 227 | C13: A | D13: 02 | E13: Beechi Toastmasters Club | F13: Active | G13: 48 | H13: 48 | I13: 0 | J13: 0 | K13: 26 | L13: 11 | M13: 37 | N13: 26 | O13: 0 | P13: 11 | Q13: 0
... A151: 28677183 | B151: 227 | C151: G | D151: 04 | E151: Titans Toastmasters Club | F151: Active | G151: 13 | H151: 20 | I151: 1 | J151: 7 | K151: 20 | L151: 0 | M151: 27 | N151: 20 | O151: 0 | P151: 0 | Q151: 0

Sheet Overall
A1: District 227 - Divisions Performance Rolled-up Summary
A3: Division | B3: Base Clubs | C3: Active Clubs | D3: Distinguished Clubs | E3: Base Membership | F3: Active Membership | G3: September Renewals | H3: September Renewals % | I3: March Renewals | J3: March Renewals % | K3: Total New Members | L3: Total Payments | M3: 20+ Clubs
A4: Division 0D | B4: =COUNTIFS(ClubDetails!C:C, "0D") | C4: =COUNTIFS(ClubDetails!C:C, "0D", ClubDetails!F:F, "Active") | D4: ='Division 0D'!G9 | E4: ='Division 0D'!D9 | F4: ='Division 0D'!E9 | G4: ='Division 0D'!H9 | H4: =IF(E4=0, 0, G4/E4) | I4: ='Division 0D'!K9 | J4: =IF(E4=0, 0, I4/E4) | K4: ='Division 0D'!O9 | L4: ='Division 0D'!N9 | M4: =COUNTIF('Division 0D'!E4:E8, ">=20")
A5: Division A | B5: =COUNTIFS(ClubDetails!C:C, "A") | C5: =COUNTIFS(ClubDetails!C:C, "A", ClubDetails!F:F, "Active") | D5: ='Division A'!G27 | E5: ='Division A'!D27 | F5: ='Division A'!E27 | G5: ='Division A'!H27 | H5: =IF(E5=0, 0, G5/E5) | I5: ='Division A'!K27 | J5: =IF(E5=0, 0, I5/E5) | K5: ='Division A'!O27 | L5: ='Division A'!N27 | M5: =COUNTIF('Division A'!E4:E26, ">=20")
A6: Division B | B6: =COUNTIFS(ClubDetails!C:C, "B") | C6: =COUNTIFS(ClubDetails!C:C, "B", ClubDetails!F:F, "Active") | D6: ='Division B'!G26 | E6: ='Division B'!D26 | F6: ='Division B'!E26 | G6: ='Division B'!H26 | H6: =IF(E6=0, 0, G6/E6) | I6: ='Division B'!K26 | J6: =IF(E6=0, 0, I6/E6) | K6: ='Division B'!O26 | L6: ='Division B'!N26 | M6: =COUNTIF('Division B'!E4:E25, ">=20")
A7: Division C | B7: =COUNTIFS(ClubDetails!C:C, "C") | C7: =COUNTIFS(ClubDetails!C:C, "C", ClubDetails!F:F, "Active") | D7: ='Division C'!G23 | E7: ='Division C'!D23 | F7: ='Division C'!E23 | G7: ='Division C'!H23 | H7: =IF(E7=0, 0, G7/E7) | I7: ='Division C'!K23 | J7: =IF(E7=0, 0, I7/E7) | K7: ='Division C'!O23 | L7: ='Division C'!N23 | M7: =COUNTIF('Division C'!E4:E22, ">=20")
A8: Division D | B8: =COUNTIFS(ClubDetails!C:C, "D") | C8: =COUNTIFS(ClubDetails!C:C, "D", ClubDetails!F:F, "Active") | D8: ='Division D'!G26 | E8: ='Division D'!D26 | F8: ='Division D'!E26 | G8: ='Division D'!H26 | H8: =IF(E8=0, 0, G8/E8) | I8: ='Division D'!K26 | J8: =IF(E8=0, 0, I8/E8) | K8: ='Division D'!O26 | L8: ='Division D'!N26 | M8: =COUNTIF('Division D'!E4:E25, ">=20")
A9: Division E | B9: =COUNTIFS(ClubDetails!C:C, "E") | C9: =COUNTIFS(ClubDetails!C:C, "E", ClubDetails!F:F, "Active") | D9: ='Division E'!G24 | E9: ='Division E'!D24 | F9: ='Division E'!E24 | G9: ='Division E'!H24 | H9: =IF(E9=0, 0, G9/E9) | I9: ='Division E'!K24 | J9: =IF(E9=0, 0, I9/E9) | K9: ='Division E'!O24 | L9: ='Division E'!N24 | M9: =COUNTIF('Division E'!E4:E23, ">=20")
A10: Division F | B10: =COUNTIFS(ClubDetails!C:C, "F") | C10: =COUNTIFS(ClubDetails!C:C, "F", ClubDetails!F:F, "Active") | D10: ='Division F'!G24 | E10: ='Division F'!D24 | F10: ='Division F'!E24 | G10: ='Division F'!H24 | H10: =IF(E10=0, 0, G10/E10) | I10: ='Division F'!K24 | J10: =IF(E10=0, 0, I10/E10) | K10: ='Division F'!O24 | L10: ='Division F'!N24 | M10: =COUNTIF('Division F'!E4:E23, ">=20")
A11: Division G | B11: =COUNTIFS(ClubDetails!C:C, "G") | C11: =COUNTIFS(ClubDetails!C:C, "G", ClubDetails!F:F, "Active") | D11: ='Division G'!G23 | E11: ='Division G'!D23 | F11: ='Division G'!E23 | G11: ='Division G'!H23 | H11: =IF(E11=0, 0, G11/E11) | I11: ='Division G'!K23 | J11: =IF(E11=0, 0, I11/E11) | K11: ='Division G'!O23 | L11: ='Division G'!N23 | M11: =COUNTIF('Division G'!E4:E22, ">=20")
A12: District Total | B12: =SUM(B4:B11) | C12: =SUM(C4:C11) | D12: =SUM(D4:D11) | E12: =SUM(E4:E11) | F12: =SUM(F4:F11) | G12: =SUM(G4:G11) | H12: =IF(E12=0, 0, G12/E12) | I12: =SUM(I4:I11) | J12: =IF(E12=0, 0, I12/E12) | K12: =SUM(K4:K11) | L12: =SUM(L4:L11) | M12: =SUM(M4:M11)
A15: Area Performance Summary
A16: Division | B16: Area | C16: Base Membership | D16: Active Membership | E16: September Renewals | F16: September Renewals % | G16: March Renewals | H16: March Renewals % | I16: Total New Members | J16: Total Payments
A17: 0D | B17: 0A | C17: =SUMIFS(ClubDetails!G:G, ClubDetails!C:C, A17, ClubDetails!D:D, B17) | D17: =SUMIFS(ClubDetails!H:H, ClubDetails!C:C, A17, ClubDetails!D:D, B17) | E17: =SUMIFS(ClubDetails!K:K, ClubDetails!C:C, A17, ClubDetails!D:D, B17) | F17: =IF(C17=0, 0, E17/C17) | G17: =SUMIFS(ClubDetails!L:L, ClubDetails!C:C, A17, ClubDetails!D:D, B17) | H17: =IF(C17=0, 0, G17/C17) | I17: =SUMIFS(ClubDetails!J:J, ClubDetails!C:C, A17, ClubDetails!D:D, B17) | J17: =SUMIFS(ClubDetails!M:M, ClubDetails!C:C, A17, ClubDetails!D:D, B17)
A18: A | B18: 01 | C18: =SUMIFS(ClubDetails!G:G, ClubDetails!C:C, A18, ClubDetails!D:D, B18) | D18: =SUMIFS(ClubDetails!H:H, ClubDetails!C:C, A18, ClubDetails!D:D, B18) | E18: =SUMIFS(ClubDetails!K:K, ClubDetails!C:C, A18, ClubDetails!D:D, B18) | F18: =IF(C18=0, 0, E18/C18) | G18: =SUMIFS(ClubDetails!L:L, ClubDetails!C:C, A18, ClubDetails!D:D, B18) | H18: =IF(C18=0, 0, G18/C18) | I18: =SUMIFS(ClubDetails!J:J, ClubDetails!C:C, A18, ClubDetails!D:D, B18) | J18: =SUMIFS(ClubDetails!M:M, ClubDetails!C:C, A18, ClubDetails!D:D, B18)
A19: A | B19: 02 | C19: =SUMIFS(ClubDetails!G:G, ClubDetails!C:C, A19, ClubDetails!D:D, B19) | D19: =SUMIFS(ClubDetails!H:H, ClubDetails!C:C, A19, ClubDetails!D:D, B19) | E19: =SUMIFS(ClubDetails!K:K, ClubDetails!C:C, A19, ClubDetails!D:D, B19) | F19: =IF(C19=0, 0, E19/C19) | G19: =SUMIFS(ClubDetails!L:L, ClubDetails!C:C, A19, ClubDetails!D:D, B19) | H19: =IF(C19=0, 0, G19/C19) | I19: =SUMIFS(ClubDetails!J:J, ClubDetails!C:C, A19, ClubDetails!D:D, B19) | J19: =SUMIFS(ClubDetails!M:M, ClubDetails!C:C, A19, ClubDetails!D:D, B19)
A20: A | B20: 03 | C20: =SUMIFS(ClubDetails!G:G, ClubDetails!C:C, A20, ClubDetails!D:D, B20) | D20: =SUMIFS(ClubDetails!H:H, ClubDetails!C:C, A20, ClubDetails!D:D, B20) | E20: =SUMIFS(ClubDetails!K:K, ClubDetails!C:C, A20, ClubDetails!D:D, B20) | F20: =IF(C20=0, 0, E20/C20) | G20: =SUMIFS(ClubDetails!L:L, ClubDetails!C:C, A20, ClubDetails!D:D, B20) | H20: =IF(C20=0, 0, G20/C20) | I20: =SUMIFS(ClubDetails!J:J, ClubDetails!C:C, A20, ClubDetails!D:D, B20) | J20: =SUMIFS(ClubDetails!M:M, ClubDetails!C:C, A20, ClubDetails!D:D, B20)
A21: A | B21: 04 | C21: =SUMIFS(ClubDetails!G:G, ClubDetails!C:C, A21, ClubDetails!D:D, B21) | D21: =SUMIFS(ClubDetails!H:H, ClubDetails!C:C, A21, ClubDetails!D:D, B21) | E21: =SUMIFS(ClubDetails!K:K, ClubDetails!C:C, A21, ClubDetails!D:D, B21) | F21: =IF(C21=0, 0, E21/C21) | G21: =SUMIFS(ClubDetails!L:L, ClubDetails!C:C, A21, ClubDetails!D:D, B21) | H21: =IF(C21=0, 0, G21/C21) | I21: =SUMIFS(ClubDetails!J:J, ClubDetails!C:C, A21, ClubDetails!D:D, B21) | J21: =SUMIFS(ClubDetails!M:M, ClubDetails!C:C, A21, ClubDetails!D:D, B21)
A22: B | B22: 01 | C22: =SUMIFS(ClubDetails!G:G, ClubDetails!C:C, A22, ClubDetails!D:D, B22) | D22: =SUMIFS(ClubDetails!H:H, ClubDetails!C:C, A22, ClubDetails!D:D, B22) | E22: =SUMIFS(ClubDetails!K:K, ClubDetails!C:C, A22, ClubDetails!D:D, B22) | F22: =IF(C22=0, 0, E22/C22) | G22: =SUMIFS(ClubDetails!L:L, ClubDetails!C:C, A22, ClubDetails!D:D, B22) | H22: =IF(C22=0, 0, G22/C22) | I22: =SUMIFS(ClubDetails!J:J, ClubDetails!C:C, A22, ClubDetails!D:D, B22) | J22: =SUMIFS(ClubDetails!M:M, ClubDetails!C:C, A22, ClubDetails!D:D, B22)
A23: B | B23: 02 | C23: =SUMIFS(ClubDetails!G:G, ClubDetails!C:C, A23, ClubDetails!D:D, B23) | D23: =SUMIFS(ClubDetails!H:H, ClubDetails!C:C, A23, ClubDetails!D:D, B23) | E23: =SUMIFS(ClubDetails!K:K, ClubDetails!C:C, A23, ClubDetails!D:D, B23) | F23: =IF(C23=0, 0, E23/C23) | G23: =SUMIFS(ClubDetails!L:L, ClubDetails!C:C, A23, ClubDetails!D:D, B23) | H23: =IF(C23=0, 0, G23/C23) | I23: =SUMIFS(ClubDetails!J:J, ClubDetails!C:C, A23, ClubDetails!D:D, B23) | J23: =SUMIFS(ClubDetails!M:M, ClubDetails!C:C, A23, ClubDetails!D:D, B23)
A24: B | B24: 03 | C24: =SUMIFS(ClubDetails!G:G, ClubDetails!C:C, A24, ClubDetails!D:D, B24) | D24: =SUMIFS(ClubDetails!H:H, ClubDetails!C:C, A24, ClubDetails!D:D, B24) | E24: =SUMIFS(ClubDetails!K:K, ClubDetails!C:C, A24, ClubDetails!D:D, B24) | F24: =IF(C24=0, 0, E24/C24) | G24: =SUMIFS(ClubDetails!L:L, ClubDetails!C:C, A24, ClubDetails!D:D, B24) | H24: =IF(C24=0, 0, G24/C24) | I24: =SUMIFS(ClubDetails!J:J, ClubDetails!C:C, A24, ClubDetails!D:D, B24) | J24: =SUMIFS(ClubDetails!M:M, ClubDetails!C:C, A24, ClubDetails!D:D, B24)
A25: B | B25: 04 | C25: =SUMIFS(ClubDetails!G:G, ClubDetails!C:C, A25, ClubDetails!D:D, B25) | D25: =SUMIFS(ClubDetails!H:H, ClubDetails!C:C, A25, ClubDetails!D:D, B25) | E25: =SUMIFS(ClubDetails!K:K, ClubDetails!C:C, A25, ClubDetails!D:D, B25) | F25: =IF(C25=0, 0, E25/C25) | G25: =SUMIFS(ClubDetails!L:L, ClubDetails!C:C, A25, ClubDetails!D:D, B25) | H25: =IF(C25=0, 0, G25/C25) | I25: =SUMIFS(ClubDetails!J:J, ClubDetails!C:C, A25, ClubDetails!D:D, B25) | J25: =SUMIFS(ClubDetails!M:M, ClubDetails!C:C, A25, ClubDetails!D:D, B25)
A26: C | B26: 01 | C26: =SUMIFS(ClubDetails!G:G, ClubDetails!C:C, A26, ClubDetails!D:D, B26) | D26: =SUMIFS(ClubDetails!H:H, ClubDetails!C:C, A26, ClubDetails!D:D, B26) | E26: =SUMIFS(ClubDetails!K:K, ClubDetails!C:C, A26, ClubDetails!D:D, B26) | F26: =IF(C26=0, 0, E26/C26) | G26: =SUMIFS(ClubDetails!L:L, ClubDetails!C:C, A26, ClubDetails!D:D, B26) | H26: =IF(C26=0, 0, G26/C26) | I26: =SUMIFS(ClubDetails!J:J, ClubDetails!C:C, A26, ClubDetails!D:D, B26) | J26: =SUMIFS(ClubDetails!M:M, ClubDetails!C:C, A26, ClubDetails!D:D, B26)
A27: C | B27: 02 | C27: =SUMIFS(ClubDetails!G:G, ClubDetails!C:C, A27, ClubDetails!D:D, B27) | D27: =SUMIFS(ClubDetails!H:H, ClubDetails!C:C, A27, ClubDetails!D:D, B27) | E27: =SUMIFS(ClubDetails!K:K, ClubDetails!C:C, A27, ClubDetails!D:D, B27) | F27: =IF(C27=0, 0, E27/C27) | G27: =SUMIFS(ClubDetails!L:L, ClubDetails!C:C, A27, ClubDetails!D:D, B27) | H27: =IF(C27=0, 0, G27/C27) | I27: =SUMIFS(ClubDetails!J:J, ClubDetails!C:C, A27, ClubDetails!D:D, B27) | J27: =SUMIFS(ClubDetails!M:M, ClubDetails!C:C, A27, ClubDetails!D:D, B27)
A28: C | B28: 03 | C28: =SUMIFS(ClubDetails!G:G, ClubDetails!C:C, A28, ClubDetails!D:D, B28) | D28: =SUMIFS(ClubDetails!H:H, ClubDetails!C:C, A28, ClubDetails!D:D, B28) | E28: =SUMIFS(ClubDetails!K:K, ClubDetails!C:C, A28, ClubDetails!D:D, B28) | F28: =IF(C28=0, 0, E28/C28) | G28: =SUMIFS(ClubDetails!L:L, ClubDetails!C:C, A28, ClubDetails!D:D, B28) | H28: =IF(C28=0, 0, G28/C28) | I28: =SUMIFS(ClubDetails!J:J, ClubDetails!C:C, A28, ClubDetails!D:D, B28) | J28: =SUMIFS(ClubDetails!M:M, ClubDetails!C:C, A28, ClubDetails!D:D, B28)
... A45: G | B45: 04 | C45: =SUMIFS(ClubDetails!G:G, ClubDetails!C:C, A45, ClubDetails!D:D, B45) | D45: =SUMIFS(ClubDetails!H:H, ClubDetails!C:C, A45, ClubDetails!D:D, B45) | E45: =SUMIFS(ClubDetails!K:K, ClubDetails!C:C, A45, ClubDetails!D:D, B45) | F45: =IF(C45=0, 0, E45/C45) | G45: =SUMIFS(ClubDetails!L:L, ClubDetails!C:C, A45, ClubDetails!D:D, B45) | H45: =IF(C45=0, 0, G45/C45) | I45: =SUMIFS(ClubDetails!J:J, ClubDetails!C:C, A45, ClubDetails!D:D, B45) | J45: =SUMIFS(ClubDetails!M:M, ClubDetails!C:C, A45, ClubDetails!D:D, B45)
A46: Area Total | C46: =SUM(C17:C45) | D46: =SUM(D17:D45) | E46: =SUM(E17:E45) | F46: =IF(C46=0, 0, E46/C46) | G46: =SUM(G17:G45) | H46: =IF(C46=0, 0, G46/C46) | I46: =SUM(I17:I45) | J46: =SUM(J17:J45)

Sheet Division 0D
A1: Division 0D - Membership and Payments Performance
A3: Club Number | B3: Area | C3: Club Name | D3: Base Membership | E3: Active Membership | F3: DCP Goals Met | G3: Distinguished Status | H3: September Renewals | I3: September Renewals % | J3: March Renewals | K3: March Renewals % | L3: Total Payments | M3: Total New Members | N3: July | O3: August | P3: September | Q3: October | R3: November | S3: December | T3: January | U3: February | V3: March | W3: April | X3: May | Y3: June | Z3: Smedley Award Eligibility | AA3: Smedley Award Goal | AB3: Talk Up Eligibility | AC3: Talk Up Goal | AD3: Beat the Clock Eligibility | AE3: Beat the Clock Goal
A4: 28679549 | B4: 0A | C4: Vialto Toastmasters Club | D4: =ClubDetails!G2 | E4: =ClubDetails!H2 | F4: =ClubDetails!I2 | G4: =IF(F4<5,"-",IF(E4>19,"Yes",IF(E4>D4+2,"Yes","-"))) | H4: =ClubDetails!K2 | I4: =IF(D4=0,0,H4/D4) | J4: =ClubDetails!L2 | K4: =IF(D4=0,0,J4/D4) | L4: =ClubDetails!M2 | M4: =ClubDetails!J2 | N4: 0 | O4: 0 | P4: 0 | Q4: 0 | R4: 0 | S4: 0 | T4: 0 | U4: 0 | V4: 0 | W4: 0 | X4: 0 | Y4: 0 | Z4: =IF(SUM(O4:P4)>=5,"Yes","No") | AA4: =IF(SUM(O4:P4)>=5,0,5-SUM(O4:P4)) | AB4: =IF(SUM(U4:V4)>=5,"Yes","No") | AC4: =IF(SUM(U4:V4)>=5,0,5-SUM(U4:V4)) | AD4: =IF(SUM(X4:Y4)>=5,"Yes","No") | AE4: =IF(SUM(X4:Y4)>=5,0,5-SUM(X4:Y4))
A5: 28680070 | B5: 0A | C5: Envision India Toastmasters Club | D5: =ClubDetails!G3 | E5: =ClubDetails!H3 | F5: =ClubDetails!I3 | G5: =IF(F5<5,"-",IF(E5>19,"Yes",IF(E5>D5+2,"Yes","-"))) | H5: =ClubDetails!K3 | I5: =IF(D5=0,0,H5/D5) | J5: =ClubDetails!L3 | K5: =IF(D5=0,0,J5/D5) | L5: =ClubDetails!M3 | M5: =ClubDetails!J3 | N5: 0 | O5: 0 | P5: 0 | Q5: 0 | R5: 0 | S5: 0 | T5: 0 | U5: 0 | V5: 0 | W5: 0 | X5: 0 | Y5: 0 | Z5: =IF(SUM(O5:P5)>=5,"Yes","No") | AA5: =IF(SUM(O5:P5)>=5,0,5-SUM(O5:P5)) | AB5: =IF(SUM(U5:V5)>=5,"Yes","No") | AC5: =IF(SUM(U5:V5)>=5,0,5-SUM(U5:V5)) | AD5: =IF(SUM(X5:Y5)>=5,"Yes","No") | AE5: =IF(SUM(X5:Y5)>=5,0,5-SUM(X5:Y5))
A6: 28680152 | B6: 0A | C6: rProcess Toastmasters Club | D6: =ClubDetails!G4 | E6: =ClubDetails!H4 | F6: =ClubDetails!I4 | G6: =IF(F6<5,"-",IF(E6>19,"Yes",IF(E6>D6+2,"Yes","-"))) | H6: =ClubDetails!K4 | I6: =IF(D6=0,0,H6/D6) | J6: =ClubDetails!L4 | K6: =IF(D6=0,0,J6/D6) | L6: =ClubDetails!M4 | M6: =ClubDetails!J4 | N6: 0 | O6: 0 | P6: 0 | Q6: 0 | R6: 0 | S6: 0 | T6: 0 | U6: 0 | V6: 0 | W6: 0 | X6: 0 | Y6: 0 | Z6: =IF(SUM(O6:P6)>=5,"Yes","No") | AA6: =IF(SUM(O6:P6)>=5,0,5-SUM(O6:P6)) | AB6: =IF(SUM(U6:V6)>=5,"Yes","No") | AC6: =IF(SUM(U6:V6)>=5,0,5-SUM(U6:V6)) | AD6: =IF(SUM(X6:Y6)>=5,"Yes","No") | AE6: =IF(SUM(X6:Y6)>=5,0,5-SUM(X6:Y6))
A7: 28680397 | B7: 0A | C7: Uxcel Toastmasters Club | D7: =ClubDetails!G5 | E7: =ClubDetails!H5 | F7: =ClubDetails!I5 | G7: =IF(F7<5,"-",IF(E7>19,"Yes",IF(E7>D7+2,"Yes","-"))) | H7: =ClubDetails!K5 | I7: =IF(D7=0,0,H7/D7) | J7: =ClubDetails!L5 | K7: =IF(D7=0,0,J7/D7) | L7: =ClubDetails!M5 | M7: =ClubDetails!J5 | N7: 0 | O7: 0 | P7: 0 | Q7: 0 | R7: 0 | S7: 0 | T7: 0 | U7: 0 | V7: 0 | W7: 0 | X7: 0 | Y7: 0 | Z7: =IF(SUM(O7:P7)>=5,"Yes","No") | AA7: =IF(SUM(O7:P7)>=5,0,5-SUM(O7:P7)) | AB7: =IF(SUM(U7:V7)>=5,"Yes","No") | AC7: =IF(SUM(U7:V7)>=5,0,5-SUM(U7:V7)) | AD7: =IF(SUM(X7:Y7)>=5,"Yes","No") | AE7: =IF(SUM(X7:Y7)>=5,0,5-SUM(X7:Y7))
A8: 28680500 | B8: 0A | C8: eGov Toastmasters Club | D8: =ClubDetails!G6 | E8: =ClubDetails!H6 | F8: =ClubDetails!I6 | G8: =IF(F8<5,"-",IF(E8>19,"Yes",IF(E8>D8+2,"Yes","-"))) | H8: =ClubDetails!K6 | I8: =IF(D8=0,0,H8/D8) | J8: =ClubDetails!L6 | K8: =IF(D8=0,0,J8/D8) | L8: =ClubDetails!M6 | M8: =ClubDetails!J6 | N8: 0 | O8: 0 | P8: 0 | Q8: 0 | R8: 0 | S8: 0 | T8: 0 | U8: 0 | V8: 0 | W8: 0 | X8: 0 | Y8: 0 | Z8: =IF(SUM(O8:P8)>=5,"Yes","No") | AA8: =IF(SUM(O8:P8)>=5,0,5-SUM(O8:P8)) | AB8: =IF(SUM(U8:V8)>=5,"Yes","No") | AC8: =IF(SUM(U8:V8)>=5,0,5-SUM(U8:V8)) | AD8: =IF(SUM(X8:Y8)>=5,"Yes","No") | AE8: =IF(SUM(X8:Y8)>=5,0,5-SUM(X8:Y8))
A9: Total / Average | D9: =SUM(D4:D8) | E9: =SUM(E4:E8) | F9: =AVERAGE(F4:F8) | G9: =COUNTIF(G4:G8,"Yes") | H9: =SUM(H4:H8) | I9: =IF(D9=0,0,H9/D9) | J9: =SUM(J4:J8) | K9: =IF(D9=0,0,J9/D9) | L9: =SUM(L4:L8) | M9: =SUM(M4:M8) | N9: =SUM(N4:N8) | O9: =SUM(O4:O8) | P9: =SUM(P4:P8) | Q9: =SUM(Q4:Q8) | R9: =SUM(R4:R8) | S9: =SUM(S4:S8) | ... Y9: =SUM(Y4:Y8) | Z9: =COUNTIF(Z4:Z8,"Yes") | AA9: =SUM(AA4:AA8) | AB9: =COUNTIF(AB4:AB8,"Yes") | AC9: =SUM(AC4:AC8) | AD9: =COUNTIF(AD4:AD8,"Yes") | AE9: =SUM(AE4:AE8)

Sheet Division A
A1: Division A - Membership and Payments Performance
A3: Club Number | B3: Area | C3: Club Name | D3: Base Membership | E3: Active Membership | F3: DCP Goals Met | G3: Distinguished Status | H3: September Renewals | I3: September Renewals % | J3: March Renewals | K3: March Renewals % | L3: Total Payments | M3: Total New Members | N3: July | O3: August | P3: September | Q3: October | R3: November | S3: December | T3: January | U3: February | V3: March | W3: April | X3: May | Y3: June | Z3: Smedley Award Eligibility | AA3: Smedley Award Goal | AB3: Talk Up Eligibility | AC3: Talk Up Goal | AD3: Beat the Clock Eligibility | AE3: Beat the Clock Goal
A4: 3803102 | B4: 01 | C4: RESONANCE | D4: =ClubDetails!G7 | E4: =ClubDetails!H7 | F4: =ClubDetails!I7 | G4: =IF(F4<5,"-",IF(E4>19,"Yes",IF(E4>D4+2,"Yes","-"))) | H4: =ClubDetails!K7 | I4: =IF(D4=0,0,H4/D4) | J4: =ClubDetails!L7 | K4: =IF(D4=0,0,J4/D4) | L4: =ClubDetails!M7 | M4: =ClubDetails!J7 | N4: 0 | O4: 0 | P4: 0 | Q4: 0 | R4: 0 | S4: 0 | T4: 0 | U4: 0 | V4: 0 | W4: 0 | X4: 0 | Y4: 0 | Z4: =IF(SUM(O4:P4)>=5,"Yes","No") | AA4: =IF(SUM(O4:P4)>=5,0,5-SUM(O4:P4)) | AB4: =IF(SUM(U4:V4)>=5,"Yes","No") | AC4: =IF(SUM(U4:V4)>=5,0,5-SUM(U4:V4)) | AD4: =IF(SUM(X4:Y4)>=5,"Yes","No") | AE4: =IF(SUM(X4:Y4)>=5,0,5-SUM(X4:Y4))
A5: 28675382 | B5: 01 | C5: INDO-MIM Toastmasters Club | D5: =ClubDetails!G8 | E5: =ClubDetails!H8 | F5: =ClubDetails!I8 | G5: =IF(F5<5,"-",IF(E5>19,"Yes",IF(E5>D5+2,"Yes","-"))) | H5: =ClubDetails!K8 | I5: =IF(D5=0,0,H5/D5) | J5: =ClubDetails!L8 | K5: =IF(D5=0,0,J5/D5) | L5: =ClubDetails!M8 | M5: =ClubDetails!J8 | N5: 0 | O5: 0 | P5: 0 | Q5: 0 | R5: 0 | S5: 0 | T5: 0 | U5: 0 | V5: 0 | W5: 0 | X5: 0 | Y5: 0 | Z5: =IF(SUM(O5:P5)>=5,"Yes","No") | AA5: =IF(SUM(O5:P5)>=5,0,5-SUM(O5:P5)) | AB5: =IF(SUM(U5:V5)>=5,"Yes","No") | AC5: =IF(SUM(U5:V5)>=5,0,5-SUM(U5:V5)) | AD5: =IF(SUM(X5:Y5)>=5,"Yes","No") | AE5: =IF(SUM(X5:Y5)>=5,0,5-SUM(X5:Y5))
A6: 28676720 | B6: 01 | C6: Presidency University Toastmasters Club | D6: =ClubDetails!G9 | E6: =ClubDetails!H9 | F6: =ClubDetails!I9 | G6: =IF(F6<5,"-",IF(E6>19,"Yes",IF(E6>D6+2,"Yes","-"))) | H6: =ClubDetails!K9 | I6: =IF(D6=0,0,H6/D6) | J6: =ClubDetails!L9 | K6: =IF(D6=0,0,J6/D6) | L6: =ClubDetails!M9 | M6: =ClubDetails!J9 | N6: 0 | O6: 0 | P6: 0 | Q6: 0 | R6: 0 | S6: 0 | T6: 0 | U6: 0 | V6: 0 | W6: 0 | X6: 0 | Y6: 0 | Z6: =IF(SUM(O6:P6)>=5,"Yes","No") | AA6: =IF(SUM(O6:P6)>=5,0,5-SUM(O6:P6)) | AB6: =IF(SUM(U6:V6)>=5,"Yes","No") | AC6: =IF(SUM(U6:V6)>=5,0,5-SUM(U6:V6)) | AD6: =IF(SUM(X6:Y6)>=5,"Yes","No") | AE6: =IF(SUM(X6:Y6)>=5,0,5-SUM(X6:Y6))
A7: 28678850 | B7: 01 | C7: Shell STCB Verve | D7: =ClubDetails!G10 | E7: =ClubDetails!H10 | F7: =ClubDetails!I10 | G7: =IF(F7<5,"-",IF(E7>19,"Yes",IF(E7>D7+2,"Yes","-"))) | H7: =ClubDetails!K10 | I7: =IF(D7=0,0,H7/D7) | J7: =ClubDetails!L10 | K7: =IF(D7=0,0,J7/D7) | L7: =ClubDetails!M10 | M7: =ClubDetails!J10 | N7: 0 | O7: 0 | P7: 0 | Q7: 0 | R7: 0 | S7: 0 | T7: 0 | U7: 0 | V7: 0 | W7: 0 | X7: 0 | Y7: 0 | Z7: =IF(SUM(O7:P7)>=5,"Yes","No") | AA7: =IF(SUM(O7:P7)>=5,0,5-SUM(O7:P7)) | AB7: =IF(SUM(U7:V7)>=5,"Yes","No") | AC7: =IF(SUM(U7:V7)>=5,0,5-SUM(U7:V7)) | AD7: =IF(SUM(X7:Y7)>=5,"Yes","No") | AE7: =IF(SUM(X7:Y7)>=5,0,5-SUM(X7:Y7))
A8: 28679352 | B8: 01 | C8: Eden Toastmasters Club | D8: =ClubDetails!G11 | E8: =ClubDetails!H11 | F8: =ClubDetails!I11 | G8: =IF(F8<5,"-",IF(E8>19,"Yes",IF(E8>D8+2,"Yes","-"))) | H8: =ClubDetails!K11 | I8: =IF(D8=0,0,H8/D8) | J8: =ClubDetails!L11 | K8: =IF(D8=0,0,J8/D8) | L8: =ClubDetails!M11 | M8: =ClubDetails!J11 | N8: 0 | O8: 0 | P8: 0 | Q8: 0 | R8: 0 | S8: 0 | T8: 0 | U8: 0 | V8: 0 | W8: 0 | X8: 0 | Y8: 0 | Z8: =IF(SUM(O8:P8)>=5,"Yes","No") | AA8: =IF(SUM(O8:P8)>=5,0,5-SUM(O8:P8)) | AB8: =IF(SUM(U8:V8)>=5,"Yes","No") | AC8: =IF(SUM(U8:V8)>=5,0,5-SUM(U8:V8)) | AD8: =IF(SUM(X8:Y8)>=5,"Yes","No") | AE8: =IF(SUM(X8:Y8)>=5,0,5-SUM(X8:Y8))
A9: 28679508 | B9: 01 | C9: SISA Emerging Orators Circle | D9: =ClubDetails!G12 | E9: =ClubDetails!H12 | F9: =ClubDetails!I12 | G9: =IF(F9<5,"-",IF(E9>19,"Yes",IF(E9>D9+2,"Yes","-"))) | H9: =ClubDetails!K12 | I9: =IF(D9=0,0,H9/D9) | J9: =ClubDetails!L12 | K9: =IF(D9=0,0,J9/D9) | L9: =ClubDetails!M12 | M9: =ClubDetails!J12 | N9: 0 | O9: 0 | P9: 0 | Q9: 0 | R9: 0 | S9: 0 | T9: 0 | U9: 0 | V9: 0 | W9: 0 | X9: 0 | Y9: 0 | Z9: =IF(SUM(O9:P9)>=5,"Yes","No") | AA9: =IF(SUM(O9:P9)>=5,0,5-SUM(O9:P9)) | AB9: =IF(SUM(U9:V9)>=5,"Yes","No") | AC9: =IF(SUM(U9:V9)>=5,0,5-SUM(U9:V9)) | AD9: =IF(SUM(X9:Y9)>=5,"Yes","No") | AE9: =IF(SUM(X9:Y9)>=5,0,5-SUM(X9:Y9))
A10: 2379914 | B10: 02 | C10: Beechi Toastmasters Club | D10: =ClubDetails!G13 | E10: =ClubDetails!H13 | F10: =ClubDetails!I13 | G10: =IF(F10<5,"-",IF(E10>19,"Yes",IF(E10>D10+2,"Yes","-"))) | H10: =ClubDetails!K13 | I10: =IF(D10=0,0,H10/D10) | J10: =ClubDetails!L13 | K10: =IF(D10=0,0,J10/D10) | L10: =ClubDetails!M13 | M10: =ClubDetails!J13 | N10: 0 | O10: 0 | P10: 0 | Q10: 0 | R10: 0 | S10: 0 | T10: 0 | U10: 0 | V10: 0 | W10: 0 | X10: 0 | Y10: 0 | Z10: =IF(SUM(O10:P10)>=5,"Yes","No") | AA10: =IF(SUM(O10:P10)>=5,0,5-SUM(O10:P10)) | AB10: =IF(SUM(U10:V10)>=5,"Yes","No") | AC10: =IF(SUM(U10:V10)>=5,0,5-SUM(U10:V10)) | AD10: =IF(SUM(X10:Y10)>=5,"Yes","No") | AE10: =IF(SUM(X10:Y10)>=5,0,5-SUM(X10:Y10))
A11: 7459390 | B11: 02 | C11: Eloquence AZ | D11: =ClubDetails!G14 | E11: =ClubDetails!H14 | F11: =ClubDetails!I14 | G11: =IF(F11<5,"-",IF(E11>19,"Yes",IF(E11>D11+2,"Yes","-"))) | H11: =ClubDetails!K14 | I11: =IF(D11=0,0,H11/D11) | J11: =ClubDetails!L14 | K11: =IF(D11=0,0,J11/D11) | L11: =ClubDetails!M14 | M11: =ClubDetails!J14 | N11: 0 | O11: 0 | P11: 0 | Q11: 0 | R11: 0 | S11: 0 | T11: 0 | U11: 0 | V11: 0 | W11: 0 | X11: 0 | Y11: 0 | Z11: =IF(SUM(O11:P11)>=5,"Yes","No") | AA11: =IF(SUM(O11:P11)>=5,0,5-SUM(O11:P11)) | AB11: =IF(SUM(U11:V11)>=5,"Yes","No") | AC11: =IF(SUM(U11:V11)>=5,0,5-SUM(U11:V11)) | AD11: =IF(SUM(X11:Y11)>=5,"Yes","No") | AE11: =IF(SUM(X11:Y11)>=5,0,5-SUM(X11:Y11))
A12: 7876884 | B12: 02 | C12: Vidyaranyapura Toastmasters Club | D12: =ClubDetails!G15 | E12: =ClubDetails!H15 | F12: =ClubDetails!I15 | G12: =IF(F12<5,"-",IF(E12>19,"Yes",IF(E12>D12+2,"Yes","-"))) | H12: =ClubDetails!K15 | I12: =IF(D12=0,0,H12/D12) | J12: =ClubDetails!L15 | K12: =IF(D12=0,0,J12/D12) | L12: =ClubDetails!M15 | M12: =ClubDetails!J15 | N12: 0 | O12: 0 | P12: 0 | Q12: 0 | R12: 0 | S12: 0 | T12: 0 | U12: 0 | V12: 0 | W12: 0 | X12: 0 | Y12: 0 | Z12: =IF(SUM(O12:P12)>=5,"Yes","No") | AA12: =IF(SUM(O12:P12)>=5,0,5-SUM(O12:P12)) | AB12: =IF(SUM(U12:V12)>=5,"Yes","No") | AC12: =IF(SUM(U12:V12)>=5,0,5-SUM(U12:V12)) | AD12: =IF(SUM(X12:Y12)>=5,"Yes","No") | AE12: =IF(SUM(X12:Y12)>=5,0,5-SUM(X12:Y12))
A13: 28677738 | B13: 02 | C13: Scarlet Speakers | D13: =ClubDetails!G16 | E13: =ClubDetails!H16 | F13: =ClubDetails!I16 | G13: =IF(F13<5,"-",IF(E13>19,"Yes",IF(E13>D13+2,"Yes","-"))) | H13: =ClubDetails!K16 | I13: =IF(D13=0,0,H13/D13) | J13: =ClubDetails!L16 | K13: =IF(D13=0,0,J13/D13) | L13: =ClubDetails!M16 | M13: =ClubDetails!J16 | N13: 0 | O13: 0 | P13: 0 | Q13: 0 | R13: 0 | S13: 0 | T13: 0 | U13: 0 | V13: 0 | W13: 0 | X13: 0 | Y13: 0 | Z13: =IF(SUM(O13:P13)>=5,"Yes","No") | AA13: =IF(SUM(O13:P13)>=5,0,5-SUM(O13:P13)) | AB13: =IF(SUM(U13:V13)>=5,"Yes","No") | AC13: =IF(SUM(U13:V13)>=5,0,5-SUM(U13:V13)) | AD13: =IF(SUM(X13:Y13)>=5,"Yes","No") | AE13: =IF(SUM(X13:Y13)>=5,0,5-SUM(X13:Y13))
A14: 28679627 | B14: 02 | C14: MAHE Bengaluru Toastmasters Club | D14: =ClubDetails!G17 | E14: =ClubDetails!H17 | F14: =ClubDetails!I17 | G14: =IF(F14<5,"-",IF(E14>19,"Yes",IF(E14>D14+2,"Yes","-"))) | H14: =ClubDetails!K17 | I14: =IF(D14=0,0,H14/D14) | J14: =ClubDetails!L17 | K14: =IF(D14=0,0,J14/D14) | L14: =ClubDetails!M17 | M14: =ClubDetails!J17 | N14: 0 | O14: 0 | P14: 0 | Q14: 0 | R14: 0 | S14: 0 | T14: 0 | U14: 0 | V14: 0 | W14: 0 | X14: 0 | Y14: 0 | Z14: =IF(SUM(O14:P14)>=5,"Yes","No") | AA14: =IF(SUM(O14:P14)>=5,0,5-SUM(O14:P14)) | AB14: =IF(SUM(U14:V14)>=5,"Yes","No") | AC14: =IF(SUM(U14:V14)>=5,0,5-SUM(U14:V14)) | AD14: =IF(SUM(X14:Y14)>=5,"Yes","No") | AE14: =IF(SUM(X14:Y14)>=5,0,5-SUM(X14:Y14))
A15: 2158258 | B15: 03 | C15: Collins Bengaluru Toastmasters Club | D15: =ClubDetails!G18 | E15: =ClubDetails!H18 | F15: =ClubDetails!I18 | G15: =IF(F15<5,"-",IF(E15>19,"Yes",IF(E15>D15+2,"Yes","-"))) | H15: =ClubDetails!K18 | I15: =IF(D15=0,0,H15/D15) | J15: =ClubDetails!L18 | K15: =IF(D15=0,0,J15/D15) | L15: =ClubDetails!M18 | M15: =ClubDetails!J18 | N15: 0 | O15: 0 | P15: 0 | Q15: 0 | R15: 0 | S15: 0 | T15: 0 | U15: 0 | V15: 0 | W15: 0 | X15: 0 | Y15: 0 | Z15: =IF(SUM(O15:P15)>=5,"Yes","No") | AA15: =IF(SUM(O15:P15)>=5,0,5-SUM(O15:P15)) | AB15: =IF(SUM(U15:V15)>=5,"Yes","No") | AC15: =IF(SUM(U15:V15)>=5,0,5-SUM(U15:V15)) | AD15: =IF(SUM(X15:Y15)>=5,"Yes","No") | AE15: =IF(SUM(X15:Y15)>=5,0,5-SUM(X15:Y15))
... A26: 28679188 | B26: 04 | C26: First Citizens India Toastmasters Club | D26: =ClubDetails!G29 | E26: =ClubDetails!H29 | F26: =ClubDetails!I29 | G26: =IF(F26<5,"-",IF(E26>19,"Yes",IF(E26>D26+2,"Yes","-"))) | H26: =ClubDetails!K29 | I26: =IF(D26=0,0,H26/D26) | J26: =ClubDetails!L29 | K26: =IF(D26=0,0,J26/D26) | L26: =ClubDetails!M29 | M26: =ClubDetails!J29 | N26: 0 | O26: 0 | P26: 0 | Q26: 0 | R26: 0 | S26: 0 | T26: 0 | U26: 0 | V26: 0 | W26: 0 | X26: 0 | Y26: 0 | Z26: =IF(SUM(O26:P26)>=5,"Yes","No") | AA26: =IF(SUM(O26:P26)>=5,0,5-SUM(O26:P26)) | AB26: =IF(SUM(U26:V26)>=5,"Yes","No") | AC26: =IF(SUM(U26:V26)>=5,0,5-SUM(U26:V26)) | AD26: =IF(SUM(X26:Y26)>=5,"Yes","No") | AE26: =IF(SUM(X26:Y26)>=5,0,5-SUM(X26:Y26))
A27: Total / Average | D27: =SUM(D4:D26) | E27: =SUM(E4:E26) | F27: =AVERAGE(F4:F26) | G27: =COUNTIF(G4:G26,"Yes") | H27: =SUM(H4:H26) | I27: =IF(D27=0,0,H27/D27) | J27: =SUM(J4:J26) | K27: =IF(D27=0,0,J27/D27) | L27: =SUM(L4:L26) | M27: =SUM(M4:M26) | N27: =SUM(N4:N26) | O27: =SUM(O4:O26) | P27: =SUM(P4:P26) | Q27: =SUM(Q4:Q26) | R27: =SUM(R4:R26) | S27: =SUM(S4:S26) | ... Y27: =SUM(Y4:Y26) | Z27: =COUNTIF(Z4:Z26,"Yes") | AA27: =SUM(AA4:AA26) | AB27: =COUNTIF(AB4:AB26,"Yes") | AC27: =SUM(AC4:AC26) | AD27: =COUNTIF(AD4:AD26,"Yes") | AE27: =SUM(AE4:AE26)

Sheet Division B
A1: Division B - Membership and Payments Performance
A3: Club Number | B3: Area | C3: Club Name | D3: Base Membership | E3: Active Membership | F3: DCP Goals Met | G3: Distinguished Status | H3: September Renewals | I3: September Renewals % | J3: March Renewals | K3: March Renewals % | L3: Total Payments | M3: Total New Members | N3: July | O3: August | P3: September | Q3: October | R3: November | S3: December | T3: January | U3: February | V3: March | W3: April | X3: May | Y3: June | Z3: Smedley Award Eligibility | AA3: Smedley Award Goal | AB3: Talk Up Eligibility | AC3: Talk Up Goal | AD3: Beat the Clock Eligibility | AE3: Beat the Clock Goal
A4: 1766 | B4: 01 | C4: Daffodils Toastmasters Club | D4: =ClubDetails!G30 | E4: =ClubDetails!H30 | F4: =ClubDetails!I30 | G4: =IF(F4<5,"-",IF(E4>19,"Yes",IF(E4>D4+2,"Yes","-"))) | H4: =ClubDetails!K30 | I4: =IF(D4=0,0,H4/D4) | J4: =ClubDetails!L30 | K4: =IF(D4=0,0,J4/D4) | L4: =ClubDetails!M30 | M4: =ClubDetails!J30 | N4: 0 | O4: 0 | P4: 0 | Q4: 0 | R4: 0 | S4: 0 | T4: 0 | U4: 0 | V4: 0 | W4: 0 | X4: 0 | Y4: 0 | Z4: =IF(SUM(O4:P4)>=5,"Yes","No") | AA4: =IF(SUM(O4:P4)>=5,0,5-SUM(O4:P4)) | AB4: =IF(SUM(U4:V4)>=5,"Yes","No") | AC4: =IF(SUM(U4:V4)>=5,0,5-SUM(U4:V4)) | AD4: =IF(SUM(X4:Y4)>=5,"Yes","No") | AE4: =IF(SUM(X4:Y4)>=5,0,5-SUM(X4:Y4))
A5: 1523866 | B5: 01 | C5: Bangalore CA's Toastmasters Club | D5: =ClubDetails!G31 | E5: =ClubDetails!H31 | F5: =ClubDetails!I31 | G5: =IF(F5<5,"-",IF(E5>19,"Yes",IF(E5>D5+2,"Yes","-"))) | H5: =ClubDetails!K31 | I5: =IF(D5=0,0,H5/D5) | J5: =ClubDetails!L31 | K5: =IF(D5=0,0,J5/D5) | L5: =ClubDetails!M31 | M5: =ClubDetails!J31 | N5: 0 | O5: 0 | P5: 0 | Q5: 0 | R5: 0 | S5: 0 | T5: 0 | U5: 0 | V5: 0 | W5: 0 | X5: 0 | Y5: 0 | Z5: =IF(SUM(O5:P5)>=5,"Yes","No") | AA5: =IF(SUM(O5:P5)>=5,0,5-SUM(O5:P5)) | AB5: =IF(SUM(U5:V5)>=5,"Yes","No") | AC5: =IF(SUM(U5:V5)>=5,0,5-SUM(U5:V5)) | AD5: =IF(SUM(X5:Y5)>=5,"Yes","No") | AE5: =IF(SUM(X5:Y5)>=5,0,5-SUM(X5:Y5))
A6: 5856861 | B6: 01 | C6: MCU Toastmasters Club | D6: =ClubDetails!G32 | E6: =ClubDetails!H32 | F6: =ClubDetails!I32 | G6: =IF(F6<5,"-",IF(E6>19,"Yes",IF(E6>D6+2,"Yes","-"))) | H6: =ClubDetails!K32 | I6: =IF(D6=0,0,H6/D6) | J6: =ClubDetails!L32 | K6: =IF(D6=0,0,J6/D6) | L6: =ClubDetails!M32 | M6: =ClubDetails!J32 | N6: 0 | O6: 0 | P6: 0 | Q6: 0 | R6: 0 | S6: 0 | T6: 0 | U6: 0 | V6: 0 | W6: 0 | X6: 0 | Y6: 0 | Z6: =IF(SUM(O6:P6)>=5,"Yes","No") | AA6: =IF(SUM(O6:P6)>=5,0,5-SUM(O6:P6)) | AB6: =IF(SUM(U6:V6)>=5,"Yes","No") | AC6: =IF(SUM(U6:V6)>=5,0,5-SUM(U6:V6)) | AD6: =IF(SUM(X6:Y6)>=5,"Yes","No") | AE6: =IF(SUM(X6:Y6)>=5,0,5-SUM(X6:Y6))
A7: 28675881 | B7: 01 | C7: Atkins Achievers | D7: =ClubDetails!G33 | E7: =ClubDetails!H33 | F7: =ClubDetails!I33 | G7: =IF(F7<5,"-",IF(E7>19,"Yes",IF(E7>D7+2,"Yes","-"))) | H7: =ClubDetails!K33 | I7: =IF(D7=0,0,H7/D7) | J7: =ClubDetails!L33 | K7: =IF(D7=0,0,J7/D7) | L7: =ClubDetails!M33 | M7: =ClubDetails!J33 | N7: 0 | O7: 0 | P7: 0 | Q7: 0 | R7: 0 | S7: 0 | T7: 0 | U7: 0 | V7: 0 | W7: 0 | X7: 0 | Y7: 0 | Z7: =IF(SUM(O7:P7)>=5,"Yes","No") | AA7: =IF(SUM(O7:P7)>=5,0,5-SUM(O7:P7)) | AB7: =IF(SUM(U7:V7)>=5,"Yes","No") | AC7: =IF(SUM(U7:V7)>=5,0,5-SUM(U7:V7)) | AD7: =IF(SUM(X7:Y7)>=5,"Yes","No") | AE7: =IF(SUM(X7:Y7)>=5,0,5-SUM(X7:Y7))
A8: 28679203 | B8: 01 | C8: JLL Bangalore Toastmasters Club | D8: =ClubDetails!G34 | E8: =ClubDetails!H34 | F8: =ClubDetails!I34 | G8: =IF(F8<5,"-",IF(E8>19,"Yes",IF(E8>D8+2,"Yes","-"))) | H8: =ClubDetails!K34 | I8: =IF(D8=0,0,H8/D8) | J8: =ClubDetails!L34 | K8: =IF(D8=0,0,J8/D8) | L8: =ClubDetails!M34 | M8: =ClubDetails!J34 | N8: 0 | O8: 0 | P8: 0 | Q8: 0 | R8: 0 | S8: 0 | T8: 0 | U8: 0 | V8: 0 | W8: 0 | X8: 0 | Y8: 0 | Z8: =IF(SUM(O8:P8)>=5,"Yes","No") | AA8: =IF(SUM(O8:P8)>=5,0,5-SUM(O8:P8)) | AB8: =IF(SUM(U8:V8)>=5,"Yes","No") | AC8: =IF(SUM(U8:V8)>=5,0,5-SUM(U8:V8)) | AD8: =IF(SUM(X8:Y8)>=5,"Yes","No") | AE8: =IF(SUM(X8:Y8)>=5,0,5-SUM(X8:Y8))
A9: 9206 | B9: 02 | C9: BANGALORE TOASTMASTERS CLUB | D9: =ClubDetails!G35 | E9: =ClubDetails!H35 | F9: =ClubDetails!I35 | G9: =IF(F9<5,"-",IF(E9>19,"Yes",IF(E9>D9+2,"Yes","-"))) | H9: =ClubDetails!K35 | I9: =IF(D9=0,0,H9/D9) | J9: =ClubDetails!L35 | K9: =IF(D9=0,0,J9/D9) | L9: =ClubDetails!M35 | M9: =ClubDetails!J35 | N9: 0 | O9: 0 | P9: 0 | Q9: 0 | R9: 0 | S9: 0 | T9: 0 | U9: 0 | V9: 0 | W9: 0 | X9: 0 | Y9: 0 | Z9: =IF(SUM(O9:P9)>=5,"Yes","No") | AA9: =IF(SUM(O9:P9)>=5,0,5-SUM(O9:P9)) | AB9: =IF(SUM(U9:V9)>=5,"Yes","No") | AC9: =IF(SUM(U9:V9)>=5,0,5-SUM(U9:V9)) | AD9: =IF(SUM(X9:Y9)>=5,"Yes","No") | AE9: =IF(SUM(X9:Y9)>=5,0,5-SUM(X9:Y9))
A10: 848580 | B10: 02 | C10: Smedley Speakers Society | D10: =ClubDetails!G36 | E10: =ClubDetails!H36 | F10: =ClubDetails!I36 | G10: =IF(F10<5,"-",IF(E10>19,"Yes",IF(E10>D10+2,"Yes","-"))) | H10: =ClubDetails!K36 | I10: =IF(D10=0,0,H10/D10) | J10: =ClubDetails!L36 | K10: =IF(D10=0,0,J10/D10) | L10: =ClubDetails!M36 | M10: =ClubDetails!J36 | N10: 0 | O10: 0 | P10: 0 | Q10: 0 | R10: 0 | S10: 0 | T10: 0 | U10: 0 | V10: 0 | W10: 0 | X10: 0 | Y10: 0 | Z10: =IF(SUM(O10:P10)>=5,"Yes","No") | AA10: =IF(SUM(O10:P10)>=5,0,5-SUM(O10:P10)) | AB10: =IF(SUM(U10:V10)>=5,"Yes","No") | AC10: =IF(SUM(U10:V10)>=5,0,5-SUM(U10:V10)) | AD10: =IF(SUM(X10:Y10)>=5,"Yes","No") | AE10: =IF(SUM(X10:Y10)>=5,0,5-SUM(X10:Y10))
A11: 4113936 | B11: 02 | C11: Infinera Toastmasters | D11: =ClubDetails!G37 | E11: =ClubDetails!H37 | F11: =ClubDetails!I37 | G11: =IF(F11<5,"-",IF(E11>19,"Yes",IF(E11>D11+2,"Yes","-"))) | H11: =ClubDetails!K37 | I11: =IF(D11=0,0,H11/D11) | J11: =ClubDetails!L37 | K11: =IF(D11=0,0,J11/D11) | L11: =ClubDetails!M37 | M11: =ClubDetails!J37 | N11: 0 | O11: 0 | P11: 0 | Q11: 0 | R11: 0 | S11: 0 | T11: 0 | U11: 0 | V11: 0 | W11: 0 | X11: 0 | Y11: 0 | Z11: =IF(SUM(O11:P11)>=5,"Yes","No") | AA11: =IF(SUM(O11:P11)>=5,0,5-SUM(O11:P11)) | AB11: =IF(SUM(U11:V11)>=5,"Yes","No") | AC11: =IF(SUM(U11:V11)>=5,0,5-SUM(U11:V11)) | AD11: =IF(SUM(X11:Y11)>=5,"Yes","No") | AE11: =IF(SUM(X11:Y11)>=5,0,5-SUM(X11:Y11))
A12: 7738613 | B12: 02 | C12: NITK BHIVE Toastmasters Club | D12: =ClubDetails!G38 | E12: =ClubDetails!H38 | F12: =ClubDetails!I38 | G12: =IF(F12<5,"-",IF(E12>19,"Yes",IF(E12>D12+2,"Yes","-"))) | H12: =ClubDetails!K38 | I12: =IF(D12=0,0,H12/D12) | J12: =ClubDetails!L38 | K12: =IF(D12=0,0,J12/D12) | L12: =ClubDetails!M38 | M12: =ClubDetails!J38 | N12: 0 | O12: 0 | P12: 0 | Q12: 0 | R12: 0 | S12: 0 | T12: 0 | U12: 0 | V12: 0 | W12: 0 | X12: 0 | Y12: 0 | Z12: =IF(SUM(O12:P12)>=5,"Yes","No") | AA12: =IF(SUM(O12:P12)>=5,0,5-SUM(O12:P12)) | AB12: =IF(SUM(U12:V12)>=5,"Yes","No") | AC12: =IF(SUM(U12:V12)>=5,0,5-SUM(U12:V12)) | AD12: =IF(SUM(X12:Y12)>=5,"Yes","No") | AE12: =IF(SUM(X12:Y12)>=5,0,5-SUM(X12:Y12))
A13: 28678039 | B13: 02 | C13: Pure Storage Toastmasters Club | D13: =ClubDetails!G39 | E13: =ClubDetails!H39 | F13: =ClubDetails!I39 | G13: =IF(F13<5,"-",IF(E13>19,"Yes",IF(E13>D13+2,"Yes","-"))) | H13: =ClubDetails!K39 | I13: =IF(D13=0,0,H13/D13) | J13: =ClubDetails!L39 | K13: =IF(D13=0,0,J13/D13) | L13: =ClubDetails!M39 | M13: =ClubDetails!J39 | N13: 0 | O13: 0 | P13: 0 | Q13: 0 | R13: 0 | S13: 0 | T13: 0 | U13: 0 | V13: 0 | W13: 0 | X13: 0 | Y13: 0 | Z13: =IF(SUM(O13:P13)>=5,"Yes","No") | AA13: =IF(SUM(O13:P13)>=5,0,5-SUM(O13:P13)) | AB13: =IF(SUM(U13:V13)>=5,"Yes","No") | AC13: =IF(SUM(U13:V13)>=5,0,5-SUM(U13:V13)) | AD13: =IF(SUM(X13:Y13)>=5,"Yes","No") | AE13: =IF(SUM(X13:Y13)>=5,0,5-SUM(X13:Y13))
A14: 28678473 | B14: 02 | C14: Flexera Toastmasters | D14: =ClubDetails!G40 | E14: =ClubDetails!H40 | F14: =ClubDetails!I40 | G14: =IF(F14<5,"-",IF(E14>19,"Yes",IF(E14>D14+2,"Yes","-"))) | H14: =ClubDetails!K40 | I14: =IF(D14=0,0,H14/D14) | J14: =ClubDetails!L40 | K14: =IF(D14=0,0,J14/D14) | L14: =ClubDetails!M40 | M14: =ClubDetails!J40 | N14: 0 | O14: 0 | P14: 0 | Q14: 0 | R14: 0 | S14: 0 | T14: 0 | U14: 0 | V14: 0 | W14: 0 | X14: 0 | Y14: 0 | Z14: =IF(SUM(O14:P14)>=5,"Yes","No") | AA14: =IF(SUM(O14:P14)>=5,0,5-SUM(O14:P14)) | AB14: =IF(SUM(U14:V14)>=5,"Yes","No") | AC14: =IF(SUM(U14:V14)>=5,0,5-SUM(U14:V14)) | AD14: =IF(SUM(X14:Y14)>=5,"Yes","No") | AE14: =IF(SUM(X14:Y14)>=5,0,5-SUM(X14:Y14))
A15: 9713 | B15: 03 | C15: Sunshine Toastmasters Club | D15: =ClubDetails!G41 | E15: =ClubDetails!H41 | F15: =ClubDetails!I41 | G15: =IF(F15<5,"-",IF(E15>19,"Yes",IF(E15>D15+2,"Yes","-"))) | H15: =ClubDetails!K41 | I15: =IF(D15=0,0,H15/D15) | J15: =ClubDetails!L41 | K15: =IF(D15=0,0,J15/D15) | L15: =ClubDetails!M41 | M15: =ClubDetails!J41 | N15: 0 | O15: 0 | P15: 0 | Q15: 0 | R15: 0 | S15: 0 | T15: 0 | U15: 0 | V15: 0 | W15: 0 | X15: 0 | Y15: 0 | Z15: =IF(SUM(O15:P15)>=5,"Yes","No") | AA15: =IF(SUM(O15:P15)>=5,0,5-SUM(O15:P15)) | AB15: =IF(SUM(U15:V15)>=5,"Yes","No") | AC15: =IF(SUM(U15:V15)>=5,0,5-SUM(U15:V15)) | AD15: =IF(SUM(X15:Y15)>=5,"Yes","No") | AE15: =IF(SUM(X15:Y15)>=5,0,5-SUM(X15:Y15))
... A25: 28679199 | B25: 04 | C25: 360° Toastmasters Club Bengaluru | D25: =ClubDetails!G51 | E25: =ClubDetails!H51 | F25: =ClubDetails!I51 | G25: =IF(F25<5,"-",IF(E25>19,"Yes",IF(E25>D25+2,"Yes","-"))) | H25: =ClubDetails!K51 | I25: =IF(D25=0,0,H25/D25) | J25: =ClubDetails!L51 | K25: =IF(D25=0,0,J25/D25) | L25: =ClubDetails!M51 | M25: =ClubDetails!J51 | N25: 0 | O25: 0 | P25: 0 | Q25: 0 | R25: 0 | S25: 0 | T25: 0 | U25: 0 | V25: 0 | W25: 0 | X25: 0 | Y25: 0 | Z25: =IF(SUM(O25:P25)>=5,"Yes","No") | AA25: =IF(SUM(O25:P25)>=5,0,5-SUM(O25:P25)) | AB25: =IF(SUM(U25:V25)>=5,"Yes","No") | AC25: =IF(SUM(U25:V25)>=5,0,5-SUM(U25:V25)) | AD25: =IF(SUM(X25:Y25)>=5,"Yes","No") | AE25: =IF(SUM(X25:Y25)>=5,0,5-SUM(X25:Y25))
A26: Total / Average | D26: =SUM(D4:D25) | E26: =SUM(E4:E25) | F26: =AVERAGE(F4:F25) | G26: =COUNTIF(G4:G25,"Yes") | H26: =SUM(H4:H25) | I26: =IF(D26=0,0,H26/D26) | J26: =SUM(J4:J25) | K26: =IF(D26=0,0,J26/D26) | L26: =SUM(L4:L25) | M26: =SUM(M4:M25) | N26: =SUM(N4:N25) | O26: =SUM(O4:O25) | P26: =SUM(P4:P25) | Q26: =SUM(Q4:Q25) | R26: =SUM(R4:R25) | S26: =SUM(S4:S25) | ... Y26: =SUM(Y4:Y25) | Z26: =COUNTIF(Z4:Z25,"Yes") | AA26: =SUM(AA4:AA25) | AB26: =COUNTIF(AB4:AB25,"Yes") | AC26: =SUM(AC4:AC25) | AD26: =COUNTIF(AD4:AD25,"Yes") | AE26: =SUM(AE4:AE25)

Sheet Division C
A1: Division C - Membership and Payments Performance
A3: Club Number | B3: Area | C3: Club Name | D3: Base Membership | E3: Active Membership | F3: DCP Goals Met | G3: Distinguished Status | H3: September Renewals | I3: September Renewals % | J3: March Renewals | K3: March Renewals % | L3: Total Payments | M3: Total New Members | N3: July | O3: August | P3: September | Q3: October | R3: November | S3: December | T3: January | U3: February | V3: March | W3: April | X3: May | Y3: June | Z3: Smedley Award Eligibility | AA3: Smedley Award Goal | AB3: Talk Up Eligibility | AC3: Talk Up Goal | AD3: Beat the Clock Eligibility | AE3: Beat the Clock Goal
A4: 631732 | B4: 01 | C4: Mahaveer Speakers Forum Toastmaster Club | D4: =ClubDetails!G52 | E4: =ClubDetails!H52 | F4: =ClubDetails!I52 | G4: =IF(F4<5,"-",IF(E4>19,"Yes",IF(E4>D4+2,"Yes","-"))) | H4: =ClubDetails!K52 | I4: =IF(D4=0,0,H4/D4) | J4: =ClubDetails!L52 | K4: =IF(D4=0,0,J4/D4) | L4: =ClubDetails!M52 | M4: =ClubDetails!J52 | N4: 0 | O4: 0 | P4: 0 | Q4: 0 | R4: 0 | S4: 0 | T4: 0 | U4: 0 | V4: 0 | W4: 0 | X4: 0 | Y4: 0 | Z4: =IF(SUM(O4:P4)>=5,"Yes","No") | AA4: =IF(SUM(O4:P4)>=5,0,5-SUM(O4:P4)) | AB4: =IF(SUM(U4:V4)>=5,"Yes","No") | AC4: =IF(SUM(U4:V4)>=5,0,5-SUM(U4:V4)) | AD4: =IF(SUM(X4:Y4)>=5,"Yes","No") | AE4: =IF(SUM(X4:Y4)>=5,0,5-SUM(X4:Y4))
A5: 632019 | B5: 01 | C5: Jain Speakers Forum Toastmasters Club | D5: =ClubDetails!G53 | E5: =ClubDetails!H53 | F5: =ClubDetails!I53 | G5: =IF(F5<5,"-",IF(E5>19,"Yes",IF(E5>D5+2,"Yes","-"))) | H5: =ClubDetails!K53 | I5: =IF(D5=0,0,H5/D5) | J5: =ClubDetails!L53 | K5: =IF(D5=0,0,J5/D5) | L5: =ClubDetails!M53 | M5: =ClubDetails!J53 | N5: 0 | O5: 0 | P5: 0 | Q5: 0 | R5: 0 | S5: 0 | T5: 0 | U5: 0 | V5: 0 | W5: 0 | X5: 0 | Y5: 0 | Z5: =IF(SUM(O5:P5)>=5,"Yes","No") | AA5: =IF(SUM(O5:P5)>=5,0,5-SUM(O5:P5)) | AB5: =IF(SUM(U5:V5)>=5,"Yes","No") | AC5: =IF(SUM(U5:V5)>=5,0,5-SUM(U5:V5)) | AD5: =IF(SUM(X5:Y5)>=5,"Yes","No") | AE5: =IF(SUM(X5:Y5)>=5,0,5-SUM(X5:Y5))
A6: 843177 | B6: 01 | C6: Talk Master CMS Toastmasters Club | D6: =ClubDetails!G54 | E6: =ClubDetails!H54 | F6: =ClubDetails!I54 | G6: =IF(F6<5,"-",IF(E6>19,"Yes",IF(E6>D6+2,"Yes","-"))) | H6: =ClubDetails!K54 | I6: =IF(D6=0,0,H6/D6) | J6: =ClubDetails!L54 | K6: =IF(D6=0,0,J6/D6) | L6: =ClubDetails!M54 | M6: =ClubDetails!J54 | N6: 0 | O6: 0 | P6: 0 | Q6: 0 | R6: 0 | S6: 0 | T6: 0 | U6: 0 | V6: 0 | W6: 0 | X6: 0 | Y6: 0 | Z6: =IF(SUM(O6:P6)>=5,"Yes","No") | AA6: =IF(SUM(O6:P6)>=5,0,5-SUM(O6:P6)) | AB6: =IF(SUM(U6:V6)>=5,"Yes","No") | AC6: =IF(SUM(U6:V6)>=5,0,5-SUM(U6:V6)) | AD6: =IF(SUM(X6:Y6)>=5,"Yes","No") | AE6: =IF(SUM(X6:Y6)>=5,0,5-SUM(X6:Y6))
A7: 843182 | B7: 01 | C7: Speech Master CMS Toastmasters Club | D7: =ClubDetails!G55 | E7: =ClubDetails!H55 | F7: =ClubDetails!I55 | G7: =IF(F7<5,"-",IF(E7>19,"Yes",IF(E7>D7+2,"Yes","-"))) | H7: =ClubDetails!K55 | I7: =IF(D7=0,0,H7/D7) | J7: =ClubDetails!L55 | K7: =IF(D7=0,0,J7/D7) | L7: =ClubDetails!M55 | M7: =ClubDetails!J55 | N7: 0 | O7: 0 | P7: 0 | Q7: 0 | R7: 0 | S7: 0 | T7: 0 | U7: 0 | V7: 0 | W7: 0 | X7: 0 | Y7: 0 | Z7: =IF(SUM(O7:P7)>=5,"Yes","No") | AA7: =IF(SUM(O7:P7)>=5,0,5-SUM(O7:P7)) | AB7: =IF(SUM(U7:V7)>=5,"Yes","No") | AC7: =IF(SUM(U7:V7)>=5,0,5-SUM(U7:V7)) | AD7: =IF(SUM(X7:Y7)>=5,"Yes","No") | AE7: =IF(SUM(X7:Y7)>=5,0,5-SUM(X7:Y7))
A8: 3926170 | B8: 02 | C8: Textron India Toastmasters Club | D8: =ClubDetails!G56 | E8: =ClubDetails!H56 | F8: =ClubDetails!I56 | G8: =IF(F8<5,"-",IF(E8>19,"Yes",IF(E8>D8+2,"Yes","-"))) | H8: =ClubDetails!K56 | I8: =IF(D8=0,0,H8/D8) | J8: =ClubDetails!L56 | K8: =IF(D8=0,0,J8/D8) | L8: =ClubDetails!M56 | M8: =ClubDetails!J56 | N8: 0 | O8: 0 | P8: 0 | Q8: 0 | R8: 0 | S8: 0 | T8: 0 | U8: 0 | V8: 0 | W8: 0 | X8: 0 | Y8: 0 | Z8: =IF(SUM(O8:P8)>=5,"Yes","No") | AA8: =IF(SUM(O8:P8)>=5,0,5-SUM(O8:P8)) | AB8: =IF(SUM(U8:V8)>=5,"Yes","No") | AC8: =IF(SUM(U8:V8)>=5,0,5-SUM(U8:V8)) | AD8: =IF(SUM(X8:Y8)>=5,"Yes","No") | AE8: =IF(SUM(X8:Y8)>=5,0,5-SUM(X8:Y8))
A9: 6479232 | B9: 02 | C9: Mphasis Speech Crafters | D9: =ClubDetails!G57 | E9: =ClubDetails!H57 | F9: =ClubDetails!I57 | G9: =IF(F9<5,"-",IF(E9>19,"Yes",IF(E9>D9+2,"Yes","-"))) | H9: =ClubDetails!K57 | I9: =IF(D9=0,0,H9/D9) | J9: =ClubDetails!L57 | K9: =IF(D9=0,0,J9/D9) | L9: =ClubDetails!M57 | M9: =ClubDetails!J57 | N9: 0 | O9: 0 | P9: 0 | Q9: 0 | R9: 0 | S9: 0 | T9: 0 | U9: 0 | V9: 0 | W9: 0 | X9: 0 | Y9: 0 | Z9: =IF(SUM(O9:P9)>=5,"Yes","No") | AA9: =IF(SUM(O9:P9)>=5,0,5-SUM(O9:P9)) | AB9: =IF(SUM(U9:V9)>=5,"Yes","No") | AC9: =IF(SUM(U9:V9)>=5,0,5-SUM(U9:V9)) | AD9: =IF(SUM(X9:Y9)>=5,"Yes","No") | AE9: =IF(SUM(X9:Y9)>=5,0,5-SUM(X9:Y9))
A10: 7991317 | B10: 02 | C10: Eloquence Elixir Toastmasters | D10: =ClubDetails!G58 | E10: =ClubDetails!H58 | F10: =ClubDetails!I58 | G10: =IF(F10<5,"-",IF(E10>19,"Yes",IF(E10>D10+2,"Yes","-"))) | H10: =ClubDetails!K58 | I10: =IF(D10=0,0,H10/D10) | J10: =ClubDetails!L58 | K10: =IF(D10=0,0,J10/D10) | L10: =ClubDetails!M58 | M10: =ClubDetails!J58 | N10: 0 | O10: 0 | P10: 0 | Q10: 0 | R10: 0 | S10: 0 | T10: 0 | U10: 0 | V10: 0 | W10: 0 | X10: 0 | Y10: 0 | Z10: =IF(SUM(O10:P10)>=5,"Yes","No") | AA10: =IF(SUM(O10:P10)>=5,0,5-SUM(O10:P10)) | AB10: =IF(SUM(U10:V10)>=5,"Yes","No") | AC10: =IF(SUM(U10:V10)>=5,0,5-SUM(U10:V10)) | AD10: =IF(SUM(X10:Y10)>=5,"Yes","No") | AE10: =IF(SUM(X10:Y10)>=5,0,5-SUM(X10:Y10))
A11: 28676363 | B11: 02 | C11: Nagarabhavi Toastmasters Club | D11: =ClubDetails!G59 | E11: =ClubDetails!H59 | F11: =ClubDetails!I59 | G11: =IF(F11<5,"-",IF(E11>19,"Yes",IF(E11>D11+2,"Yes","-"))) | H11: =ClubDetails!K59 | I11: =IF(D11=0,0,H11/D11) | J11: =ClubDetails!L59 | K11: =IF(D11=0,0,J11/D11) | L11: =ClubDetails!M59 | M11: =ClubDetails!J59 | N11: 0 | O11: 0 | P11: 0 | Q11: 0 | R11: 0 | S11: 0 | T11: 0 | U11: 0 | V11: 0 | W11: 0 | X11: 0 | Y11: 0 | Z11: =IF(SUM(O11:P11)>=5,"Yes","No") | AA11: =IF(SUM(O11:P11)>=5,0,5-SUM(O11:P11)) | AB11: =IF(SUM(U11:V11)>=5,"Yes","No") | AC11: =IF(SUM(U11:V11)>=5,0,5-SUM(U11:V11)) | AD11: =IF(SUM(X11:Y11)>=5,"Yes","No") | AE11: =IF(SUM(X11:Y11)>=5,0,5-SUM(X11:Y11))
A12: 28677190 | B12: 02 | C12: Christ Kengeri Club | D12: =ClubDetails!G60 | E12: =ClubDetails!H60 | F12: =ClubDetails!I60 | G12: =IF(F12<5,"-",IF(E12>19,"Yes",IF(E12>D12+2,"Yes","-"))) | H12: =ClubDetails!K60 | I12: =IF(D12=0,0,H12/D12) | J12: =ClubDetails!L60 | K12: =IF(D12=0,0,J12/D12) | L12: =ClubDetails!M60 | M12: =ClubDetails!J60 | N12: 0 | O12: 0 | P12: 0 | Q12: 0 | R12: 0 | S12: 0 | T12: 0 | U12: 0 | V12: 0 | W12: 0 | X12: 0 | Y12: 0 | Z12: =IF(SUM(O12:P12)>=5,"Yes","No") | AA12: =IF(SUM(O12:P12)>=5,0,5-SUM(O12:P12)) | AB12: =IF(SUM(U12:V12)>=5,"Yes","No") | AC12: =IF(SUM(U12:V12)>=5,0,5-SUM(U12:V12)) | AD12: =IF(SUM(X12:Y12)>=5,"Yes","No") | AE12: =IF(SUM(X12:Y12)>=5,0,5-SUM(X12:Y12))
A13: 3793772 | B13: 03 | C13: Utthishta Toastmasters | D13: =ClubDetails!G61 | E13: =ClubDetails!H61 | F13: =ClubDetails!I61 | G13: =IF(F13<5,"-",IF(E13>19,"Yes",IF(E13>D13+2,"Yes","-"))) | H13: =ClubDetails!K61 | I13: =IF(D13=0,0,H13/D13) | J13: =ClubDetails!L61 | K13: =IF(D13=0,0,J13/D13) | L13: =ClubDetails!M61 | M13: =ClubDetails!J61 | N13: 0 | O13: 0 | P13: 0 | Q13: 0 | R13: 0 | S13: 0 | T13: 0 | U13: 0 | V13: 0 | W13: 0 | X13: 0 | Y13: 0 | Z13: =IF(SUM(O13:P13)>=5,"Yes","No") | AA13: =IF(SUM(O13:P13)>=5,0,5-SUM(O13:P13)) | AB13: =IF(SUM(U13:V13)>=5,"Yes","No") | AC13: =IF(SUM(U13:V13)>=5,0,5-SUM(U13:V13)) | AD13: =IF(SUM(X13:Y13)>=5,"Yes","No") | AE13: =IF(SUM(X13:Y13)>=5,0,5-SUM(X13:Y13))
A14: 6714857 | B14: 03 | C14: Galaxy Toastmasters Club | D14: =ClubDetails!G62 | E14: =ClubDetails!H62 | F14: =ClubDetails!I62 | G14: =IF(F14<5,"-",IF(E14>19,"Yes",IF(E14>D14+2,"Yes","-"))) | H14: =ClubDetails!K62 | I14: =IF(D14=0,0,H14/D14) | J14: =ClubDetails!L62 | K14: =IF(D14=0,0,J14/D14) | L14: =ClubDetails!M62 | M14: =ClubDetails!J62 | N14: 0 | O14: 0 | P14: 0 | Q14: 0 | R14: 0 | S14: 0 | T14: 0 | U14: 0 | V14: 0 | W14: 0 | X14: 0 | Y14: 0 | Z14: =IF(SUM(O14:P14)>=5,"Yes","No") | AA14: =IF(SUM(O14:P14)>=5,0,5-SUM(O14:P14)) | AB14: =IF(SUM(U14:V14)>=5,"Yes","No") | AC14: =IF(SUM(U14:V14)>=5,0,5-SUM(U14:V14)) | AD14: =IF(SUM(X14:Y14)>=5,"Yes","No") | AE14: =IF(SUM(X14:Y14)>=5,0,5-SUM(X14:Y14))
A15: 7915396 | B15: 03 | C15: Rajajinagar Toastmasters Club | D15: =ClubDetails!G63 | E15: =ClubDetails!H63 | F15: =ClubDetails!I63 | G15: =IF(F15<5,"-",IF(E15>19,"Yes",IF(E15>D15+2,"Yes","-"))) | H15: =ClubDetails!K63 | I15: =IF(D15=0,0,H15/D15) | J15: =ClubDetails!L63 | K15: =IF(D15=0,0,J15/D15) | L15: =ClubDetails!M63 | M15: =ClubDetails!J63 | N15: 0 | O15: 0 | P15: 0 | Q15: 0 | R15: 0 | S15: 0 | T15: 0 | U15: 0 | V15: 0 | W15: 0 | X15: 0 | Y15: 0 | Z15: =IF(SUM(O15:P15)>=5,"Yes","No") | AA15: =IF(SUM(O15:P15)>=5,0,5-SUM(O15:P15)) | AB15: =IF(SUM(U15:V15)>=5,"Yes","No") | AC15: =IF(SUM(U15:V15)>=5,0,5-SUM(U15:V15)) | AD15: =IF(SUM(X15:Y15)>=5,"Yes","No") | AE15: =IF(SUM(X15:Y15)>=5,0,5-SUM(X15:Y15))
... A22: 28679581 | B22: 04 | C22: Movius Toastmasters Club | D22: =ClubDetails!G70 | E22: =ClubDetails!H70 | F22: =ClubDetails!I70 | G22: =IF(F22<5,"-",IF(E22>19,"Yes",IF(E22>D22+2,"Yes","-"))) | H22: =ClubDetails!K70 | I22: =IF(D22=0,0,H22/D22) | J22: =ClubDetails!L70 | K22: =IF(D22=0,0,J22/D22) | L22: =ClubDetails!M70 | M22: =ClubDetails!J70 | N22: 0 | O22: 0 | P22: 0 | Q22: 0 | R22: 0 | S22: 0 | T22: 0 | U22: 0 | V22: 0 | W22: 0 | X22: 0 | Y22: 0 | Z22: =IF(SUM(O22:P22)>=5,"Yes","No") | AA22: =IF(SUM(O22:P22)>=5,0,5-SUM(O22:P22)) | AB22: =IF(SUM(U22:V22)>=5,"Yes","No") | AC22: =IF(SUM(U22:V22)>=5,0,5-SUM(U22:V22)) | AD22: =IF(SUM(X22:Y22)>=5,"Yes","No") | AE22: =IF(SUM(X22:Y22)>=5,0,5-SUM(X22:Y22))
A23: Total / Average | D23: =SUM(D4:D22) | E23: =SUM(E4:E22) | F23: =AVERAGE(F4:F22) | G23: =COUNTIF(G4:G22,"Yes") | H23: =SUM(H4:H22) | I23: =IF(D23=0,0,H23/D23) | J23: =SUM(J4:J22) | K23: =IF(D23=0,0,J23/D23) | L23: =SUM(L4:L22) | M23: =SUM(M4:M22) | N23: =SUM(N4:N22) | O23: =SUM(O4:O22) | P23: =SUM(P4:P22) | Q23: =SUM(Q4:Q22) | R23: =SUM(R4:R22) | S23: =SUM(S4:S22) | ... Y23: =SUM(Y4:Y22) | Z23: =COUNTIF(Z4:Z22,"Yes") | AA23: =SUM(AA4:AA22) | AB23: =COUNTIF(AB4:AB22,"Yes") | AC23: =SUM(AC4:AC22) | AD23: =COUNTIF(AD4:AD22,"Yes") | AE23: =SUM(AE4:AE22)

Sheet Division D
A1: Division D - Membership and Payments Performance
A3: Club Number | B3: Area | C3: Club Name | D3: Base Membership | E3: Active Membership | F3: DCP Goals Met | G3: Distinguished Status | H3: September Renewals | I3: September Renewals % | J3: March Renewals | K3: March Renewals % | L3: Total Payments | M3: Total New Members | N3: July | O3: August | P3: September | Q3: October | R3: November | S3: December | T3: January | U3: February | V3: March | W3: April | X3: May | Y3: June | Z3: Smedley Award Eligibility | AA3: Smedley Award Goal | AB3: Talk Up Eligibility | AC3: Talk Up Goal | AD3: Beat the Clock Eligibility | AE3: Beat the Clock Goal
A4: 2188958 | B4: 01 | C4: Koramangala Toastmasters Club | D4: =ClubDetails!G71 | E4: =ClubDetails!H71 | F4: =ClubDetails!I71 | G4: =IF(F4<5,"-",IF(E4>19,"Yes",IF(E4>D4+2,"Yes","-"))) | H4: =ClubDetails!K71 | I4: =IF(D4=0,0,H4/D4) | J4: =ClubDetails!L71 | K4: =IF(D4=0,0,J4/D4) | L4: =ClubDetails!M71 | M4: =ClubDetails!J71 | N4: 0 | O4: 0 | P4: 0 | Q4: 0 | R4: 0 | S4: 0 | T4: 0 | U4: 0 | V4: 0 | W4: 0 | X4: 0 | Y4: 0 | Z4: =IF(SUM(O4:P4)>=5,"Yes","No") | AA4: =IF(SUM(O4:P4)>=5,0,5-SUM(O4:P4)) | AB4: =IF(SUM(U4:V4)>=5,"Yes","No") | AC4: =IF(SUM(U4:V4)>=5,0,5-SUM(U4:V4)) | AD4: =IF(SUM(X4:Y4)>=5,"Yes","No") | AE4: =IF(SUM(X4:Y4)>=5,0,5-SUM(X4:Y4))
A5: 5868577 | B5: 01 | C5: Bosch Raconteurs | D5: =ClubDetails!G72 | E5: =ClubDetails!H72 | F5: =ClubDetails!I72 | G5: =IF(F5<5,"-",IF(E5>19,"Yes",IF(E5>D5+2,"Yes","-"))) | H5: =ClubDetails!K72 | I5: =IF(D5=0,0,H5/D5) | J5: =ClubDetails!L72 | K5: =IF(D5=0,0,J5/D5) | L5: =ClubDetails!M72 | M5: =ClubDetails!J72 | N5: 0 | O5: 0 | P5: 0 | Q5: 0 | R5: 0 | S5: 0 | T5: 0 | U5: 0 | V5: 0 | W5: 0 | X5: 0 | Y5: 0 | Z5: =IF(SUM(O5:P5)>=5,"Yes","No") | AA5: =IF(SUM(O5:P5)>=5,0,5-SUM(O5:P5)) | AB5: =IF(SUM(U5:V5)>=5,"Yes","No") | AC5: =IF(SUM(U5:V5)>=5,0,5-SUM(U5:V5)) | AD5: =IF(SUM(X5:Y5)>=5,"Yes","No") | AE5: =IF(SUM(X5:Y5)>=5,0,5-SUM(X5:Y5))
A6: 28676014 | B6: 01 | C6: Autodesk Toastmasters Club | D6: =ClubDetails!G73 | E6: =ClubDetails!H73 | F6: =ClubDetails!I73 | G6: =IF(F6<5,"-",IF(E6>19,"Yes",IF(E6>D6+2,"Yes","-"))) | H6: =ClubDetails!K73 | I6: =IF(D6=0,0,H6/D6) | J6: =ClubDetails!L73 | K6: =IF(D6=0,0,J6/D6) | L6: =ClubDetails!M73 | M6: =ClubDetails!J73 | N6: 0 | O6: 0 | P6: 0 | Q6: 0 | R6: 0 | S6: 0 | T6: 0 | U6: 0 | V6: 0 | W6: 0 | X6: 0 | Y6: 0 | Z6: =IF(SUM(O6:P6)>=5,"Yes","No") | AA6: =IF(SUM(O6:P6)>=5,0,5-SUM(O6:P6)) | AB6: =IF(SUM(U6:V6)>=5,"Yes","No") | AC6: =IF(SUM(U6:V6)>=5,0,5-SUM(U6:V6)) | AD6: =IF(SUM(X6:Y6)>=5,"Yes","No") | AE6: =IF(SUM(X6:Y6)>=5,0,5-SUM(X6:Y6))
A7: 28676901 | B7: 01 | C7: Accenture Toasters | D7: =ClubDetails!G74 | E7: =ClubDetails!H74 | F7: =ClubDetails!I74 | G7: =IF(F7<5,"-",IF(E7>19,"Yes",IF(E7>D7+2,"Yes","-"))) | H7: =ClubDetails!K74 | I7: =IF(D7=0,0,H7/D7) | J7: =ClubDetails!L74 | K7: =IF(D7=0,0,J7/D7) | L7: =ClubDetails!M74 | M7: =ClubDetails!J74 | N7: 0 | O7: 0 | P7: 0 | Q7: 0 | R7: 0 | S7: 0 | T7: 0 | U7: 0 | V7: 0 | W7: 0 | X7: 0 | Y7: 0 | Z7: =IF(SUM(O7:P7)>=5,"Yes","No") | AA7: =IF(SUM(O7:P7)>=5,0,5-SUM(O7:P7)) | AB7: =IF(SUM(U7:V7)>=5,"Yes","No") | AC7: =IF(SUM(U7:V7)>=5,0,5-SUM(U7:V7)) | AD7: =IF(SUM(X7:Y7)>=5,"Yes","No") | AE7: =IF(SUM(X7:Y7)>=5,0,5-SUM(X7:Y7))
A8: 28678701 | B8: 01 | C8: Tavant Speakers Club | D8: =ClubDetails!G75 | E8: =ClubDetails!H75 | F8: =ClubDetails!I75 | G8: =IF(F8<5,"-",IF(E8>19,"Yes",IF(E8>D8+2,"Yes","-"))) | H8: =ClubDetails!K75 | I8: =IF(D8=0,0,H8/D8) | J8: =ClubDetails!L75 | K8: =IF(D8=0,0,J8/D8) | L8: =ClubDetails!M75 | M8: =ClubDetails!J75 | N8: 0 | O8: 0 | P8: 0 | Q8: 0 | R8: 0 | S8: 0 | T8: 0 | U8: 0 | V8: 0 | W8: 0 | X8: 0 | Y8: 0 | Z8: =IF(SUM(O8:P8)>=5,"Yes","No") | AA8: =IF(SUM(O8:P8)>=5,0,5-SUM(O8:P8)) | AB8: =IF(SUM(U8:V8)>=5,"Yes","No") | AC8: =IF(SUM(U8:V8)>=5,0,5-SUM(U8:V8)) | AD8: =IF(SUM(X8:Y8)>=5,"Yes","No") | AE8: =IF(SUM(X8:Y8)>=5,0,5-SUM(X8:Y8))
A9: 9639 | B9: 02 | C9: Mecon Communication Club | D9: =ClubDetails!G76 | E9: =ClubDetails!H76 | F9: =ClubDetails!I76 | G9: =IF(F9<5,"-",IF(E9>19,"Yes",IF(E9>D9+2,"Yes","-"))) | H9: =ClubDetails!K76 | I9: =IF(D9=0,0,H9/D9) | J9: =ClubDetails!L76 | K9: =IF(D9=0,0,J9/D9) | L9: =ClubDetails!M76 | M9: =ClubDetails!J76 | N9: 0 | O9: 0 | P9: 0 | Q9: 0 | R9: 0 | S9: 0 | T9: 0 | U9: 0 | V9: 0 | W9: 0 | X9: 0 | Y9: 0 | Z9: =IF(SUM(O9:P9)>=5,"Yes","No") | AA9: =IF(SUM(O9:P9)>=5,0,5-SUM(O9:P9)) | AB9: =IF(SUM(U9:V9)>=5,"Yes","No") | AC9: =IF(SUM(U9:V9)>=5,0,5-SUM(U9:V9)) | AD9: =IF(SUM(X9:Y9)>=5,"Yes","No") | AE9: =IF(SUM(X9:Y9)>=5,0,5-SUM(X9:Y9))
A10: 4329635 | B10: 02 | C10: Tarento India Toastmasters Club | D10: =ClubDetails!G77 | E10: =ClubDetails!H77 | F10: =ClubDetails!I77 | G10: =IF(F10<5,"-",IF(E10>19,"Yes",IF(E10>D10+2,"Yes","-"))) | H10: =ClubDetails!K77 | I10: =IF(D10=0,0,H10/D10) | J10: =ClubDetails!L77 | K10: =IF(D10=0,0,J10/D10) | L10: =ClubDetails!M77 | M10: =ClubDetails!J77 | N10: 0 | O10: 0 | P10: 0 | Q10: 0 | R10: 0 | S10: 0 | T10: 0 | U10: 0 | V10: 0 | W10: 0 | X10: 0 | Y10: 0 | Z10: =IF(SUM(O10:P10)>=5,"Yes","No") | AA10: =IF(SUM(O10:P10)>=5,0,5-SUM(O10:P10)) | AB10: =IF(SUM(U10:V10)>=5,"Yes","No") | AC10: =IF(SUM(U10:V10)>=5,0,5-SUM(U10:V10)) | AD10: =IF(SUM(X10:Y10)>=5,"Yes","No") | AE10: =IF(SUM(X10:Y10)>=5,0,5-SUM(X10:Y10))
A11: 7734175 | B11: 02 | C11: Republic of Toastmasters | D11: =ClubDetails!G78 | E11: =ClubDetails!H78 | F11: =ClubDetails!I78 | G11: =IF(F11<5,"-",IF(E11>19,"Yes",IF(E11>D11+2,"Yes","-"))) | H11: =ClubDetails!K78 | I11: =IF(D11=0,0,H11/D11) | J11: =ClubDetails!L78 | K11: =IF(D11=0,0,J11/D11) | L11: =ClubDetails!M78 | M11: =ClubDetails!J78 | N11: 0 | O11: 0 | P11: 0 | Q11: 0 | R11: 0 | S11: 0 | T11: 0 | U11: 0 | V11: 0 | W11: 0 | X11: 0 | Y11: 0 | Z11: =IF(SUM(O11:P11)>=5,"Yes","No") | AA11: =IF(SUM(O11:P11)>=5,0,5-SUM(O11:P11)) | AB11: =IF(SUM(U11:V11)>=5,"Yes","No") | AC11: =IF(SUM(U11:V11)>=5,0,5-SUM(U11:V11)) | AD11: =IF(SUM(X11:Y11)>=5,"Yes","No") | AE11: =IF(SUM(X11:Y11)>=5,0,5-SUM(X11:Y11))
A12: 28676900 | B12: 02 | C12: Acuity Toastmasters Open Mic | D12: =ClubDetails!G79 | E12: =ClubDetails!H79 | F12: =ClubDetails!I79 | G12: =IF(F12<5,"-",IF(E12>19,"Yes",IF(E12>D12+2,"Yes","-"))) | H12: =ClubDetails!K79 | I12: =IF(D12=0,0,H12/D12) | J12: =ClubDetails!L79 | K12: =IF(D12=0,0,J12/D12) | L12: =ClubDetails!M79 | M12: =ClubDetails!J79 | N12: 0 | O12: 0 | P12: 0 | Q12: 0 | R12: 0 | S12: 0 | T12: 0 | U12: 0 | V12: 0 | W12: 0 | X12: 0 | Y12: 0 | Z12: =IF(SUM(O12:P12)>=5,"Yes","No") | AA12: =IF(SUM(O12:P12)>=5,0,5-SUM(O12:P12)) | AB12: =IF(SUM(U12:V12)>=5,"Yes","No") | AC12: =IF(SUM(U12:V12)>=5,0,5-SUM(U12:V12)) | AD12: =IF(SUM(X12:Y12)>=5,"Yes","No") | AE12: =IF(SUM(X12:Y12)>=5,0,5-SUM(X12:Y12))
A13: 28677046 | B13: 02 | C13: Bosch Adugodi | D13: =ClubDetails!G80 | E13: =ClubDetails!H80 | F13: =ClubDetails!I80 | G13: =IF(F13<5,"-",IF(E13>19,"Yes",IF(E13>D13+2,"Yes","-"))) | H13: =ClubDetails!K80 | I13: =IF(D13=0,0,H13/D13) | J13: =ClubDetails!L80 | K13: =IF(D13=0,0,J13/D13) | L13: =ClubDetails!M80 | M13: =ClubDetails!J80 | N13: 0 | O13: 0 | P13: 0 | Q13: 0 | R13: 0 | S13: 0 | T13: 0 | U13: 0 | V13: 0 | W13: 0 | X13: 0 | Y13: 0 | Z13: =IF(SUM(O13:P13)>=5,"Yes","No") | AA13: =IF(SUM(O13:P13)>=5,0,5-SUM(O13:P13)) | AB13: =IF(SUM(U13:V13)>=5,"Yes","No") | AC13: =IF(SUM(U13:V13)>=5,0,5-SUM(U13:V13)) | AD13: =IF(SUM(X13:Y13)>=5,"Yes","No") | AE13: =IF(SUM(X13:Y13)>=5,0,5-SUM(X13:Y13))
A14: 28678720 | B14: 02 | C14: Acharyas Speaking Forum | D14: =ClubDetails!G81 | E14: =ClubDetails!H81 | F14: =ClubDetails!I81 | G14: =IF(F14<5,"-",IF(E14>19,"Yes",IF(E14>D14+2,"Yes","-"))) | H14: =ClubDetails!K81 | I14: =IF(D14=0,0,H14/D14) | J14: =ClubDetails!L81 | K14: =IF(D14=0,0,J14/D14) | L14: =ClubDetails!M81 | M14: =ClubDetails!J81 | N14: 0 | O14: 0 | P14: 0 | Q14: 0 | R14: 0 | S14: 0 | T14: 0 | U14: 0 | V14: 0 | W14: 0 | X14: 0 | Y14: 0 | Z14: =IF(SUM(O14:P14)>=5,"Yes","No") | AA14: =IF(SUM(O14:P14)>=5,0,5-SUM(O14:P14)) | AB14: =IF(SUM(U14:V14)>=5,"Yes","No") | AC14: =IF(SUM(U14:V14)>=5,0,5-SUM(U14:V14)) | AD14: =IF(SUM(X14:Y14)>=5,"Yes","No") | AE14: =IF(SUM(X14:Y14)>=5,0,5-SUM(X14:Y14))
A15: 28678997 | B15: 02 | C15: Paychex Catalyst Crew 2 | D15: =ClubDetails!G82 | E15: =ClubDetails!H82 | F15: =ClubDetails!I82 | G15: =IF(F15<5,"-",IF(E15>19,"Yes",IF(E15>D15+2,"Yes","-"))) | H15: =ClubDetails!K82 | I15: =IF(D15=0,0,H15/D15) | J15: =ClubDetails!L82 | K15: =IF(D15=0,0,J15/D15) | L15: =ClubDetails!M82 | M15: =ClubDetails!J82 | N15: 0 | O15: 0 | P15: 0 | Q15: 0 | R15: 0 | S15: 0 | T15: 0 | U15: 0 | V15: 0 | W15: 0 | X15: 0 | Y15: 0 | Z15: =IF(SUM(O15:P15)>=5,"Yes","No") | AA15: =IF(SUM(O15:P15)>=5,0,5-SUM(O15:P15)) | AB15: =IF(SUM(U15:V15)>=5,"Yes","No") | AC15: =IF(SUM(U15:V15)>=5,0,5-SUM(U15:V15)) | AD15: =IF(SUM(X15:Y15)>=5,"Yes","No") | AE15: =IF(SUM(X15:Y15)>=5,0,5-SUM(X15:Y15))
