Workbook

Sheet District
A1: District 121 Performance Dashboard
A2: Membership, Payments & Club Recognition Goals
A4: Payments Goals | D4: Clubs Goals | G4: Distinguished Clubs Goals
A5: Base Payments | B5: 8634 | D5: Base Clubs | E5: 174 | G5: Distinguished Clubs Prereq | H5: 0
A6: Distinguished | B6: =ROUND(B5*1.01, 0) | D6: Distinguished | E6: =E5 | G6: Distinguished | H6: =ROUND(0.4*E5, 0)
A7: Select Distinguished | B7: =ROUND(B5*1.03, 0) | D7: Select Distinguished | E7: 184 | G7: Select Distinguished | H7: 89
A8: President's Distinguished | B8: =ROUND(B5*1.05, 0) | D8: President's Distinguished | E8: 194 | G8: President's Distinguished | H8: 100
A9: Smedley Distinguished | B9: =ROUND(B5*1.08, 0) | D9: Smedley Distinguished | E9: 197 | G9: Smedley Distinguished | H9: 108
A11: Payments To Date | B11: =Overall!L14 | D11: Active Clubs | E11: =Overall!C14 | G11: Distinguished To Date | H11: =Overall!D14
A13: Pending Distinguished | B13: =IF(B6-B11<0,0,B6-B11) | D13: Pending Distinguished | E13: =IF(E6-E11<0,0,E6-E11) | G13: Pending Distinguished | H13: =IF(H6-H11<0,0,H6-H11)
A14: Pending Select Distinguished | B14: =IF(B7-B11<0,0,B7-B11) | D14: Pending Select Distinguished | E14: =IF(E7-E11<0,0,E7-E11) | G14: Pending Select Distinguished | H14: =IF(H7-H11<0,0,H7-H11)
A15: Pending President's Distinguished | B15: =IF(B8-B11<0,0,B8-B11) | D15: Pending President's Distinguished | E15: =IF(E8-E11<0,0,E8-E11) | G15: Pending President's Distinguished | H15: =IF(H8-H11<0,0,H8-H11)
A16: Pending Smedley Distinguished | B16: =IF(B9-B11<0,0,B9-B11) | D16: Pending Smedley Distinguished | E16: =IF(E9-E11<0,0,E9-E11) | G16: Pending Smedley Distinguished | H16: =IF(H9-H11<0,0,H9-H11)
A18: Payments % Base | B18: =B11/B5 | D18: 20 + Clubs | E18: =Overall!M14 | G18: Distinguished % Base | H18: =H11/E5
A19: Payments % SDD Goal | B19: =B11/B9 | D19: 20 + Clubs % Active Clubs | E19: =E18/E11
A21: Membership Campaigns & Deadlines
A23: Campaign Name | B23: Timeline | C23: Status / Time Left
A24: Smedley Award | B24: Aug 1 - Sep 30 | C24: =IF(TODAY()>DATE(YEAR(TODAY()),9,30), "Ended", DATE(YEAR(TODAY()),9,30)-TODAY() & " days left")
A25: Talk Up Toastmasters | B25: Feb 1 - Mar 31 | C25: =IF(TODAY()>DATE(YEAR(TODAY())+IF(MONTH(TODAY())>3,1,0),3,31), "Ended", DATE(YEAR(TODAY())+IF(MONTH(TODAY())>3,1,0),3,31)-TODAY() & " days left")
A26: Beat the Clock | B26: May 1 - Jun 30 | C26: =IF(TODAY()>DATE(YEAR(TODAY())+IF(MONTH(TODAY())>6,1,0),6,30), "Ended", DATE(YEAR(TODAY())+IF(MONTH(TODAY())>6,1,0),6,30)-TODAY() & " days left")

Sheet ClubDetails
A1: Club Number | B1: District | C1: Division | D1: Area | E1: Club Name | F1: Club Status | G1: Base Membership | H1: Active Membership | I1: Goals Met | J1: New Member Payments | K1: September Renewals | L1: March Renewals | M1: Total Payments
A2: 7896844 | B2: 121 | C2: 0D | D2: 0A | E2: ICSI Mysuru RoyalPro TM Club | F2: Active | G2: 0 | H2: 12 | I2: 2 | J2: 12 | K2: 0 | L2: 0 | M2: 12
A3: 1449300 | B3: 121 | C3: A | D3: 01 | E3: Mysore Toastmasters | F3: Active | G3: 35 | H3: 30 | I3: 10 | J3: 21 | K3: 25 | L3: 27 | M3: 73
A4: 6632488 | B4: 121 | C4: A | D4: 01 | E4: VVCE TOASTMASTERS CLUB | F4: Active | G4: 29 | H4: 31 | I4: 8 | J4: 13 | K4: 22 | L4: 21 | M4: 56
A5: 7992645 | B5: 121 | C5: A | D5: 01 | E5: All Women and Entrepreneurs Toastmasters Club | F5: Active | G5: 23 | H5: 20 | I5: 10 | J5: 11 | K5: 11 | L5: 15 | M5: 37
A6: 28678068 | B6: 121 | C6: A | D6: 01 | E6: MIT Toastmasters | F6: Ineligible | G6: 12 | H6: 0 | I6: 3 | J6: 26 | K6: 26 | L6: 0 | M6: 52
A7: 28680152 | B7: 121 | C7: A | D7: 01 | E7: rProcess Toastmasters Club | F7: Active | G7: 21 | H7: 21 | I7: 1 | J7: 0 | K7: 0 | L7: 0 | M7: 21
A8: 5953659 | B8: 121 | C8: A | D8: 02 | E8: Ritoras | F8: Active | G8: 14 | H8: 23 | I8: 9 | J8: 17 | K8: 13 | L8: 17 | M8: 47
A9: 6714857 | B9: 121 | C9: A | D9: 02 | E9: Galaxy Toastmasters Club | F9: Active | G9: 30 | H9: 33 | I9: 10 | J9: 29 | K9: 23 | L9: 25 | M9: 77
A10: 7772645 | B10: 121 | C10: A | D10: 02 | E10: Namma Bengaluru Toastmasters Club | F10: Active | G10: 10 | H10: 9 | I10: 7 | J10: 8 | K10: 3 | L10: 7 | M10: 18
A11: 28678224 | B11: 121 | C11: A | D11: 02 | E11: TE Services Toastmasters Club | F11: Active | G11: 32 | H11: 37 | I11: 5 | J11: 54 | K11: 9 | L11: 9 | M11: 72
A12: 28678951 | B12: 121 | C12: A | D12: 02 | E12: Welldoc Toastmasters | F12: Active | G12: 20 | H12: 10 | I12: 1 | J12: 5 | K12: 9 | L12: 5 | M12: 19
A13: 28679251 | B13: 121 | C13: A | D13: 02 | E13: Terra | F13: Suspended | G13: 26 | H13: 0 | I13: 0 | J13: 0 | K13: 0 | L13: 0 | M13: 26
... A190: 28678026 | B190: 121 | C190: I | D190: 04 | E190: Brighthearts Toastmasters | F190: Active | G190: 39 | H190: 41 | I190: 10 | J190: 26 | K190: 41 | L190: 32 | M190: 99

Sheet Overall
A1: District 121 - Divisions Performance Rolled-up Summary
A3: Division | B3: Base Clubs | C3: Active Clubs | D3: Distinguished Clubs | E3: Base Membership | F3: Active Membership | G3: September Renewals | H3: September Renewals % | I3: March Renewals | J3: March Renewals % | K3: Total New Members | L3: Total Payments | M3: 20+ Clubs
A4: Division 0D | B4: =COUNTIFS(ClubDetails!C:C, "0D") | C4: =COUNTIFS(ClubDetails!C:C, "0D", ClubDetails!F:F, "Active") | D4: ='Division 0D'!G5 | E4: ='Division 0D'!D5 | F4: ='Division 0D'!E5 | G4: ='Division 0D'!H5 | H4: =IF(E4=0, 0, G4/E4) | I4: ='Division 0D'!K5 | J4: =IF(E4=0, 0, I4/E4) | K4: ='Division 0D'!O5 | L4: ='Division 0D'!N5 | M4: =COUNTIF('Division 0D'!E4:E4, ">=20")
A5: Division A | B5: =COUNTIFS(ClubDetails!C:C, "A") | C5: =COUNTIFS(ClubDetails!C:C, "A", ClubDetails!F:F, "Active") | D5: ='Division A'!G30 | E5: ='Division A'!D30 | F5: ='Division A'!E30 | G5: ='Division A'!H30 | H5: =IF(E5=0, 0, G5/E5) | I5: ='Division A'!K30 | J5: =IF(E5=0, 0, I5/E5) | K5: ='Division A'!O30 | L5: ='Division A'!N30 | M5: =COUNTIF('Division A'!E4:E29, ">=20")
A6: Division B | B6: =COUNTIFS(ClubDetails!C:C, "B") | C6: =COUNTIFS(ClubDetails!C:C, "B", ClubDetails!F:F, "Active") | D6: ='Division B'!G25 | E6: ='Division B'!D25 | F6: ='Division B'!E25 | G6: ='Division B'!H25 | H6: =IF(E6=0, 0, G6/E6) | I6: ='Division B'!K25 | J6: =IF(E6=0, 0, I6/E6) | K6: ='Division B'!O25 | L6: ='Division B'!N25 | M6: =COUNTIF('Division B'!E4:E24, ">=20")
A7: Division C | B7: =COUNTIFS(ClubDetails!C:C, "C") | C7: =COUNTIFS(ClubDetails!C:C, "C", ClubDetails!F:F, "Active") | D7: ='Division C'!G22 | E7: ='Division C'!D22 | F7: ='Division C'!E22 | G7: ='Division C'!H22 | H7: =IF(E7=0, 0, G7/E7) | I7: ='Division C'!K22 | J7: =IF(E7=0, 0, I7/E7) | K7: ='Division C'!O22 | L7: ='Division C'!N22 | M7: =COUNTIF('Division C'!E4:E21, ">=20")
A8: Division D | B8: =COUNTIFS(ClubDetails!C:C, "D") | C8: =COUNTIFS(ClubDetails!C:C, "D", ClubDetails!F:F, "Active") | D8: ='Division D'!G25 | E8: ='Division D'!D25 | F8: ='Division D'!E25 | G8: ='Division D'!H25 | H8: =IF(E8=0, 0, G8/E8) | I8: ='Division D'!K25 | J8: =IF(E8=0, 0, I8/E8) | K8: ='Division D'!O25 | L8: ='Division D'!N25 | M8: =COUNTIF('Division D'!E4:E24, ">=20")
A9: Division E | B9: =COUNTIFS(ClubDetails!C:C, "E") | C9: =COUNTIFS(ClubDetails!C:C, "E", ClubDetails!F:F, "Active") | D9: ='Division E'!G20 | E9: ='Division E'!D20 | F9: ='Division E'!E20 | G9: ='Division E'!H20 | H9: =IF(E9=0, 0, G9/E9) | I9: ='Division E'!K20 | J9: =IF(E9=0, 0, I9/E9) | K9: ='Division E'!O20 | L9: ='Division E'!N20 | M9: =COUNTIF('Division E'!E4:E19, ">=20")
A10: Division F | B10: =COUNTIFS(ClubDetails!C:C, "F") | C10: =COUNTIFS(ClubDetails!C:C, "F", ClubDetails!F:F, "Active") | D10: ='Division F'!G28 | E10: ='Division F'!D28 | F10: ='Division F'!E28 | G10: ='Division F'!H28 | H10: =IF(E10=0, 0, G10/E10) | I10: ='Division F'!K28 | J10: =IF(E10=0, 0, I10/E10) | K10: ='Division F'!O28 | L10: ='Division F'!N28 | M10: =COUNTIF('Division F'!E4:E27, ">=20")
A11: Division G | B11: =COUNTIFS(ClubDetails!C:C, "G") | C11: =COUNTIFS(ClubDetails!C:C, "G", ClubDetails!F:F, "Active") | D11: ='Division G'!G23 | E11: ='Division G'!D23 | F11: ='Division G'!E23 | G11: ='Division G'!H23 | H11: =IF(E11=0, 0, G11/E11) | I11: ='Division G'!K23 | J11: =IF(E11=0, 0, I11/E11) | K11: ='Division G'!O23 | L11: ='Division G'!N23 | M11: =COUNTIF('Division G'!E4:E22, ">=20")
A12: Division H | B12: =COUNTIFS(ClubDetails!C:C, "H") | C12: =COUNTIFS(ClubDetails!C:C, "H", ClubDetails!F:F, "Active") | D12: ='Division H'!G28 | E12: ='Division H'!D28 | F12: ='Division H'!E28 | G12: ='Division H'!H28 | H12: =IF(E12=0, 0, G12/E12) | I12: ='Division H'!K28 | J12: =IF(E12=0, 0, I12/E12) | K12: ='Division H'!O28 | L12: ='Division H'!N28 | M12: =COUNTIF('Division H'!E4:E27, ">=20")
A13: Division I | B13: =COUNTIFS(ClubDetails!C:C, "I") | C13: =COUNTIFS(ClubDetails!C:C, "I", ClubDetails!F:F, "Active") | D13: ='Division I'!G23 | E13: ='Division I'!D23 | F13: ='Division I'!E23 | G13: ='Division I'!H23 | H13: =IF(E13=0, 0, G13/E13) | I13: ='Division I'!K23 | J13: =IF(E13=0, 0, I13/E13) | K13: ='Division I'!O23 | L13: ='Division I'!N23 | M13: =COUNTIF('Division I'!E4:E22, ">=20")
A14: District Total | B14: =SUM(B4:B13) | C14: =SUM(C4:C13) | D14: =SUM(D4:D13) | E14: =SUM(E4:E13) | F14: =SUM(F4:F13) | G14: =SUM(G4:G13) | H14: =IF(E14=0, 0, G14/E14) | I14: =SUM(I4:I13) | J14: =IF(E14=0, 0, I14/E14) | K14: =SUM(K4:K13) | L14: =SUM(L4:L13) | M14: =SUM(M4:M13)
A17: Area Performance Summary
A18: Division | B18: Area | C18: Base Membership | D18: Active Membership | E18: September Renewals | F18: September Renewals % | G18: March Renewals | H18: March Renewals % | I18: Total New Members | J18: Total Payments
A19: 0D | B19: 0A | C19: =SUMIFS(ClubDetails!G:G, ClubDetails!C:C, A19, ClubDetails!D:D, B19) | D19: =SUMIFS(ClubDetails!H:H, ClubDetails!C:C, A19, ClubDetails!D:D, B19) | E19: =SUMIFS(ClubDetails!K:K, ClubDetails!C:C, A19, ClubDetails!D:D, B19) | F19: =IF(C19=0, 0, E19/C19) | G19: =SUMIFS(ClubDetails!L:L, ClubDetails!C:C, A19, ClubDetails!D:D, B19) | H19: =IF(C19=0, 0, G19/C19) | I19: =SUMIFS(ClubDetails!J:J, ClubDetails!C:C, A19, ClubDetails!D:D, B19) | J19: =SUMIFS(ClubDetails!M:M, ClubDetails!C:C, A19, ClubDetails!D:D, B19)
A20: A | B20: 01 | C20: =SUMIFS(ClubDetails!G:G, ClubDetails!C:C, A20, ClubDetails!D:D, B20) | D20: =SUMIFS(ClubDetails!H:H, ClubDetails!C:C, A20, ClubDetails!D:D, B20) | E20: =SUMIFS(ClubDetails!K:K, ClubDetails!C:C, A20, ClubDetails!D:D, B20) | F20: =IF(C20=0, 0, E20/C20) | G20: =SUMIFS(ClubDetails!L:L, ClubDetails!C:C, A20, ClubDetails!D:D, B20) | H20: =IF(C20=0, 0, G20/C20) | I20: =SUMIFS(ClubDetails!J:J, ClubDetails!C:C, A20, ClubDetails!D:D, B20) | J20: =SUMIFS(ClubDetails!M:M, ClubDetails!C:C, A20, ClubDetails!D:D, B20)
A21: A | B21: 02 | C21: =SUMIFS(ClubDetails!G:G, ClubDetails!C:C, A21, ClubDetails!D:D, B21) | D21: =SUMIFS(ClubDetails!H:H, ClubDetails!C:C, A21, ClubDetails!D:D, B21) | E21: =SUMIFS(ClubDetails!K:K, ClubDetails!C:C, A21, ClubDetails!D:D, B21) | F21: =IF(C21=0, 0, E21/C21) | G21: =SUMIFS(ClubDetails!L:L, ClubDetails!C:C, A21, ClubDetails!D:D, B21) | H21: =IF(C21=0, 0, G21/C21) | I21: =SUMIFS(ClubDetails!J:J, ClubDetails!C:C, A21, ClubDetails!D:D, B21) | J21: =SUMIFS(ClubDetails!M:M, ClubDetails!C:C, A21, ClubDetails!D:D, B21)
A22: A | B22: 03 | C22: =SUMIFS(ClubDetails!G:G, ClubDetails!C:C, A22, ClubDetails!D:D, B22) | D22: =SUMIFS(ClubDetails!H:H, ClubDetails!C:C, A22, ClubDetails!D:D, B22) | E22: =SUMIFS(ClubDetails!K:K, ClubDetails!C:C, A22, ClubDetails!D:D, B22) | F22: =IF(C22=0, 0, E22/C22) | G22: =SUMIFS(ClubDetails!L:L, ClubDetails!C:C, A22, ClubDetails!D:D, B22) | H22: =IF(C22=0, 0, G22/C22) | I22: =SUMIFS(ClubDetails!J:J, ClubDetails!C:C, A22, ClubDetails!D:D, B22) | J22: =SUMIFS(ClubDetails!M:M, ClubDetails!C:C, A22, ClubDetails!D:D, B22)
A23: A | B23: 04 | C23: =SUMIFS(ClubDetails!G:G, ClubDetails!C:C, A23, ClubDetails!D:D, B23) | D23: =SUMIFS(ClubDetails!H:H, ClubDetails!C:C, A23, ClubDetails!D:D, B23) | E23: =SUMIFS(ClubDetails!K:K, ClubDetails!C:C, A23, ClubDetails!D:D, B23) | F23: =IF(C23=0, 0, E23/C23) | G23: =SUMIFS(ClubDetails!L:L, ClubDetails!C:C, A23, ClubDetails!D:D, B23) | H23: =IF(C23=0, 0, G23/C23) | I23: =SUMIFS(ClubDetails!J:J, ClubDetails!C:C, A23, ClubDetails!D:D, B23) | J23: =SUMIFS(ClubDetails!M:M, ClubDetails!C:C, A23, ClubDetails!D:D, B23)
A24: A | B24: 05 | C24: =SUMIFS(ClubDetails!G:G, ClubDetails!C:C, A24, ClubDetails!D:D, B24) | D24: =SUMIFS(ClubDetails!H:H, ClubDetails!C:C, A24, ClubDetails!D:D, B24) | E24: =SUMIFS(ClubDetails!K:K, ClubDetails!C:C, A24, ClubDetails!D:D, B24) | F24: =IF(C24=0, 0, E24/C24) | G24: =SUMIFS(ClubDetails!L:L, ClubDetails!C:C, A24, ClubDetails!D:D, B24) | H24: =IF(C24=0, 0, G24/C24) | I24: =SUMIFS(ClubDetails!J:J, ClubDetails!C:C, A24, ClubDetails!D:D, B24) | J24: =SUMIFS(ClubDetails!M:M, ClubDetails!C:C, A24, ClubDetails!D:D, B24)
A25: B | B25: 01 | C25: =SUMIFS(ClubDetails!G:G, ClubDetails!C:C, A25, ClubDetails!D:D, B25) | D25: =SUMIFS(ClubDetails!H:H, ClubDetails!C:C, A25, ClubDetails!D:D, B25) | E25: =SUMIFS(ClubDetails!K:K, ClubDetails!C:C, A25, ClubDetails!D:D, B25) | F25: =IF(C25=0, 0, E25/C25) | G25: =SUMIFS(ClubDetails!L:L, ClubDetails!C:C, A25, ClubDetails!D:D, B25) | H25: =IF(C25=0, 0, G25/C25) | I25: =SUMIFS(ClubDetails!J:J, ClubDetails!C:C, A25, ClubDetails!D:D, B25) | J25: =SUMIFS(ClubDetails!M:M, ClubDetails!C:C, A25, ClubDetails!D:D, B25)
A26: B | B26: 02 | C26: =SUMIFS(ClubDetails!G:G, ClubDetails!C:C, A26, ClubDetails!D:D, B26) | D26: =SUMIFS(ClubDetails!H:H, ClubDetails!C:C, A26, ClubDetails!D:D, B26) | E26: =SUMIFS(ClubDetails!K:K, ClubDetails!C:C, A26, ClubDetails!D:D, B26) | F26: =IF(C26=0, 0, E26/C26) | G26: =SUMIFS(ClubDetails!L:L, ClubDetails!C:C, A26, ClubDetails!D:D, B26) | H26: =IF(C26=0, 0, G26/C26) | I26: =SUMIFS(ClubDetails!J:J, ClubDetails!C:C, A26, ClubDetails!D:D, B26) | J26: =SUMIFS(ClubDetails!M:M, ClubDetails!C:C, A26, ClubDetails!D:D, B26)
A27: B | B27: 03 | C27: =SUMIFS(ClubDetails!G:G, ClubDetails!C:C, A27, ClubDetails!D:D, B27) | D27: =SUMIFS(ClubDetails!H:H, ClubDetails!C:C, A27, ClubDetails!D:D, B27) | E27: =SUMIFS(ClubDetails!K:K, ClubDetails!C:C, A27, ClubDetails!D:D, B27) | F27: =IF(C27=0, 0, E27/C27) | G27: =SUMIFS(ClubDetails!L:L, ClubDetails!C:C, A27, ClubDetails!D:D, B27) | H27: =IF(C27=0, 0, G27/C27) | I27: =SUMIFS(ClubDetails!J:J, ClubDetails!C:C, A27, ClubDetails!D:D, B27) | J27: =SUMIFS(ClubDetails!M:M, ClubDetails!C:C, A27, ClubDetails!D:D, B27)
A28: B | B28: 04 | C28: =SUMIFS(ClubDetails!G:G, ClubDetails!C:C, A28, ClubDetails!D:D, B28) | D28: =SUMIFS(ClubDetails!H:H, ClubDetails!C:C, A28, ClubDetails!D:D, B28) | E28: =SUMIFS(ClubDetails!K:K, ClubDetails!C:C, A28, ClubDetails!D:D, B28) | F28: =IF(C28=0, 0, E28/C28) | G28: =SUMIFS(ClubDetails!L:L, ClubDetails!C:C, A28, ClubDetails!D:D, B28) | H28: =IF(C28=0, 0, G28/C28) | I28: =SUMIFS(ClubDetails!J:J, ClubDetails!C:C, A28, ClubDetails!D:D, B28) | J28: =SUMIFS(ClubDetails!M:M, ClubDetails!C:C, A28, ClubDetails!D:D, B28)
A29: C | B29: 01 | C29: =SUMIFS(ClubDetails!G:G, ClubDetails!C:C, A29, ClubDetails!D:D, B29) | D29: =SUMIFS(ClubDetails!H:H, ClubDetails!C:C, A29, ClubDetails!D:D, B29) | E29: =SUMIFS(ClubDetails!K:K, ClubDetails!C:C, A29, ClubDetails!D:D, B29) | F29: =IF(C29=0, 0, E29/C29) | G29: =SUMIFS(ClubDetails!L:L, ClubDetails!C:C, A29, ClubDetails!D:D, B29) | H29: =IF(C29=0, 0, G29/C29) | I29: =SUMIFS(ClubDetails!J:J, ClubDetails!C:C, A29, ClubDetails!D:D, B29) | J29: =SUMIFS(ClubDetails!M:M, ClubDetails!C:C, A29, ClubDetails!D:D, B29)
A30: C | B30: 02 | C30: =SUMIFS(ClubDetails!G:G, ClubDetails!C:C, A30, ClubDetails!D:D, B30) | D30: =SUMIFS(ClubDetails!H:H, ClubDetails!C:C, A30, ClubDetails!D:D, B30) | E30: =SUMIFS(ClubDetails!K:K, ClubDetails!C:C, A30, ClubDetails!D:D, B30) | F30: =IF(C30=0, 0, E30/C30) | G30: =SUMIFS(ClubDetails!L:L, ClubDetails!C:C, A30, ClubDetails!D:D, B30) | H30: =IF(C30=0, 0, G30/C30) | I30: =SUMIFS(ClubDetails!J:J, ClubDetails!C:C, A30, ClubDetails!D:D, B30) | J30: =SUMIFS(ClubDetails!M:M, ClubDetails!C:C, A30, ClubDetails!D:D, B30)
... A59: I | B59: 04 | C59: =SUMIFS(ClubDetails!G:G, ClubDetails!C:C, A59, ClubDetails!D:D, B59) | D59: =SUMIFS(ClubDetails!H:H, ClubDetails!C:C, A59, ClubDetails!D:D, B59) | E59: =SUMIFS(ClubDetails!K:K, ClubDetails!C:C, A59, ClubDetails!D:D, B59) | F59: =IF(C59=0, 0, E59/C59) | G59: =SUMIFS(ClubDetails!L:L, ClubDetails!C:C, A59, ClubDetails!D:D, B59) | H59: =IF(C59=0, 0, G59/C59) | I59: =SUMIFS(ClubDetails!J:J, ClubDetails!C:C, A59, ClubDetails!D:D, B59) | J59: =SUMIFS(ClubDetails!M:M, ClubDetails!C:C, A59, ClubDetails!D:D, B59)
A60: Area Total | C60: =SUM(C19:C59) | D60: =SUM(D19:D59) | E60: =SUM(E19:E59) | F60: =IF(C60=0, 0, E60/C60) | G60: =SUM(G19:G59) | H60: =IF(C60=0, 0, G60/C60) | I60: =SUM(I19:I59) | J60: =SUM(J19:J59)

Sheet Division 0D
A1: Division 0D - Membership and Payments Performance
A3: Club Number | B3: Area | C3: Club Name | D3: Base Membership | E3: Active Membership | F3: DCP Goals Met | G3: Distinguished Status | H3: September Renewals | I3: September Renewals % | J3: September Renewal Status | K3: March Renewals | L3: March Renewals % | M3: March Renewal Status | N3: Total Payments | O3: Total New Members | P3: July | Q3: August | R3: September | S3: October | T3: November | U3: December | V3: January | W3: February | X3: March | Y3: April | Z3: May | AA3: June | AB3: Smedley Award Eligibility | AC3: Smedley Award Goal | AD3: Talk Up Eligibility | AE3: Talk Up Goal | AF3: Beat the Clock Eligibility | AG3: Beat the Clock Goal
A4: 7896844 | B4: 0A | C4: ICSI Mysuru RoyalPro TM Club | D4: =ClubDetails!G2 | E4: =ClubDetails!H2 | F4: =ClubDetails!I2 | G4: =IF(F4<5,"-",IF(E4>19,"Yes",IF(E4>D4+2,"Yes","-"))) | H4: =ClubDetails!K2 | I4: =IF(D4=0,0,H4/D4) | J4: =IF(H4=0,"Renewals not here",IF(H4<3,"Ineligible",IF(D4<8,"Low","Active"))) | K4: =ClubDetails!L2 | L4: =IF(D4=0,0,K4/D4) | M4: =IF(K4=0,"Renewals not here",IF(K4<3,"Ineligible",IF(E4<8,"Low","Active"))) | N4: =ClubDetails!M2 | O4: =ClubDetails!J2 | P4: 0 | Q4: 0 | R4: 0 | S4: 0 | T4: 0 | U4: 0 | V4: 0 | W4: 0 | X4: 0 | Y4: 0 | Z4: 0 | AA4: 0 | AB4: =IF(SUM(Q4:R4)>=5,"Yes","No") | AC4: =IF(SUM(Q4:R4)>=5,0,5-SUM(Q4:R4)) | AD4: =IF(SUM(W4:X4)>=5,"Yes","No") | AE4: =IF(SUM(W4:X4)>=5,0,5-SUM(W4:X4)) | AF4: =IF(SUM(Z4:AA4)>=5,"Yes","No") | AG4: =IF(SUM(Z4:AA4)>=5,0,5-SUM(Z4:AA4))
A5: Total / Average | D5: =SUM(D4:D4) | E5: =SUM(E4:E4) | F5: =AVERAGE(F4:F4) | G5: =COUNTIF(G4:G4,"Yes") | H5: =SUM(H4:H4) | I5: =IF(D5=0,0,H5/D5) | K5: =SUM(K4:K4) | L5: =IF(D5=0,0,K5/D5) | N5: =SUM(N4:N4) | O5: =SUM(O4:O4) | P5: =SUM(P4:P4) | Q5: =SUM(Q4:Q4) | R5: =SUM(R4:R4) | S5: =SUM(S4:S4) | T5: =SUM(T4:T4) | U5: =SUM(U4:U4) | ... AA5: =SUM(AA4:AA4) | AB5: =COUNTIF(AB4:AB4,"Yes") | AC5: =SUM(AC4:AC4) | AD5: =COUNTIF(AD4:AD4,"Yes") | AE5: =SUM(AE4:AE4) | AF5: =COUNTIF(AF4:AF4,"Yes") | AG5: =SUM(AG4:AG4)

Sheet Division A
A1: Division A - Membership and Payments Performance
A3: Club Number | B3: Area | C3: Club Name | D3: Base Membership | E3: Active Membership | F3: DCP Goals Met | G3: Distinguished Status | H3: September Renewals | I3: September Renewals % | J3: September Renewal Status | K3: March Renewals | L3: March Renewals % | M3: March Renewal Status | N3: Total Payments | O3: Total New Members | P3: July | Q3: August | R3: September | S3: October | T3: November | U3: December | V3: January | W3: February | X3: March | Y3: April | Z3: May | AA3: June | AB3: Smedley Award Eligibility | AC3: Smedley Award Goal | AD3: Talk Up Eligibility | AE3: Talk Up Goal | AF3: Beat the Clock Eligibility | AG3: Beat the Clock Goal
A4: 1449300 | B4: 01 | C4: Mysore Toastmasters | D4: =ClubDetails!G3 | E4: =ClubDetails!H3 | F4: =ClubDetails!I3 | G4: =IF(F4<5,"-",IF(E4>19,"Yes",IF(E4>D4+2,"Yes","-"))) | H4: =ClubDetails!K3 | I4: =IF(D4=0,0,H4/D4) | J4: =IF(H4=0,"Renewals not here",IF(H4<3,"Ineligible",IF(D4<8,"Low","Active"))) | K4: =ClubDetails!L3 | L4: =IF(D4=0,0,K4/D4) | M4: =IF(K4=0,"Renewals not here",IF(K4<3,"Ineligible",IF(E4<8,"Low","Active"))) | N4: =ClubDetails!M3 | O4: =ClubDetails!J3 | P4: 0 | Q4: 0 | R4: 0 | S4: 0 | T4: 0 | U4: 0 | V4: 0 | W4: 0 | X4: 0 | Y4: 0 | Z4: 0 | AA4: 0 | AB4: =IF(SUM(Q4:R4)>=5,"Yes","No") | AC4: =IF(SUM(Q4:R4)>=5,0,5-SUM(Q4:R4)) | AD4: =IF(SUM(W4:X4)>=5,"Yes","No") | AE4: =IF(SUM(W4:X4)>=5,0,5-SUM(W4:X4)) | AF4: =IF(SUM(Z4:AA4)>=5,"Yes","No") | AG4: =IF(SUM(Z4:AA4)>=5,0,5-SUM(Z4:AA4))
A5: 6632488 | B5: 01 | C5: VVCE TOASTMASTERS CLUB | D5: =ClubDetails!G4 | E5: =ClubDetails!H4 | F5: =ClubDetails!I4 | G5: =IF(F5<5,"-",IF(E5>19,"Yes",IF(E5>D5+2,"Yes","-"))) | H5: =ClubDetails!K4 | I5: =IF(D5=0,0,H5/D5) | J5: =IF(H5=0,"Renewals not here",IF(H5<3,"Ineligible",IF(D5<8,"Low","Active"))) | K5: =ClubDetails!L4 | L5: =IF(D5=0,0,K5/D5) | M5: =IF(K5=0,"Renewals not here",IF(K5<3,"Ineligible",IF(E5<8,"Low","Active"))) | N5: =ClubDetails!M4 | O5: =ClubDetails!J4 | P5: 0 | Q5: 0 | R5: 0 | S5: 0 | T5: 0 | U5: 0 | V5: 0 | W5: 0 | X5: 0 | Y5: 0 | Z5: 0 | AA5: 0 | AB5: =IF(SUM(Q5:R5)>=5,"Yes","No") | AC5: =IF(SUM(Q5:R5)>=5,0,5-SUM(Q5:R5)) | AD5: =IF(SUM(W5:X5)>=5,"Yes","No") | AE5: =IF(SUM(W5:X5)>=5,0,5-SUM(W5:X5)) | AF5: =IF(SUM(Z5:AA5)>=5,"Yes","No") | AG5: =IF(SUM(Z5:AA5)>=5,0,5-SUM(Z5:AA5))
A6: 7992645 | B6: 01 | C6: All Women and Entrepreneurs Toastmasters Club | D6: =ClubDetails!G5 | E6: =ClubDetails!H5 | F6: =ClubDetails!I5 | G6: =IF(F6<5,"-",IF(E6>19,"Yes",IF(E6>D6+2,"Yes","-"))) | H6: =ClubDetails!K5 | I6: =IF(D6=0,0,H6/D6) | J6: =IF(H6=0,"Renewals not here",IF(H6<3,"Ineligible",IF(D6<8,"Low","Active"))) | K6: =ClubDetails!L5 | L6: =IF(D6=0,0,K6/D6) | M6: =IF(K6=0,"Renewals not here",IF(K6<3,"Ineligible",IF(E6<8,"Low","Active"))) | N6: =ClubDetails!M5 | O6: =ClubDetails!J5 | P6: 0 | Q6: 0 | R6: 0 | S6: 0 | T6: 0 | U6: 0 | V6: 0 | W6: 0 | X6: 0 | Y6: 0 | Z6: 0 | AA6: 0 | AB6: =IF(SUM(Q6:R6)>=5,"Yes","No") | AC6: =IF(SUM(Q6:R6)>=5,0,5-SUM(Q6:R6)) | AD6: =IF(SUM(W6:X6)>=5,"Yes","No") | AE6: =IF(SUM(W6:X6)>=5,0,5-SUM(W6:X6)) | AF6: =IF(SUM(Z6:AA6)>=5,"Yes","No") | AG6: =IF(SUM(Z6:AA6)>=5,0,5-SUM(Z6:AA6))
A7: 28678068 | B7: 01 | C7: MIT Toastmasters | D7: =ClubDetails!G6 | E7: =ClubDetails!H6 | F7: =ClubDetails!I6 | G7: =IF(F7<5,"-",IF(E7>19,"Yes",IF(E7>D7+2,"Yes","-"))) | H7: =ClubDetails!K6 | I7: =IF(D7=0,0,H7/D7) | J7: =IF(H7=0,"Renewals not here",IF(H7<3,"Ineligible",IF(D7<8,"Low","Active"))) | K7: =ClubDetails!L6 | L7: =IF(D7=0,0,K7/D7) | M7: =IF(K7=0,"Renewals not here",IF(K7<3,"Ineligible",IF(E7<8,"Low","Active"))) | N7: =ClubDetails!M6 | O7: =ClubDetails!J6 | P7: 0 | Q7: 0 | R7: 0 | S7: 0 | T7: 0 | U7: 0 | V7: 0 | W7: 0 | X7: 0 | Y7: 0 | Z7: 0 | AA7: 0 | AB7: =IF(SUM(Q7:R7)>=5,"Yes","No") | AC7: =IF(SUM(Q7:R7)>=5,0,5-SUM(Q7:R7)) | AD7: =IF(SUM(W7:X7)>=5,"Yes","No") | AE7: =IF(SUM(W7:X7)>=5,0,5-SUM(W7:X7)) | AF7: =IF(SUM(Z7:AA7)>=5,"Yes","No") | AG7: =IF(SUM(Z7:AA7)>=5,0,5-SUM(Z7:AA7))
A8: 28680152 | B8: 01 | C8: rProcess Toastmasters Club | D8: =ClubDetails!G7 | E8: =ClubDetails!H7 | F8: =ClubDetails!I7 | G8: =IF(F8<5,"-",IF(E8>19,"Yes",IF(E8>D8+2,"Yes","-"))) | H8: =ClubDetails!K7 | I8: =IF(D8=0,0,H8/D8) | J8: =IF(H8=0,"Renewals not here",IF(H8<3,"Ineligible",IF(D8<8,"Low","Active"))) | K8: =ClubDetails!L7 | L8: =IF(D8=0,0,K8/D8) | M8: =IF(K8=0,"Renewals not here",IF(K8<3,"Ineligible",IF(E8<8,"Low","Active"))) | N8: =ClubDetails!M7 | O8: =ClubDetails!J7 | P8: 0 | Q8: 0 | R8: 0 | S8: 0 | T8: 0 | U8: 0 | V8: 0 | W8: 0 | X8: 0 | Y8: 0 | Z8: 0 | AA8: 0 | AB8: =IF(SUM(Q8:R8)>=5,"Yes","No") | AC8: =IF(SUM(Q8:R8)>=5,0,5-SUM(Q8:R8)) | AD8: =IF(SUM(W8:X8)>=5,"Yes","No") | AE8: =IF(SUM(W8:X8)>=5,0,5-SUM(W8:X8)) | AF8: =IF(SUM(Z8:AA8)>=5,"Yes","No") | AG8: =IF(SUM(Z8:AA8)>=5,0,5-SUM(Z8:AA8))
A9: 5953659 | B9: 02 | C9: Ritoras | D9: =ClubDetails!G8 | E9: =ClubDetails!H8 | F9: =ClubDetails!I8 | G9: =IF(F9<5,"-",IF(E9>19,"Yes",IF(E9>D9+2,"Yes","-"))) | H9: =ClubDetails!K8 | I9: =IF(D9=0,0,H9/D9) | J9: =IF(H9=0,"Renewals not here",IF(H9<3,"Ineligible",IF(D9<8,"Low","Active"))) | K9: =ClubDetails!L8 | L9: =IF(D9=0,0,K9/D9) | M9: =IF(K9=0,"Renewals not here",IF(K9<3,"Ineligible",IF(E9<8,"Low","Active"))) | N9: =ClubDetails!M8 | O9: =ClubDetails!J8 | P9: 0 | Q9: 0 | R9: 0 | S9: 0 | T9: 0 | U9: 0 | V9: 0 | W9: 0 | X9: 0 | Y9: 0 | Z9: 0 | AA9: 0 | AB9: =IF(SUM(Q9:R9)>=5,"Yes","No") | AC9: =IF(SUM(Q9:R9)>=5,0,5-SUM(Q9:R9)) | AD9: =IF(SUM(W9:X9)>=5,"Yes","No") | AE9: =IF(SUM(W9:X9)>=5,0,5-SUM(W9:X9)) | AF9: =IF(SUM(Z9:AA9)>=5,"Yes","No") | AG9: =IF(SUM(Z9:AA9)>=5,0,5-SUM(Z9:AA9))
A10: 6714857 | B10: 02 | C10: Galaxy Toastmasters Club | D10: =ClubDetails!G9 | E10: =ClubDetails!H9 | F10: =ClubDetails!I9 | G10: =IF(F10<5,"-",IF(E10>19,"Yes",IF(E10>D10+2,"Yes","-"))) | H10: =ClubDetails!K9 | I10: =IF(D10=0,0,H10/D10) | J10: =IF(H10=0,"Renewals not here",IF(H10<3,"Ineligible",IF(D10<8,"Low","Active"))) | K10: =ClubDetails!L9 | L10: =IF(D10=0,0,K10/D10) | M10: =IF(K10=0,"Renewals not here",IF(K10<3,"Ineligible",IF(E10<8,"Low","Active"))) | N10: =ClubDetails!M9 | O10: =ClubDetails!J9 | P10: 0 | Q10: 0 | R10: 0 | S10: 0 | T10: 0 | U10: 0 | V10: 0 | W10: 0 | X10: 0 | Y10: 0 | Z10: 0 | AA10: 0 | AB10: =IF(SUM(Q10:R10)>=5,"Yes","No") | AC10: =IF(SUM(Q10:R10)>=5,0,5-SUM(Q10:R10)) | AD10: =IF(SUM(W10:X10)>=5,"Yes","No") | AE10: =IF(SUM(W10:X10)>=5,0,5-SUM(W10:X10)) | AF10: =IF(SUM(Z10:AA10)>=5,"Yes","No") | AG10: =IF(SUM(Z10:AA10)>=5,0,5-SUM(Z10:AA10))
A11: 7772645 | B11: 02 | C11: Namma Bengaluru Toastmasters Club | D11: =ClubDetails!G10 | E11: =ClubDetails!H10 | F11: =ClubDetails!I10 | G11: =IF(F11<5,"-",IF(E11>19,"Yes",IF(E11>D11+2,"Yes","-"))) | H11: =ClubDetails!K10 | I11: =IF(D11=0,0,H11/D11) | J11: =IF(H11=0,"Renewals not here",IF(H11<3,"Ineligible",IF(D11<8,"Low","Active"))) | K11: =ClubDetails!L10 | L11: =IF(D11=0,0,K11/D11) | M11: =IF(K11=0,"Renewals not here",IF(K11<3,"Ineligible",IF(E11<8,"Low","Active"))) | N11: =ClubDetails!M10 | O11: =ClubDetails!J10 | P11: 0 | Q11: 0 | R11: 0 | S11: 0 | T11: 0 | U11: 0 | V11: 0 | W11: 0 | X11: 0 | Y11: 0 | Z11: 0 | AA11: 0 | AB11: =IF(SUM(Q11:R11)>=5,"Yes","No") | AC11: =IF(SUM(Q11:R11)>=5,0,5-SUM(Q11:R11)) | AD11: =IF(SUM(W11:X11)>=5,"Yes","No") | AE11: =IF(SUM(W11:X11)>=5,0,5-SUM(W11:X11)) | AF11: =IF(SUM(Z11:AA11)>=5,"Yes","No") | AG11: =IF(SUM(Z11:AA11)>=5,0,5-SUM(Z11:AA11))
A12: 28678224 | B12: 02 | C12: TE Services Toastmasters Club | D12: =ClubDetails!G11 | E12: =ClubDetails!H11 | F12: =ClubDetails!I11 | G12: =IF(F12<5,"-",IF(E12>19,"Yes",IF(E12>D12+2,"Yes","-"))) | H12: =ClubDetails!K11 | I12: =IF(D12=0,0,H12/D12) | J12: =IF(H12=0,"Renewals not here",IF(H12<3,"Ineligible",IF(D12<8,"Low","Active"))) | K12: =ClubDetails!L11 | L12: =IF(D12=0,0,K12/D12) | M12: =IF(K12=0,"Renewals not here",IF(K12<3,"Ineligible",IF(E12<8,"Low","Active"))) | N12: =ClubDetails!M11 | O12: =ClubDetails!J11 | P12: 0 | Q12: 0 | R12: 0 | S12: 0 | T12: 0 | U12: 0 | V12: 0 | W12: 0 | X12: 0 | Y12: 0 | Z12: 0 | AA12: 0 | AB12: =IF(SUM(Q12:R12)>=5,"Yes","No") | AC12: =IF(SUM(Q12:R12)>=5,0,5-SUM(Q12:R12)) | AD12: =IF(SUM(W12:X12)>=5,"Yes","No") | AE12: =IF(SUM(W12:X12)>=5,0,5-SUM(W12:X12)) | AF12: =IF(SUM(Z12:AA12)>=5,"Yes","No") | AG12: =IF(SUM(Z12:AA12)>=5,0,5-SUM(Z12:AA12))
A13: 28678951 | B13: 02 | C13: Welldoc Toastmasters | D13: =ClubDetails!G12 | E13: =ClubDetails!H12 | F13: =ClubDetails!I12 | G13: =IF(F13<5,"-",IF(E13>19,"Yes",IF(E13>D13+2,"Yes","-"))) | H13: =ClubDetails!K12 | I13: =IF(D13=0,0,H13/D13) | J13: =IF(H13=0,"Renewals not here",IF(H13<3,"Ineligible",IF(D13<8,"Low","Active"))) | K13: =ClubDetails!L12 | L13: =IF(D13=0,0,K13/D13) | M13: =IF(K13=0,"Renewals not here",IF(K13<3,"Ineligible",IF(E13<8,"Low","Active"))) | N13: =ClubDetails!M12 | O13: =ClubDetails!J12 | P13: 0 | Q13: 0 | R13: 0 | S13: 0 | T13: 0 | U13: 0 | V13: 0 | W13: 0 | X13: 0 | Y13: 0 | Z13: 0 | AA13: 0 | AB13: =IF(SUM(Q13:R13)>=5,"Yes","No") | AC13: =IF(SUM(Q13:R13)>=5,0,5-SUM(Q13:R13)) | AD13: =IF(SUM(W13:X13)>=5,"Yes","No") | AE13: =IF(SUM(W13:X13)>=5,0,5-SUM(W13:X13)) | AF13: =IF(SUM(Z13:AA13)>=5,"Yes","No") | AG13: =IF(SUM(Z13:AA13)>=5,0,5-SUM(Z13:AA13))
A14: 28679251 | B14: 02 | C14: Terra | D14: =ClubDetails!G13 | E14: =ClubDetails!H13 | F14: =ClubDetails!I13 | G14: =IF(F14<5,"-",IF(E14>19,"Yes",IF(E14>D14+2,"Yes","-"))) | H14: =ClubDetails!K13 | I14: =IF(D14=0,0,H14/D14) | J14: =IF(H14=0,"Renewals not here",IF(H14<3,"Ineligible",IF(D14<8,"Low","Active"))) | K14: =ClubDetails!L13 | L14: =IF(D14=0,0,K14/D14) | M14: =IF(K14=0,"Renewals not here",IF(K14<3,"Ineligible",IF(E14<8,"Low","Active"))) | N14: =ClubDetails!M13 | O14: =ClubDetails!J13 | P14: 0 | Q14: 0 | R14: 0 | S14: 0 | T14: 0 | U14: 0 | V14: 0 | W14: 0 | X14: 0 | Y14: 0 | Z14: 0 | AA14: 0 | AB14: =IF(SUM(Q14:R14)>=5,"Yes","No") | AC14: =IF(SUM(Q14:R14)>=5,0,5-SUM(Q14:R14)) | AD14: =IF(SUM(W14:X14)>=5,"Yes","No") | AE14: =IF(SUM(W14:X14)>=5,0,5-SUM(W14:X14)) | AF14: =IF(SUM(Z14:AA14)>=5,"Yes","No") | AG14: =IF(SUM(Z14:AA14)>=5,0,5-SUM(Z14:AA14))
A15: 3793772 | B15: 03 | C15: Utthishta Toastmasters | D15: =ClubDetails!G14 | E15: =ClubDetails!H14 | F15: =ClubDetails!I14 | G15: =IF(F15<5,"-",IF(E15>19,"Yes",IF(E15>D15+2,"Yes","-"))) | H15: =ClubDetails!K14 | I15: =IF(D15=0,0,H15/D15) | J15: =IF(H15=0,"Renewals not here",IF(H15<3,"Ineligible",IF(D15<8,"Low","Active"))) | K15: =ClubDetails!L14 | L15: =IF(D15=0,0,K15/D15) | M15: =IF(K15=0,"Renewals not here",IF(K15<3,"Ineligible",IF(E15<8,"Low","Active"))) | N15: =ClubDetails!M14 | O15: =ClubDetails!J14 | P15: 0 | Q15: 0 | R15: 0 | S15: 0 | T15: 0 | U15: 0 | V15: 0 | W15: 0 | X15: 0 | Y15: 0 | Z15: 0 | AA15: 0 | AB15: =IF(SUM(Q15:R15)>=5,"Yes","No") | AC15: =IF(SUM(Q15:R15)>=5,0,5-SUM(Q15:R15)) | AD15: =IF(SUM(W15:X15)>=5,"Yes","No") | AE15: =IF(SUM(W15:X15)>=5,0,5-SUM(W15:X15)) | AF15: =IF(SUM(Z15:AA15)>=5,"Yes","No") | AG15: =IF(SUM(Z15:AA15)>=5,0,5-SUM(Z15:AA15))
... A29: 843182 | B29: 05 | C29: Speech Master CMS Toastmasters Club | D29: =ClubDetails!G28 | E29: =ClubDetails!H28 | F29: =ClubDetails!I28 | G29: =IF(F29<5,"-",IF(E29>19,"Yes",IF(E29>D29+2,"Yes","-"))) | H29: =ClubDetails!K28 | I29: =IF(D29=0,0,H29/D29) | J29: =IF(H29=0,"Renewals not here",IF(H29<3,"Ineligible",IF(D29<8,"Low","Active"))) | K29: =ClubDetails!L28 | L29: =IF(D29=0,0,K29/D29) | M29: =IF(K29=0,"Renewals not here",IF(K29<3,"Ineligible",IF(E29<8,"Low","Active"))) | N29: =ClubDetails!M28 | O29: =ClubDetails!J28 | P29: 0 | Q29: 0 | R29: 0 | S29: 0 | T29: 0 | U29: 0 | V29: 0 | W29: 0 | X29: 0 | Y29: 0 | Z29: 0 | AA29: 0 | AB29: =IF(SUM(Q29:R29)>=5,"Yes","No") | AC29: =IF(SUM(Q29:R29)>=5,0,5-SUM(Q29:R29)) | AD29: =IF(SUM(W29:X29)>=5,"Yes","No") | AE29: =IF(SUM(W29:X29)>=5,0,5-SUM(W29:X29)) | AF29: =IF(SUM(Z29:AA29)>=5,"Yes","No") | AG29: =IF(SUM(Z29:AA29)>=5,0,5-SUM(Z29:AA29))
A30: Total / Average | D30: =SUM(D4:D29) | E30: =SUM(E4:E29) | F30: =AVERAGE(F4:F29) | G30: =COUNTIF(G4:G29,"Yes") | H30: =SUM(H4:H29) | I30: =IF(D30=0,0,H30/D30) | K30: =SUM(K4:K29) | L30: =IF(D30=0,0,K30/D30) | N30: =SUM(N4:N29) | O30: =SUM(O4:O29) | P30: =SUM(P4:P29) | Q30: =SUM(Q4:Q29) | R30: =SUM(R4:R29) | S30: =SUM(S4:S29) | T30: =SUM(T4:T29) | U30: =SUM(U4:U29) | ... AA30: =SUM(AA4:AA29) | AB30: =COUNTIF(AB4:AB29,"Yes") | AC30: =SUM(AC4:AC29) | AD30: =COUNTIF(AD4:AD29,"Yes") | AE30: =SUM(AE4:AE29) | AF30: =COUNTIF(AF4:AF29,"Yes") | AG30: =SUM(AG4:AG29)

Sheet Division B
A1: Division B - Membership and Payments Performance
A3: Club Number | B3: Area | C3: Club Name | D3: Base Membership | E3: Active Membership | F3: DCP Goals Met | G3: Distinguished Status | H3: September Renewals | I3: September Renewals % | J3: September Renewal Status | K3: March Renewals | L3: March Renewals % | M3: March Renewal Status | N3: Total Payments | O3: Total New Members | P3: July | Q3: August | R3: September | S3: October | T3: November | U3: December | V3: January | W3: February | X3: March | Y3: April | Z3: May | AA3: June | AB3: Smedley Award Eligibility | AC3: Smedley Award Goal | AD3: Talk Up Eligibility | AE3: Talk Up Goal | AF3: Beat the Clock Eligibility | AG3: Beat the Clock Goal
A4: 7335393 | B4: 01 | C4: Shivamogga Toastmasters | D4: =ClubDetails!G29 | E4: =ClubDetails!H29 | F4: =ClubDetails!I29 | G4: =IF(F4<5,"-",IF(E4>19,"Yes",IF(E4>D4+2,"Yes","-"))) | H4: =ClubDetails!K29 | I4: =IF(D4=0,0,H4/D4) | J4: =IF(H4=0,"Renewals not here",IF(H4<3,"Ineligible",IF(D4<8,"Low","Active"))) | K4: =ClubDetails!L29 | L4: =IF(D4=0,0,K4/D4) | M4: =IF(K4=0,"Renewals not here",IF(K4<3,"Ineligible",IF(E4<8,"Low","Active"))) | N4: =ClubDetails!M29 | O4: =ClubDetails!J29 | P4: 0 | Q4: 0 | R4: 0 | S4: 0 | T4: 0 | U4: 0 | V4: 0 | W4: 0 | X4: 0 | Y4: 0 | Z4: 0 | AA4: 0 | AB4: =IF(SUM(Q4:R4)>=5,"Yes","No") | AC4: =IF(SUM(Q4:R4)>=5,0,5-SUM(Q4:R4)) | AD4: =IF(SUM(W4:X4)>=5,"Yes","No") | AE4: =IF(SUM(W4:X4)>=5,0,5-SUM(W4:X4)) | AF4: =IF(SUM(Z4:AA4)>=5,"Yes","No") | AG4: =IF(SUM(Z4:AA4)>=5,0,5-SUM(Z4:AA4))
A5: 28675426 | B5: 01 | C5: Valyou Toastmasters | D5: =ClubDetails!G30 | E5: =ClubDetails!H30 | F5: =ClubDetails!I30 | G5: =IF(F5<5,"-",IF(E5>19,"Yes",IF(E5>D5+2,"Yes","-"))) | H5: =ClubDetails!K30 | I5: =IF(D5=0,0,H5/D5) | J5: =IF(H5=0,"Renewals not here",IF(H5<3,"Ineligible",IF(D5<8,"Low","Active"))) | K5: =ClubDetails!L30 | L5: =IF(D5=0,0,K5/D5) | M5: =IF(K5=0,"Renewals not here",IF(K5<3,"Ineligible",IF(E5<8,"Low","Active"))) | N5: =ClubDetails!M30 | O5: =ClubDetails!J30 | P5: 0 | Q5: 0 | R5: 0 | S5: 0 | T5: 0 | U5: 0 | V5: 0 | W5: 0 | X5: 0 | Y5: 0 | Z5: 0 | AA5: 0 | AB5: =IF(SUM(Q5:R5)>=5,"Yes","No") | AC5: =IF(SUM(Q5:R5)>=5,0,5-SUM(Q5:R5)) | AD5: =IF(SUM(W5:X5)>=5,"Yes","No") | AE5: =IF(SUM(W5:X5)>=5,0,5-SUM(W5:X5)) | AF5: =IF(SUM(Z5:AA5)>=5,"Yes","No") | AG5: =IF(SUM(Z5:AA5)>=5,0,5-SUM(Z5:AA5))
A6: 28676014 | B6: 01 | C6: Autodesk Toastmasters Club | D6: =ClubDetails!G31 | E6: =ClubDetails!H31 | F6: =ClubDetails!I31 | G6: =IF(F6<5,"-",IF(E6>19,"Yes",IF(E6>D6+2,"Yes","-"))) | H6: =ClubDetails!K31 | I6: =IF(D6=0,0,H6/D6) | J6: =IF(H6=0,"Renewals not here",IF(H6<3,"Ineligible",IF(D6<8,"Low","Active"))) | K6: =ClubDetails!L31 | L6: =IF(D6=0,0,K6/D6) | M6: =IF(K6=0,"Renewals not here",IF(K6<3,"Ineligible",IF(E6<8,"Low","Active"))) | N6: =ClubDetails!M31 | O6: =ClubDetails!J31 | P6: 0 | Q6: 0 | R6: 0 | S6: 0 | T6: 0 | U6: 0 | V6: 0 | W6: 0 | X6: 0 | Y6: 0 | Z6: 0 | AA6: 0 | AB6: =IF(SUM(Q6:R6)>=5,"Yes","No") | AC6: =IF(SUM(Q6:R6)>=5,0,5-SUM(Q6:R6)) | AD6: =IF(SUM(W6:X6)>=5,"Yes","No") | AE6: =IF(SUM(W6:X6)>=5,0,5-SUM(W6:X6)) | AF6: =IF(SUM(Z6:AA6)>=5,"Yes","No") | AG6: =IF(SUM(Z6:AA6)>=5,0,5-SUM(Z6:AA6))
A7: 28676901 | B7: 01 | C7: Accenture Toasters | D7: =ClubDetails!G32 | E7: =ClubDetails!H32 | F7: =ClubDetails!I32 | G7: =IF(F7<5,"-",IF(E7>19,"Yes",IF(E7>D7+2,"Yes","-"))) | H7: =ClubDetails!K32 | I7: =IF(D7=0,0,H7/D7) | J7: =IF(H7=0,"Renewals not here",IF(H7<3,"Ineligible",IF(D7<8,"Low","Active"))) | K7: =ClubDetails!L32 | L7: =IF(D7=0,0,K7/D7) | M7: =IF(K7=0,"Renewals not here",IF(K7<3,"Ineligible",IF(E7<8,"Low","Active"))) | N7: =ClubDetails!M32 | O7: =ClubDetails!J32 | P7: 0 | Q7: 0 | R7: 0 | S7: 0 | T7: 0 | U7: 0 | V7: 0 | W7: 0 | X7: 0 | Y7: 0 | Z7: 0 | AA7: 0 | AB7: =IF(SUM(Q7:R7)>=5,"Yes","No") | AC7: =IF(SUM(Q7:R7)>=5,0,5-SUM(Q7:R7)) | AD7: =IF(SUM(W7:X7)>=5,"Yes","No") | AE7: =IF(SUM(W7:X7)>=5,0,5-SUM(W7:X7)) | AF7: =IF(SUM(Z7:AA7)>=5,"Yes","No") | AG7: =IF(SUM(Z7:AA7)>=5,0,5-SUM(Z7:AA7))
A8: 28678720 | B8: 01 | C8: Acharyas Speaking Forum | D8: =ClubDetails!G33 | E8: =ClubDetails!H33 | F8: =ClubDetails!I33 | G8: =IF(F8<5,"-",IF(E8>19,"Yes",IF(E8>D8+2,"Yes","-"))) | H8: =ClubDetails!K33 | I8: =IF(D8=0,0,H8/D8) | J8: =IF(H8=0,"Renewals not here",IF(H8<3,"Ineligible",IF(D8<8,"Low","Active"))) | K8: =ClubDetails!L33 | L8: =IF(D8=0,0,K8/D8) | M8: =IF(K8=0,"Renewals not here",IF(K8<3,"Ineligible",IF(E8<8,"Low","Active"))) | N8: =ClubDetails!M33 | O8: =ClubDetails!J33 | P8: 0 | Q8: 0 | R8: 0 | S8: 0 | T8: 0 | U8: 0 | V8: 0 | W8: 0 | X8: 0 | Y8: 0 | Z8: 0 | AA8: 0 | AB8: =IF(SUM(Q8:R8)>=5,"Yes","No") | AC8: =IF(SUM(Q8:R8)>=5,0,5-SUM(Q8:R8)) | AD8: =IF(SUM(W8:X8)>=5,"Yes","No") | AE8: =IF(SUM(W8:X8)>=5,0,5-SUM(W8:X8)) | AF8: =IF(SUM(Z8:AA8)>=5,"Yes","No") | AG8: =IF(SUM(Z8:AA8)>=5,0,5-SUM(Z8:AA8))
A9: 28678997 | B9: 01 | C9: Paychex Catalyst Crew 2 | D9: =ClubDetails!G34 | E9: =ClubDetails!H34 | F9: =ClubDetails!I34 | G9: =IF(F9<5,"-",IF(E9>19,"Yes",IF(E9>D9+2,"Yes","-"))) | H9: =ClubDetails!K34 | I9: =IF(D9=0,0,H9/D9) | J9: =IF(H9=0,"Renewals not here",IF(H9<3,"Ineligible",IF(D9<8,"Low","Active"))) | K9: =ClubDetails!L34 | L9: =IF(D9=0,0,K9/D9) | M9: =IF(K9=0,"Renewals not here",IF(K9<3,"Ineligible",IF(E9<8,"Low","Active"))) | N9: =ClubDetails!M34 | O9: =ClubDetails!J34 | P9: 0 | Q9: 0 | R9: 0 | S9: 0 | T9: 0 | U9: 0 | V9: 0 | W9: 0 | X9: 0 | Y9: 0 | Z9: 0 | AA9: 0 | AB9: =IF(SUM(Q9:R9)>=5,"Yes","No") | AC9: =IF(SUM(Q9:R9)>=5,0,5-SUM(Q9:R9)) | AD9: =IF(SUM(W9:X9)>=5,"Yes","No") | AE9: =IF(SUM(W9:X9)>=5,0,5-SUM(W9:X9)) | AF9: =IF(SUM(Z9:AA9)>=5,"Yes","No") | AG9: =IF(SUM(Z9:AA9)>=5,0,5-SUM(Z9:AA9))
A10: 547 | B10: 02 | C10: deejays Toastmasters | D10: =ClubDetails!G35 | E10: =ClubDetails!H35 | F10: =ClubDetails!I35 | G10: =IF(F10<5,"-",IF(E10>19,"Yes",IF(E10>D10+2,"Yes","-"))) | H10: =ClubDetails!K35 | I10: =IF(D10=0,0,H10/D10) | J10: =IF(H10=0,"Renewals not here",IF(H10<3,"Ineligible",IF(D10<8,"Low","Active"))) | K10: =ClubDetails!L35 | L10: =IF(D10=0,0,K10/D10) | M10: =IF(K10=0,"Renewals not here",IF(K10<3,"Ineligible",IF(E10<8,"Low","Active"))) | N10: =ClubDetails!M35 | O10: =ClubDetails!J35 | P10: 0 | Q10: 0 | R10: 0 | S10: 0 | T10: 0 | U10: 0 | V10: 0 | W10: 0 | X10: 0 | Y10: 0 | Z10: 0 | AA10: 0 | AB10: =IF(SUM(Q10:R10)>=5,"Yes","No") | AC10: =IF(SUM(Q10:R10)>=5,0,5-SUM(Q10:R10)) | AD10: =IF(SUM(W10:X10)>=5,"Yes","No") | AE10: =IF(SUM(W10:X10)>=5,0,5-SUM(W10:X10)) | AF10: =IF(SUM(Z10:AA10)>=5,"Yes","No") | AG10: =IF(SUM(Z10:AA10)>=5,0,5-SUM(Z10:AA10))
A11: 7734175 | B11: 02 | C11: Republic of Toastmasters | D11: =ClubDetails!G36 | E11: =ClubDetails!H36 | F11: =ClubDetails!I36 | G11: =IF(F11<5,"-",IF(E11>19,"Yes",IF(E11>D11+2,"Yes","-"))) | H11: =ClubDetails!K36 | I11: =IF(D11=0,0,H11/D11) | J11: =IF(H11=0,"Renewals not here",IF(H11<3,"Ineligible",IF(D11<8,"Low","Active"))) | K11: =ClubDetails!L36 | L11: =IF(D11=0,0,K11/D11) | M11: =IF(K11=0,"Renewals not here",IF(K11<3,"Ineligible",IF(E11<8,"Low","Active"))) | N11: =ClubDetails!M36 | O11: =ClubDetails!J36 | P11: 0 | Q11: 0 | R11: 0 | S11: 0 | T11: 0 | U11: 0 | V11: 0 | W11: 0 | X11: 0 | Y11: 0 | Z11: 0 | AA11: 0 | AB11: =IF(SUM(Q11:R11)>=5,"Yes","No") | AC11: =IF(SUM(Q11:R11)>=5,0,5-SUM(Q11:R11)) | AD11: =IF(SUM(W11:X11)>=5,"Yes","No") | AE11: =IF(SUM(W11:X11)>=5,0,5-SUM(W11:X11)) | AF11: =IF(SUM(Z11:AA11)>=5,"Yes","No") | AG11: =IF(SUM(Z11:AA11)>=5,0,5-SUM(Z11:AA11))
A12: 28677183 | B12: 02 | C12: Titans Toastmasters Club | D12: =ClubDetails!G37 | E12: =ClubDetails!H37 | F12: =ClubDetails!I37 | G12: =IF(F12<5,"-",IF(E12>19,"Yes",IF(E12>D12+2,"Yes","-"))) | H12: =ClubDetails!K37 | I12: =IF(D12=0,0,H12/D12) | J12: =IF(H12=0,"Renewals not here",IF(H12<3,"Ineligible",IF(D12<8,"Low","Active"))) | K12: =ClubDetails!L37 | L12: =IF(D12=0,0,K12/D12) | M12: =IF(K12=0,"Renewals not here",IF(K12<3,"Ineligible",IF(E12<8,"Low","Active"))) | N12: =ClubDetails!M37 | O12: =ClubDetails!J37 | P12: 0 | Q12: 0 | R12: 0 | S12: 0 | T12: 0 | U12: 0 | V12: 0 | W12: 0 | X12: 0 | Y12: 0 | Z12: 0 | AA12: 0 | AB12: =IF(SUM(Q12:R12)>=5,"Yes","No") | AC12: =IF(SUM(Q12:R12)>=5,0,5-SUM(Q12:R12)) | AD12: =IF(SUM(W12:X12)>=5,"Yes","No") | AE12: =IF(SUM(W12:X12)>=5,0,5-SUM(W12:X12)) | AF12: =IF(SUM(Z12:AA12)>=5,"Yes","No") | AG12: =IF(SUM(Z12:AA12)>=5,0,5-SUM(Z12:AA12))
A13: 28678400 | B13: 02 | C13: Voices of Pearson Toastmasters Club | D13: =ClubDetails!G38 | E13: =ClubDetails!H38 | F13: =ClubDetails!I38 | G13: =IF(F13<5,"-",IF(E13>19,"Yes",IF(E13>D13+2,"Yes","-"))) | H13: =ClubDetails!K38 | I13: =IF(D13=0,0,H13/D13) | J13: =IF(H13=0,"Renewals not here",IF(H13<3,"Ineligible",IF(D13<8,"Low","Active"))) | K13: =ClubDetails!L38 | L13: =IF(D13=0,0,K13/D13) | M13: =IF(K13=0,"Renewals not here",IF(K13<3,"Ineligible",IF(E13<8,"Low","Active"))) | N13: =ClubDetails!M38 | O13: =ClubDetails!J38 | P13: 0 | Q13: 0 | R13: 0 | S13: 0 | T13: 0 | U13: 0 | V13: 0 | W13: 0 | X13: 0 | Y13: 0 | Z13: 0 | AA13: 0 | AB13: =IF(SUM(Q13:R13)>=5,"Yes","No") | AC13: =IF(SUM(Q13:R13)>=5,0,5-SUM(Q13:R13)) | AD13: =IF(SUM(W13:X13)>=5,"Yes","No") | AE13: =IF(SUM(W13:X13)>=5,0,5-SUM(W13:X13)) | AF13: =IF(SUM(Z13:AA13)>=5,"Yes","No") | AG13: =IF(SUM(Z13:AA13)>=5,0,5-SUM(Z13:AA13))
A14: 28678746 | B14: 02 | C14: The Orator's Society | D14: =ClubDetails!G39 | E14: =ClubDetails!H39 | F14: =ClubDetails!I39 | G14: =IF(F14<5,"-",IF(E14>19,"Yes",IF(E14>D14+2,"Yes","-"))) | H14: =ClubDetails!K39 | I14: =IF(D14=0,0,H14/D14) | J14: =IF(H14=0,"Renewals not here",IF(H14<3,"Ineligible",IF(D14<8,"Low","Active"))) | K14: =ClubDetails!L39 | L14: =IF(D14=0,0,K14/D14) | M14: =IF(K14=0,"Renewals not here",IF(K14<3,"Ineligible",IF(E14<8,"Low","Active"))) | N14: =ClubDetails!M39 | O14: =ClubDetails!J39 | P14: 0 | Q14: 0 | R14: 0 | S14: 0 | T14: 0 | U14: 0 | V14: 0 | W14: 0 | X14: 0 | Y14: 0 | Z14: 0 | AA14: 0 | AB14: =IF(SUM(Q14:R14)>=5,"Yes","No") | AC14: =IF(SUM(Q14:R14)>=5,0,5-SUM(Q14:R14)) | AD14: =IF(SUM(W14:X14)>=5,"Yes","No") | AE14: =IF(SUM(W14:X14)>=5,0,5-SUM(W14:X14)) | AF14: =IF(SUM(Z14:AA14)>=5,"Yes","No") | AG14: =IF(SUM(Z14:AA14)>=5,0,5-SUM(Z14:AA14))
A15: 6975394 | B15: 03 | C15: Toastmasters of HP | D15: =ClubDetails!G40 | E15: =ClubDetails!H40 | F15: =ClubDetails!I40 | G15: =IF(F15<5,"-",IF(E15>19,"Yes",IF(E15>D15+2,"Yes","-"))) | H15: =ClubDetails!K40 | I15: =IF(D15=0,0,H15/D15) | J15: =IF(H15=0,"Renewals not here",IF(H15<3,"Ineligible",IF(D15<8,"Low","Active"))) | K15: =ClubDetails!L40 | L15: =IF(D15=0,0,K15/D15) | M15: =IF(K15=0,"Renewals not here",IF(K15<3,"Ineligible",IF(E15<8,"Low","Active"))) | N15: =ClubDetails!M40 | O15: =ClubDetails!J40 | P15: 0 | Q15: 0 | R15: 0 | S15: 0 | T15: 0 | U15: 0 | V15: 0 | W15: 0 | X15: 0 | Y15: 0 | Z15: 0 | AA15: 0 | AB15: =IF(SUM(Q15:R15)>=5,"Yes","No") | AC15: =IF(SUM(Q15:R15)>=5,0,5-SUM(Q15:R15)) | AD15: =IF(SUM(W15:X15)>=5,"Yes","No") | AE15: =IF(SUM(W15:X15)>=5,0,5-SUM(W15:X15)) | AF15: =IF(SUM(Z15:AA15)>=5,"Yes","No") | AG15: =IF(SUM(Z15:AA15)>=5,0,5-SUM(Z15:AA15))
... A24: 28677046 | B24: 04 | C24: Bosch Adugodi | D24: =ClubDetails!G49 | E24: =ClubDetails!H49 | F24: =ClubDetails!I49 | G24: =IF(F24<5,"-",IF(E24>19,"Yes",IF(E24>D24+2,"Yes","-"))) | H24: =ClubDetails!K49 | I24: =IF(D24=0,0,H24/D24) | J24: =IF(H24=0,"Renewals not here",IF(H24<3,"Ineligible",IF(D24<8,"Low","Active"))) | K24: =ClubDetails!L49 | L24: =IF(D24=0,0,K24/D24) | M24: =IF(K24=0,"Renewals not here",IF(K24<3,"Ineligible",IF(E24<8,"Low","Active"))) | N24: =ClubDetails!M49 | O24: =ClubDetails!J49 | P24: 0 | Q24: 0 | R24: 0 | S24: 0 | T24: 0 | U24: 0 | V24: 0 | W24: 0 | X24: 0 | Y24: 0 | Z24: 0 | AA24: 0 | AB24: =IF(SUM(Q24:R24)>=5,"Yes","No") | AC24: =IF(SUM(Q24:R24)>=5,0,5-SUM(Q24:R24)) | AD24: =IF(SUM(W24:X24)>=5,"Yes","No") | AE24: =IF(SUM(W24:X24)>=5,0,5-SUM(W24:X24)) | AF24: =IF(SUM(Z24:AA24)>=5,"Yes","No") | AG24: =IF(SUM(Z24:AA24)>=5,0,5-SUM(Z24:AA24))
A25: Total / Average | D25: =SUM(D4:D24) | E25: =SUM(E4:E24) | F25: =AVERAGE(F4:F24) | G25: =COUNTIF(G4:G24,"Yes") | H25: =SUM(H4:H24) | I25: =IF(D25=0,0,H25/D25) | K25: =SUM(K4:K24) | L25: =IF(D25=0,0,K25/D25) | N25: =SUM(N4:N24) | O25: =SUM(O4:O24) | P25: =SUM(P4:P24) | Q25: =SUM(Q4:Q24) | R25: =SUM(R4:R24) | S25: =SUM(S4:S24) | T25: =SUM(T4:T24) | U25: =SUM(U4:U24) | ... AA25: =SUM(AA4:AA24) | AB25: =COUNTIF(AB4:AB24,"Yes") | AC25: =SUM(AC4:AC24) | AD25: =COUNTIF(AD4:AD24,"Yes") | AE25: =SUM(AE4:AE24) | AF25: =COUNTIF(AF4:AF24,"Yes") | AG25: =SUM(AG4:AG24)

Sheet Division C
A1: Division C - Membership and Payments Performance
A3: Club Number | B3: Area | C3: Club Name | D3: Base Membership | E3: Active Membership | F3: DCP Goals Met | G3: Distinguished Status | H3: September Renewals | I3: September Renewals % | J3: September Renewal Status | K3: March Renewals | L3: March Renewals % | M3: March Renewal Status | N3: Total Payments | O3: Total New Members | P3: July | Q3: August | R3: September | S3: October | T3: November | U3: December | V3: January | W3: February | X3: March | Y3: April | Z3: May | AA3: June | AB3: Smedley Award Eligibility | AC3: Smedley Award Goal | AD3: Talk Up Eligibility | AE3: Talk Up Goal | AF3: Beat the Clock Eligibility | AG3: Beat the Clock Goal
A4: 1389390 | B4: 01 | C4: IIMB Orators Club | D4: =ClubDetails!G50 | E4: =ClubDetails!H50 | F4: =ClubDetails!I50 | G4: =IF(F4<5,"-",IF(E4>19,"Yes",IF(E4>D4+2,"Yes","-"))) | H4: =ClubDetails!K50 | I4: =IF(D4=0,0,H4/D4) | J4: =IF(H4=0,"Renewals not here",IF(H4<3,"Ineligible",IF(D4<8,"Low","Active"))) | K4: =ClubDetails!L50 | L4: =IF(D4=0,0,K4/D4) | M4: =IF(K4=0,"Renewals not here",IF(K4<3,"Ineligible",IF(E4<8,"Low","Active"))) | N4: =ClubDetails!M50 | O4: =ClubDetails!J50 | P4: 0 | Q4: 0 | R4: 0 | S4: 0 | T4: 0 | U4: 0 | V4: 0 | W4: 0 | X4: 0 | Y4: 0 | Z4: 0 | AA4: 0 | AB4: =IF(SUM(Q4:R4)>=5,"Yes","No") | AC4: =IF(SUM(Q4:R4)>=5,0,5-SUM(Q4:R4)) | AD4: =IF(SUM(W4:X4)>=5,"Yes","No") | AE4: =IF(SUM(W4:X4)>=5,0,5-SUM(W4:X4)) | AF4: =IF(SUM(Z4:AA4)>=5,"Yes","No") | AG4: =IF(SUM(Z4:AA4)>=5,0,5-SUM(Z4:AA4))
A5: 7514725 | B5: 01 | C5: LKQI Toastmasters Club | D5: =ClubDetails!G51 | E5: =ClubDetails!H51 | F5: =ClubDetails!I51 | G5: =IF(F5<5,"-",IF(E5>19,"Yes",IF(E5>D5+2,"Yes","-"))) | H5: =ClubDetails!K51 | I5: =IF(D5=0,0,H5/D5) | J5: =IF(H5=0,"Renewals not here",IF(H5<3,"Ineligible",IF(D5<8,"Low","Active"))) | K5: =ClubDetails!L51 | L5: =IF(D5=0,0,K5/D5) | M5: =IF(K5=0,"Renewals not here",IF(K5<3,"Ineligible",IF(E5<8,"Low","Active"))) | N5: =ClubDetails!M51 | O5: =ClubDetails!J51 | P5: 0 | Q5: 0 | R5: 0 | S5: 0 | T5: 0 | U5: 0 | V5: 0 | W5: 0 | X5: 0 | Y5: 0 | Z5: 0 | AA5: 0 | AB5: =IF(SUM(Q5:R5)>=5,"Yes","No") | AC5: =IF(SUM(Q5:R5)>=5,0,5-SUM(Q5:R5)) | AD5: =IF(SUM(W5:X5)>=5,"Yes","No") | AE5: =IF(SUM(W5:X5)>=5,0,5-SUM(W5:X5)) | AF5: =IF(SUM(Z5:AA5)>=5,"Yes","No") | AG5: =IF(SUM(Z5:AA5)>=5,0,5-SUM(Z5:AA5))
A6: 7762021 | B6: 01 | C6: Christ Toastmasters Club | D6: =ClubDetails!G52 | E6: =ClubDetails!H52 | F6: =ClubDetails!I52 | G6: =IF(F6<5,"-",IF(E6>19,"Yes",IF(E6>D6+2,"Yes","-"))) | H6: =ClubDetails!K52 | I6: =IF(D6=0,0,H6/D6) | J6: =IF(H6=0,"Renewals not here",IF(H6<3,"Ineligible",IF(D6<8,"Low","Active"))) | K6: =ClubDetails!L52 | L6: =IF(D6=0,0,K6/D6) | M6: =IF(K6=0,"Renewals not here",IF(K6<3,"Ineligible",IF(E6<8,"Low","Active"))) | N6: =ClubDetails!M52 | O6: =ClubDetails!J52 | P6: 0 | Q6: 0 | R6: 0 | S6: 0 | T6: 0 | U6: 0 | V6: 0 | W6: 0 | X6: 0 | Y6: 0 | Z6: 0 | AA6: 0 | AB6: =IF(SUM(Q6:R6)>=5,"Yes","No") | AC6: =IF(SUM(Q6:R6)>=5,0,5-SUM(Q6:R6)) | AD6: =IF(SUM(W6:X6)>=5,"Yes","No") | AE6: =IF(SUM(W6:X6)>=5,0,5-SUM(W6:X6)) | AF6: =IF(SUM(Z6:AA6)>=5,"Yes","No") | AG6: =IF(SUM(Z6:AA6)>=5,0,5-SUM(Z6:AA6))
A7: 28678373 | B7: 01 | C7: Sense-say-tional Toastmasters | D7: =ClubDetails!G53 | E7: =ClubDetails!H53 | F7: =ClubDetails!I53 | G7: =IF(F7<5,"-",IF(E7>19,"Yes",IF(E7>D7+2,"Yes","-"))) | H7: =ClubDetails!K53 | I7: =IF(D7=0,0,H7/D7) | J7: =IF(H7=0,"Renewals not here",IF(H7<3,"Ineligible",IF(D7<8,"Low","Active"))) | K7: =ClubDetails!L53 | L7: =IF(D7=0,0,K7/D7) | M7: =IF(K7=0,"Renewals not here",IF(K7<3,"Ineligible",IF(E7<8,"Low","Active"))) | N7: =ClubDetails!M53 | O7: =ClubDetails!J53 | P7: 0 | Q7: 0 | R7: 0 | S7: 0 | T7: 0 | U7: 0 | V7: 0 | W7: 0 | X7: 0 | Y7: 0 | Z7: 0 | AA7: 0 | AB7: =IF(SUM(Q7:R7)>=5,"Yes","No") | AC7: =IF(SUM(Q7:R7)>=5,0,5-SUM(Q7:R7)) | AD7: =IF(SUM(W7:X7)>=5,"Yes","No") | AE7: =IF(SUM(W7:X7)>=5,0,5-SUM(W7:X7)) | AF7: =IF(SUM(Z7:AA7)>=5,"Yes","No") | AG7: =IF(SUM(Z7:AA7)>=5,0,5-SUM(Z7:AA7))
A8: 9639 | B8: 02 | C8: Mecon Communication Club | D8: =ClubDetails!G54 | E8: =ClubDetails!H54 | F8: =ClubDetails!I54 | G8: =IF(F8<5,"-",IF(E8>19,"Yes",IF(E8>D8+2,"Yes","-"))) | H8: =ClubDetails!K54 | I8: =IF(D8=0,0,H8/D8) | J8: =IF(H8=0,"Renewals not here",IF(H8<3,"Ineligible",IF(D8<8,"Low","Active"))) | K8: =ClubDetails!L54 | L8: =IF(D8=0,0,K8/D8) | M8: =IF(K8=0,"Renewals not here",IF(K8<3,"Ineligible",IF(E8<8,"Low","Active"))) | N8: =ClubDetails!M54 | O8: =ClubDetails!J54 | P8: 0 | Q8: 0 | R8: 0 | S8: 0 | T8: 0 | U8: 0 | V8: 0 | W8: 0 | X8: 0 | Y8: 0 | Z8: 0 | AA8: 0 | AB8: =IF(SUM(Q8:R8)>=5,"Yes","No") | AC8: =IF(SUM(Q8:R8)>=5,0,5-SUM(Q8:R8)) | AD8: =IF(SUM(W8:X8)>=5,"Yes","No") | AE8: =IF(SUM(W8:X8)>=5,0,5-SUM(W8:X8)) | AF8: =IF(SUM(Z8:AA8)>=5,"Yes","No") | AG8: =IF(SUM(Z8:AA8)>=5,0,5-SUM(Z8:AA8))
A9: 4329635 | B9: 02 | C9: Tarento India Toastmasters Club | D9: =ClubDetails!G55 | E9: =ClubDetails!H55 | F9: =ClubDetails!I55 | G9: =IF(F9<5,"-",IF(E9>19,"Yes",IF(E9>D9+2,"Yes","-"))) | H9: =ClubDetails!K55 | I9: =IF(D9=0,0,H9/D9) | J9: =IF(H9=0,"Renewals not here",IF(H9<3,"Ineligible",IF(D9<8,"Low","Active"))) | K9: =ClubDetails!L55 | L9: =IF(D9=0,0,K9/D9) | M9: =IF(K9=0,"Renewals not here",IF(K9<3,"Ineligible",IF(E9<8,"Low","Active"))) | N9: =ClubDetails!M55 | O9: =ClubDetails!J55 | P9: 0 | Q9: 0 | R9: 0 | S9: 0 | T9: 0 | U9: 0 | V9: 0 | W9: 0 | X9: 0 | Y9: 0 | Z9: 0 | AA9: 0 | AB9: =IF(SUM(Q9:R9)>=5,"Yes","No") | AC9: =IF(SUM(Q9:R9)>=5,0,5-SUM(Q9:R9)) | AD9: =IF(SUM(W9:X9)>=5,"Yes","No") | AE9: =IF(SUM(W9:X9)>=5,0,5-SUM(W9:X9)) | AF9: =IF(SUM(Z9:AA9)>=5,"Yes","No") | AG9: =IF(SUM(Z9:AA9)>=5,0,5-SUM(Z9:AA9))
A10: 6584495 | B10: 02 | C10: The Impressions | D10: =ClubDetails!G56 | E10: =ClubDetails!H56 | F10: =ClubDetails!I56 | G10: =IF(F10<5,"-",IF(E10>19,"Yes",IF(E10>D10+2,"Yes","-"))) | H10: =ClubDetails!K56 | I10: =IF(D10=0,0,H10/D10) | J10: =IF(H10=0,"Renewals not here",IF(H10<3,"Ineligible",IF(D10<8,"Low","Active"))) | K10: =ClubDetails!L56 | L10: =IF(D10=0,0,K10/D10) | M10: =IF(K10=0,"Renewals not here",IF(K10<3,"Ineligible",IF(E10<8,"Low","Active"))) | N10: =ClubDetails!M56 | O10: =ClubDetails!J56 | P10: 0 | Q10: 0 | R10: 0 | S10: 0 | T10: 0 | U10: 0 | V10: 0 | W10: 0 | X10: 0 | Y10: 0 | Z10: 0 | AA10: 0 | AB10: =IF(SUM(Q10:R10)>=5,"Yes","No") | AC10: =IF(SUM(Q10:R10)>=5,0,5-SUM(Q10:R10)) | AD10: =IF(SUM(W10:X10)>=5,"Yes","No") | AE10: =IF(SUM(W10:X10)>=5,0,5-SUM(W10:X10)) | AF10: =IF(SUM(Z10:AA10)>=5,"Yes","No") | AG10: =IF(SUM(Z10:AA10)>=5,0,5-SUM(Z10:AA10))
A11: 28675687 | B11: 02 | C11: School of Commerce, Jain University Toastmasters | D11: =ClubDetails!G57 | E11: =ClubDetails!H57 | F11: =ClubDetails!I57 | G11: =IF(F11<5,"-",IF(E11>19,"Yes",IF(E11>D11+2,"Yes","-"))) | H11: =ClubDetails!K57 | I11: =IF(D11=0,0,H11/D11) | J11: =IF(H11=0,"Renewals not here",IF(H11<3,"Ineligible",IF(D11<8,"Low","Active"))) | K11: =ClubDetails!L57 | L11: =IF(D11=0,0,K11/D11) | M11: =IF(K11=0,"Renewals not here",IF(K11<3,"Ineligible",IF(E11<8,"Low","Active"))) | N11: =ClubDetails!M57 | O11: =ClubDetails!J57 | P11: 0 | Q11: 0 | R11: 0 | S11: 0 | T11: 0 | U11: 0 | V11: 0 | W11: 0 | X11: 0 | Y11: 0 | Z11: 0 | AA11: 0 | AB11: =IF(SUM(Q11:R11)>=5,"Yes","No") | AC11: =IF(SUM(Q11:R11)>=5,0,5-SUM(Q11:R11)) | AD11: =IF(SUM(W11:X11)>=5,"Yes","No") | AE11: =IF(SUM(W11:X11)>=5,0,5-SUM(W11:X11)) | AF11: =IF(SUM(Z11:AA11)>=5,"Yes","No") | AG11: =IF(SUM(Z11:AA11)>=5,0,5-SUM(Z11:AA11))
A12: 2188958 | B12: 03 | C12: Koramangala Toastmasters Club | D12: =ClubDetails!G58 | E12: =ClubDetails!H58 | F12: =ClubDetails!I58 | G12: =IF(F12<5,"-",IF(E12>19,"Yes",IF(E12>D12+2,"Yes","-"))) | H12: =ClubDetails!K58 | I12: =IF(D12=0,0,H12/D12) | J12: =IF(H12=0,"Renewals not here",IF(H12<3,"Ineligible",IF(D12<8,"Low","Active"))) | K12: =ClubDetails!L58 | L12: =IF(D12=0,0,K12/D12) | M12: =IF(K12=0,"Renewals not here",IF(K12<3,"Ineligible",IF(E12<8,"Low","Active"))) | N12: =ClubDetails!M58 | O12: =ClubDetails!J58 | P12: 0 | Q12: 0 | R12: 0 | S12: 0 | T12: 0 | U12: 0 | V12: 0 | W12: 0 | X12: 0 | Y12: 0 | Z12: 0 | AA12: 0 | AB12: =IF(SUM(Q12:R12)>=5,"Yes","No") | AC12: =IF(SUM(Q12:R12)>=5,0,5-SUM(Q12:R12)) | AD12: =IF(SUM(W12:X12)>=5,"Yes","No") | AE12: =IF(SUM(W12:X12)>=5,0,5-SUM(W12:X12)) | AF12: =IF(SUM(Z12:AA12)>=5,"Yes","No") | AG12: =IF(SUM(Z12:AA12)>=5,0,5-SUM(Z12:AA12))
A13: 6636162 | B13: 03 | C13: BTM Toastmasters Club | D13: =ClubDetails!G59 | E13: =ClubDetails!H59 | F13: =ClubDetails!I59 | G13: =IF(F13<5,"-",IF(E13>19,"Yes",IF(E13>D13+2,"Yes","-"))) | H13: =ClubDetails!K59 | I13: =IF(D13=0,0,H13/D13) | J13: =IF(H13=0,"Renewals not here",IF(H13<3,"Ineligible",IF(D13<8,"Low","Active"))) | K13: =ClubDetails!L59 | L13: =IF(D13=0,0,K13/D13) | M13: =IF(K13=0,"Renewals not here",IF(K13<3,"Ineligible",IF(E13<8,"Low","Active"))) | N13: =ClubDetails!M59 | O13: =ClubDetails!J59 | P13: 0 | Q13: 0 | R13: 0 | S13: 0 | T13: 0 | U13: 0 | V13: 0 | W13: 0 | X13: 0 | Y13: 0 | Z13: 0 | AA13: 0 | AB13: =IF(SUM(Q13:R13)>=5,"Yes","No") | AC13: =IF(SUM(Q13:R13)>=5,0,5-SUM(Q13:R13)) | AD13: =IF(SUM(W13:X13)>=5,"Yes","No") | AE13: =IF(SUM(W13:X13)>=5,0,5-SUM(W13:X13)) | AF13: =IF(SUM(Z13:AA13)>=5,"Yes","No") | AG13: =IF(SUM(Z13:AA13)>=5,0,5-SUM(Z13:AA13))
A14: 6636175 | B14: 03 | C14: Clinisys Toastmasters Club | D14: =ClubDetails!G60 | E14: =ClubDetails!H60 | F14: =ClubDetails!I60 | G14: =IF(F14<5,"-",IF(E14>19,"Yes",IF(E14>D14+2,"Yes","-"))) | H14: =ClubDetails!K60 | I14: =IF(D14=0,0,H14/D14) | J14: =IF(H14=0,"Renewals not here",IF(H14<3,"Ineligible",IF(D14<8,"Low","Active"))) | K14: =ClubDetails!L60 | L14: =IF(D14=0,0,K14/D14) | M14: =IF(K14=0,"Renewals not here",IF(K14<3,"Ineligible",IF(E14<8,"Low","Active"))) | N14: =ClubDetails!M60 | O14: =ClubDetails!J60 | P14: 0 | Q14: 0 | R14: 0 | S14: 0 | T14: 0 | U14: 0 | V14: 0 | W14: 0 | X14: 0 | Y14: 0 | Z14: 0 | AA14: 0 | AB14: =IF(SUM(Q14:R14)>=5,"Yes","No") | AC14: =IF(SUM(Q14:R14)>=5,0,5-SUM(Q14:R14)) | AD14: =IF(SUM(W14:X14)>=5,"Yes","No") | AE14: =IF(SUM(W14:X14)>=5,0,5-SUM(W14:X14)) | AF14: =IF(SUM(Z14:AA14)>=5,"Yes","No") | AG14: =IF(SUM(Z14:AA14)>=5,0,5-SUM(Z14:AA14))
A15: 28676357 | B15: 03 | C15: Ascend Trailblazers Toastmasters Club | D15: =ClubDetails!G61 | E15: =ClubDetails!H61 | F15: =ClubDetails!I61 | G15: =IF(F15<5,"-",IF(E15>19,"Yes",IF(E15>D15+2,"Yes","-"))) | H15: =ClubDetails!K61 | I15: =IF(D15=0,0,H15/D15) | J15: =IF(H15=0,"Renewals not here",IF(H15<3,"Ineligible",IF(D15<8,"Low","Active"))) | K15: =ClubDetails!L61 | L15: =IF(D15=0,0,K15/D15) | M15: =IF(K15=0,"Renewals not here",IF(K15<3,"Ineligible",IF(E15<8,"Low","Active"))) | N15: =ClubDetails!M61 | O15: =ClubDetails!J61 | P15: 0 | Q15: 0 | R15: 0 | S15: 0 | T15: 0 | U15: 0 | V15: 0 | W15: 0 | X15: 0 | Y15: 0 | Z15: 0 | AA15: 0 | AB15: =IF(SUM(Q15:R15)>=5,"Yes","No") | AC15: =IF(SUM(Q15:R15)>=5,0,5-SUM(Q15:R15)) | AD15: =IF(SUM(W15:X15)>=5,"Yes","No") | AE15: =IF(SUM(W15:X15)>=5,0,5-SUM(W15:X15)) | AF15: =IF(SUM(Z15:AA15)>=5,"Yes","No") | AG15: =IF(SUM(Z15:AA15)>=5,0,5-SUM(Z15:AA15))
... A21: 7962666 | B21: 04 | C21: Transcend Toastmasters Club 3 | D21: =ClubDetails!G67 | E21: =ClubDetails!H67 | F21: =ClubDetails!I67 | G21: =IF(F21<5,"-",IF(E21>19,"Yes",IF(E21>D21+2,"Yes","-"))) | H21: =ClubDetails!K67 | I21: =IF(D21=0,0,H21/D21) | J21: =IF(H21=0,"Renewals not here",IF(H21<3,"Ineligible",IF(D21<8,"Low","Active"))) | K21: =ClubDetails!L67 | L21: =IF(D21=0,0,K21/D21) | M21: =IF(K21=0,"Renewals not here",IF(K21<3,"Ineligible",IF(E21<8,"Low","Active"))) | N21: =ClubDetails!M67 | O21: =ClubDetails!J67 | P21: 0 | Q21: 0 | R21: 0 | S21: 0 | T21: 0 | U21: 0 | V21: 0 | W21: 0 | X21: 0 | Y21: 0 | Z21: 0 | AA21: 0 | AB21: =IF(SUM(Q21:R21)>=5,"Yes","No") | AC21: =IF(SUM(Q21:R21)>=5,0,5-SUM(Q21:R21)) | AD21: =IF(SUM(W21:X21)>=5,"Yes","No") | AE21: =IF(SUM(W21:X21)>=5,0,5-SUM(W21:X21)) | AF21: =IF(SUM(Z21:AA21)>=5,"Yes","No") | AG21: =IF(SUM(Z21:AA21)>=5,0,5-SUM(Z21:AA21))
A22: Total / Average | D22: =SUM(D4:D21) | E22: =SUM(E4:E21) | F22: =AVERAGE(F4:F21) | G22: =COUNTIF(G4:G21,"Yes") | H22: =SUM(H4:H21) | I22: =IF(D22=0,0,H22/D22) | K22: =SUM(K4:K21) | L22: =IF(D22=0,0,K22/D22) | N22: =SUM(N4:N21) | O22: =SUM(O4:O21) | P22: =SUM(P4:P21) | Q22: =SUM(Q4:Q21) | R22: =SUM(R4:R21) | S22: =SUM(S4:S21) | T22: =SUM(T4:T21) | U22: =SUM(U4:U21) | ... AA22: =SUM(AA4:AA21) | AB22: =COUNTIF(AB4:AB21,"Yes") | AC22: =SUM(AC4:AC21) | AD22: =COUNTIF(AD4:AD21,"Yes") | AE22: =SUM(AE4:AE21) | AF22: =COUNTIF(AF4:AF21,"Yes") | AG22: =SUM(AG4:AG21)

Sheet Division D
A1: Division D - Membership and Payments Performance
A3: Club Number | B3: Area | C3: Club Name | D3: Base Membership | E3: Active Membership | F3: DCP Goals Met | G3: Distinguished Status | H3: September Renewals | I3: September Renewals % | J3: September Renewal Status | K3: March Renewals | L3: March Renewals % | M3: March Renewal Status | N3: Total Payments | O3: Total New Members | P3: July | Q3: August | R3: September | S3: October | T3: November | U3: December | V3: January | W3: February | X3: March | Y3: April | Z3: May | AA3: June | AB3: Smedley Award Eligibility | AC3: Smedley Award Goal | AD3: Talk Up Eligibility | AE3: Talk Up Goal | AF3: Beat the Clock Eligibility | AG3: Beat the Clock Goal
A4: 3984104 | B4: 01 | C4: Calicut Toastmasters | D4: =ClubDetails!G68 | E4: =ClubDetails!H68 | F4: =ClubDetails!I68 | G4: =IF(F4<5,"-",IF(E4>19,"Yes",IF(E4>D4+2,"Yes","-"))) | H4: =ClubDetails!K68 | I4: =IF(D4=0,0,H4/D4) | J4: =IF(H4=0,"Renewals not here",IF(H4<3,"Ineligible",IF(D4<8,"Low","Active"))) | K4: =ClubDetails!L68 | L4: =IF(D4=0,0,K4/D4) | M4: =IF(K4=0,"Renewals not here",IF(K4<3,"Ineligible",IF(E4<8,"Low","Active"))) | N4: =ClubDetails!M68 | O4: =ClubDetails!J68 | P4: 0 | Q4: 0 | R4: 0 | S4: 0 | T4: 0 | U4: 0 | V4: 0 | W4: 0 | X4: 0 | Y4: 0 | Z4: 0 | AA4: 0 | AB4: =IF(SUM(Q4:R4)>=5,"Yes","No") | AC4: =IF(SUM(Q4:R4)>=5,0,5-SUM(Q4:R4)) | AD4: =IF(SUM(W4:X4)>=5,"Yes","No") | AE4: =IF(SUM(W4:X4)>=5,0,5-SUM(W4:X4)) | AF4: =IF(SUM(Z4:AA4)>=5,"Yes","No") | AG4: =IF(SUM(Z4:AA4)>=5,0,5-SUM(Z4:AA4))
A5: 6750919 | B5: 01 | C5: Kannur Toastmasters Club | D5: =ClubDetails!G69 | E5: =ClubDetails!H69 | F5: =ClubDetails!I69 | G5: =IF(F5<5,"-",IF(E5>19,"Yes",IF(E5>D5+2,"Yes","-"))) | H5: =ClubDetails!K69 | I5: =IF(D5=0,0,H5/D5) | J5: =IF(H5=0,"Renewals not here",IF(H5<3,"Ineligible",IF(D5<8,"Low","Active"))) | K5: =ClubDetails!L69 | L5: =IF(D5=0,0,K5/D5) | M5: =IF(K5=0,"Renewals not here",IF(K5<3,"Ineligible",IF(E5<8,"Low","Active"))) | N5: =ClubDetails!M69 | O5: =ClubDetails!J69 | P5: 0 | Q5: 0 | R5: 0 | S5: 0 | T5: 0 | U5: 0 | V5: 0 | W5: 0 | X5: 0 | Y5: 0 | Z5: 0 | AA5: 0 | AB5: =IF(SUM(Q5:R5)>=5,"Yes","No") | AC5: =IF(SUM(Q5:R5)>=5,0,5-SUM(Q5:R5)) | AD5: =IF(SUM(W5:X5)>=5,"Yes","No") | AE5: =IF(SUM(W5:X5)>=5,0,5-SUM(W5:X5)) | AF5: =IF(SUM(Z5:AA5)>=5,"Yes","No") | AG5: =IF(SUM(Z5:AA5)>=5,0,5-SUM(Z5:AA5))
A6: 28675444 | B6: 01 | C6: Advanced Debate Club | D6: =ClubDetails!G70 | E6: =ClubDetails!H70 | F6: =ClubDetails!I70 | G6: =IF(F6<5,"-",IF(E6>19,"Yes",IF(E6>D6+2,"Yes","-"))) | H6: =ClubDetails!K70 | I6: =IF(D6=0,0,H6/D6) | J6: =IF(H6=0,"Renewals not here",IF(H6<3,"Ineligible",IF(D6<8,"Low","Active"))) | K6: =ClubDetails!L70 | L6: =IF(D6=0,0,K6/D6) | M6: =IF(K6=0,"Renewals not here",IF(K6<3,"Ineligible",IF(E6<8,"Low","Active"))) | N6: =ClubDetails!M70 | O6: =ClubDetails!J70 | P6: 0 | Q6: 0 | R6: 0 | S6: 0 | T6: 0 | U6: 0 | V6: 0 | W6: 0 | X6: 0 | Y6: 0 | Z6: 0 | AA6: 0 | AB6: =IF(SUM(Q6:R6)>=5,"Yes","No") | AC6: =IF(SUM(Q6:R6)>=5,0,5-SUM(Q6:R6)) | AD6: =IF(SUM(W6:X6)>=5,"Yes","No") | AE6: =IF(SUM(W6:X6)>=5,0,5-SUM(W6:X6)) | AF6: =IF(SUM(Z6:AA6)>=5,"Yes","No") | AG6: =IF(SUM(Z6:AA6)>=5,0,5-SUM(Z6:AA6))
A7: 28676179 | B7: 01 | C7: Malabar Toastmasters Club | D7: =ClubDetails!G71 | E7: =ClubDetails!H71 | F7: =ClubDetails!I71 | G7: =IF(F7<5,"-",IF(E7>19,"Yes",IF(E7>D7+2,"Yes","-"))) | H7: =ClubDetails!K71 | I7: =IF(D7=0,0,H7/D7) | J7: =IF(H7=0,"Renewals not here",IF(H7<3,"Ineligible",IF(D7<8,"Low","Active"))) | K7: =ClubDetails!L71 | L7: =IF(D7=0,0,K7/D7) | M7: =IF(K7=0,"Renewals not here",IF(K7<3,"Ineligible",IF(E7<8,"Low","Active"))) | N7: =ClubDetails!M71 | O7: =ClubDetails!J71 | P7: 0 | Q7: 0 | R7: 0 | S7: 0 | T7: 0 | U7: 0 | V7: 0 | W7: 0 | X7: 0 | Y7: 0 | Z7: 0 | AA7: 0 | AB7: =IF(SUM(Q7:R7)>=5,"Yes","No") | AC7: =IF(SUM(Q7:R7)>=5,0,5-SUM(Q7:R7)) | AD7: =IF(SUM(W7:X7)>=5,"Yes","No") | AE7: =IF(SUM(W7:X7)>=5,0,5-SUM(W7:X7)) | AF7: =IF(SUM(Z7:AA7)>=5,"Yes","No") | AG7: =IF(SUM(Z7:AA7)>=5,0,5-SUM(Z7:AA7))
